Workbook
Name Excel_BuiltIn__FilterDatabase: Üldinfo!$A$1:$BB$153

Sheet Üldinfo
F1: Ülalõug | X1: Alalõug
A2: Täida | F2: Parem | O2: Vasak | X2: Parem | AF2: Vasak | AN2: Kontroll (automaatne) | AU2: Kas esineb: tühi=ei; 1=jah | BB2: 0 kuni 6 (autom.)
A3: Nr | B3: Sugu | C3: Vanus | D3: Vanuserühm | E3: Hambaid (1/0) | F3: M4 | G3: M3 | H3: M2 | I3: M1 | J3: PM2 | K3: PM1 | L3: C | M3: I2 | N3: I1 | O3: I1 | P3: I2 | Q3: C | R3: PM1 | S3: PM2 | T3: M1 | U3: M2 | V3: M3 | W3: M4 | X3: M3 | Y3: M2 | Z3: M1 | AA3: PM2 | AB3: PM1 | AC3: C | AD3: I2 | AE3: I1 | AF3: I1 | AG3: I2 | AH3: C | AI3: PM1 | AJ3: PM2 | AK3: M1 | AL3: M2 | AM3: M3 | AN3: Säilinud | AO3: AM | AP3: PM | AQ3: Lõikunud | AR3: Lõikumata | AS3: KOKKU | AT3: ? = NA | AU3: Kas? | AV3: DC | AW3: Kaaries | AX3: DEH | AY3: PA | AZ3: AM | BA3: RED | BB3: Mitu pat. esineb | BD3: Muu | BE3: PH | BF3: JH
A4: 1 | B4: Mees | C4: 40-50 a | D4: Maturus/Senilis | E4: 1 | X4: pm | Y4: 1 | AM4: pm | AN4: =COUNTIF(F4:AM4,"1") -> 1 | AO4: =COUNTIF(F4:AM4,"am") -> 0 | AP4: =COUNTIF(F4:AM4,"pm") -> 2 | AQ4: =SUM((COUNTIF(F4:AM4,"1"))+(COUNTIF(F4:AM4,"am"))+(COUNTIF(F4:AM4,"pm"))) -> 3 | AR4: =COUNTIF(F4:AM4,"x") -> 0 | AS4: =SUM(AQ4:AR4) -> 3 | AT4: =COUNTIF(F4:AM4,"NA") -> 0 | AU4: 1 | AW4: 1 | AY4: 1 | BB4: =SUM(AV4:BA4) -> 2 | BF4: 1 | BG4: =SUM(BE4:BF4) -> 1
A5: 2 | B5: Naine | C5: 35-45 a | D5: Maturus | E5: 1 | V5: 1 | X5: 1 | Y5: 1 | Z5: am | AA5: 1 | AB5: 1 | AC5: 1 | AD5: pm | AE5: pm | AF5: pm | AG5: pm | AH5: pm | AI5: pm | AJ5: pm | AK5: pm | AL5: 1 | AM5: 1 | AN5: =COUNTIF(F5:AM5,"1") -> 8 | AO5: =COUNTIF(F5:AM5,"am") -> 1 | AP5: =COUNTIF(F5:AM5,"pm") -> 8 | AQ5: =SUM((COUNTIF(F5:AM5,"1"))+(COUNTIF(F5:AM5,"am"))+(COUNTIF(F5:AM5,"pm"))) -> 17 | AR5: =COUNTIF(F5:AM5,"x") -> 0 | AS5: =SUM(AQ5:AR5) -> 17 | AT5: =COUNTIF(F5:AM5,"NA") -> 0 | AU5: 1 | AV5: 1 | AW5: 1 | AZ5: 1 | BA5: 1 | BB5: =SUM(AV5:BA5) -> 4 | BD5: Alalõualuu p PM2 on lõikunud viltu (gen eripära) | BF5: 8 | BG5: =SUM(BE5:BF5) -> 8
A6: 3 | B6: Mees | C6: Täisk | D6: Täisk | E6: 0 | AN6: =COUNTIF(F6:AM6,"1") -> 0 | AO6: =COUNTIF(F6:AM6,"am") -> 0 | AP6: =COUNTIF(F6:AM6,"pm") -> 0 | AQ6: =SUM((COUNTIF(F6:AM6,"1"))+(COUNTIF(F6:AM6,"am"))+(COUNTIF(F6:AM6,"pm"))) -> 0 | AR6: =COUNTIF(F6:AM6,"x") -> 0 | AS6: =SUM(AQ6:AR6) -> 0 | AT6: =COUNTIF(F6:AM6,"NA") -> 0 | BB6: =SUM(AV6:BA6) -> 0 | BG6: =SUM(BE6:BF6) -> 0
A7: 4 | B7: Naine | C7: 18-20 a | D7: Adultus | E7: 1 | F7: X | G7: X | H7: 1 | I7: 1 | J7: 1 | K7: 1 | L7: 1 | M7: 1 | N7: 1 | O7: 1 | P7: 1 | Q7: 1 | R7: 1 | S7: 1 | T7: 1 | U7: 1 | V7: X | W7: X | X7: 1 | Y7: 1 | Z7: 1 | AA7: 1 | AB7: 1 | AC7: 1 | AD7: 1 | AE7: 1 | AF7: 1 | AG7: 1 | AH7: 1 | AI7: 1 | AJ7: 1 | AK7: 1 | AL7: 1 | AM7: 1 | AN7: =COUNTIF(F7:AM7,"1") -> 30 | AO7: =COUNTIF(F7:AM7,"am") -> 0 | AP7: =COUNTIF(F7:AM7,"pm") -> 0 | AQ7: =SUM((COUNTIF(F7:AM7,"1"))+(COUNTIF(F7:AM7,"am"))+(COUNTIF(F7:AM7,"pm"))) -> 30 | AR7: =COUNTIF(F7:AM7,"x") -> 4 | AS7: =SUM(AQ7:AR7) -> 34 | AT7: =COUNTIF(F7:AM7,"NA") -> 0 | AU7: 1 | AV7: 1 | AX7: 1 | BB7: =SUM(AV7:BA7) -> 2 | BD7: alumine p M3 on lõikunud vastu M2-e; alumine v C on lõikunud viltu; alumise V PM5 krooni emailist dist-külje o-oAlaealinest tükk väljas; ülemised M4 ei ole lõikunud | BF7: 30 | BG7: =SUM(BE7:BF7) -> 30
A8: 5 | B8: Naine | C8: 45+ a | D8: Senilis | E8: 1 | G8: pm | H8: pm | I8: 1 | J8: 1 | K8: 1 | L8: 1 | M8: 1 | N8: 1 | O8: 1 | P8: 1 | Q8: 1 | R8: 1 | S8: 1 | T8: am | U8: 1 | V8: am | Y8: 1 | Z8: pm | AA8: am | AB8: 1 | AC8: 1 | AD8: 1 | AE8: 1 | AF8: pm | AG8: pm | AH8: 1 | AI8: 1 | AJ8: am | AK8: am | AL8: 1 | AN8: =COUNTIF(F8:AM8,"1") -> 20 | AO8: =COUNTIF(F8:AM8,"am") -> 5 | AP8: =COUNTIF(F8:AM8,"pm") -> 5 | AQ8: =SUM((COUNTIF(F8:AM8,"1"))+(COUNTIF(F8:AM8,"am"))+(COUNTIF(F8:AM8,"pm"))) -> 30 | AR8: =COUNTIF(F8:AM8,"x") -> 0 | AS8: =SUM(AQ8:AR8) -> 30 | AT8: =COUNTIF(F8:AM8,"NA") -> 0 | AU8: 1 | AV8: 1 | AW8: 1 | AX8: 1 | AY8: 1 | AZ8: 1 | BA8: 1 | BB8: =SUM(AV8:BA8) -> 6 | BD8: alumise parema I1 o-pinnalt tükk väljas | BF8: 20 | BG8: =SUM(BE8:BF8) -> 20
A9: 6 | B9: Naine | C9: 40-50 a | D9: Maturus/Senilis | E9: 1 | G9: 1 | H9: 1 | L9: 1 | M9: 1 | V9: 1 | Y9: 1 | Z9: 1 | AA9: 1 | AB9: 1 | AC9: 1 | AD9: 1 | AE9: pm | AF9: 1 | AG9: 1 | AH9: 1 | AI9: 1 | AJ9: 1 | AK9: 1 | AL9: 1 | AN9: =COUNTIF(F9:AM9,"1") -> 18 | AO9: =COUNTIF(F9:AM9,"am") -> 0 | AP9: =COUNTIF(F9:AM9,"pm") -> 1 | AQ9: =SUM((COUNTIF(F9:AM9,"1"))+(COUNTIF(F9:AM9,"am"))+(COUNTIF(F9:AM9,"pm"))) -> 19 | AR9: =COUNTIF(F9:AM9,"x") -> 0 | AS9: =SUM(AQ9:AR9) -> 19 | AT9: =COUNTIF(F9:AM9,"NA") -> 0 | AU9: 1 | AV9: 1 | AW9: 1 | AY9: 1 | BB9: =SUM(AV9:BA9) -> 3 | BD9: alumise parema C ja vaAlaealineku I1 emaili o-pinnast tükid väljas | BF9: 18 | BG9: =SUM(BE9:BF9) -> 18
A10: 7 | B10: Alaealine | C10: 12-16 a | D10: Juvenilis 1 | E10: 1 | G10: X | H10: 1 | I10: 1 | J10: 1 | K10: 1 | L10: 1 | M10: X | N10: 1 | O10: 1 | P10: X | Q10: 1 | R10: 1 | S10: 1 | T10: 1 | U10: 1 | V10: X | Y10: 1 | Z10: 1 | AA10: 1 | AB10: 1 | AC10: 1 | AD10: 1 | AE10: 1 | AF10: 1 | AG10: 1 | AH10: 1 | AI10: 1 | AJ10: 1 | AK10: 1 | AL10: 1 | AN10: =COUNTIF(F10:AM10,"1") -> 26 | AO10: =COUNTIF(F10:AM10,"am") -> 0 | AP10: =COUNTIF(F10:AM10,"pm") -> 0 | AQ10: =SUM((COUNTIF(F10:AM10,"1"))+(COUNTIF(F10:AM10,"am"))+(COUNTIF(F10:AM10,"pm"))) -> 26 | AR10: =COUNTIF(F10:AM10,"x") -> 4 | AS10: =SUM(AQ10:AR10) -> 30 | AT10: =COUNTIF(F10:AM10,"NA") -> 0 | AU10: 1 | AV10: 1 | AW10: 1 | AX10: 1 | BB10: =SUM(AV10:BA10) -> 3 | BD10: 2I ja I2 olemasolu ei ole kindel | BF10: 26 | BG10: =SUM(BE10:BF10) -> 26
A11: 8 | B11: Mees | C11: 35-45 a | D11: Maturus | E11: 1 | G11: 1 | H11: 1 | I11: am | J11: 1 | K11: 1 | L11: 1 | M11: 1 | N11: 1 | O11: 1 | P11: 1 | Q11: 1 | R11: 1 | S11: 1 | T11: 1 | U11: 1 | V11: 1 | X11: 1 | Y11: 1 | Z11: 1 | AA11: 1 | AB11: 1 | AC11: 1 | AD11: 1 | AE11: 1 | AF11: 1 | AG11: 1 | AH11: 1 | AI11: 1 | AJ11: 1 | AK11: 1 | AL11: 1 | AM11: 1 | AN11: =COUNTIF(F11:AM11,"1") -> 31 | AO11: =COUNTIF(F11:AM11,"am") -> 1 | AP11: =COUNTIF(F11:AM11,"pm") -> 0 | AQ11: =SUM((COUNTIF(F11:AM11,"1"))+(COUNTIF(F11:AM11,"am"))+(COUNTIF(F11:AM11,"pm"))) -> 32 | AR11: =COUNTIF(F11:AM11,"x") -> 0 | AS11: =SUM(AQ11:AR11) -> 32 | AT11: =COUNTIF(F11:AM11,"NA") -> 0 | AU11: 1 | AV11: 1 | AW11: 1 | AX11: 1 | AY11: 1 | AZ11: 1 | BA11: 1 | BB11: =SUM(AV11:BA11) -> 6 | BF11: 31 | BG11: =SUM(BE11:BF11) -> 31
A12: 9 | B12: Mees | C12: 40-50 a | D12: Maturus/Senilis | E12: 1 | K12: pm | L12: 1 | M12: 1 | N12: 1 | O12: 1 | P12: pm | Q12: 1 | R12: 1 | S12: 1 | T12: am | U12: 1 | V12: 1 | AN12: =COUNTIF(F12:AM12,"1") -> 9 | AO12: =COUNTIF(F12:AM12,"am") -> 1 | AP12: =COUNTIF(F12:AM12,"pm") -> 2 | AQ12: =SUM((COUNTIF(F12:AM12,"1"))+(COUNTIF(F12:AM12,"am"))+(COUNTIF(F12:AM12,"pm"))) -> 12 | AR12: =COUNTIF(F12:AM12,"x") -> 0 | AS12: =SUM(AQ12:AR12) -> 12 | AT12: =COUNTIF(F12:AM12,"NA") -> 0 | AU12: 1 | AV12: 1 | AW12: 1 | AY12: 1 | AZ12: 1 | BB12: =SUM(AV12:BA12) -> 4 | BD12: Kõik ülalõualuu hambad on tugevasti kulunud | BF12: 9 | BG12: =SUM(BE12:BF12) -> 9
A13: 10 | B13: Mees | C13: 45+ a | D13: Senilis | E13: 1 | G13: 1 | H13: 1 | I13: am | J13: 1 | K13: am | L13: 1 | M13: 1 | N13: pm | O13: 1 | P13: 1 | Q13: 1 | R13: 1 | S13: am | T13: 1 | U13: 1 | V13: 1 | X13: NA | Y13: am | Z13: am | AA13: 1 | AB13: 1 | AC13: 1 | AD13: 1 | AE13: am | AF13: 1 | AG13: 1 | AH13: pm | AI13: 1 | AJ13: 1 | AK13: 1 | AL13: 1 | AM13: NA | AN13: =COUNTIF(F13:AM13,"1") -> 22 | AO13: =COUNTIF(F13:AM13,"am") -> 6 | AP13: =COUNTIF(F13:AM13,"pm") -> 2 | AQ13: =SUM((COUNTIF(F13:AM13,"1"))+(COUNTIF(F13:AM13,"am"))+(COUNTIF(F13:AM13,"pm"))) -> 30 | AR13: =COUNTIF(F13:AM13,"x") -> 0 | AS13: =SUM(AQ13:AR13) -> 30 | AT13: =COUNTIF(F13:AM13,"NA") -> 2 | AU13: 1 | AV13: 1 | AW13: 1 | AY13: 1 | AZ13: 1 | BA13: 1 | BB13: =SUM(AV13:BA13) -> 5 | BD13: Lõike-, silma ja esimesed eespurihambad olid tugevasti kulunud | BF13: 22 | BG13: =SUM(BE13:BF13) -> 22
A14: 11 | B14: Naine | C14: 40+ a | D14: Maturus/Senilis | E14: 0 | AN14: =COUNTIF(F14:AM14,"1") -> 0 | AO14: =COUNTIF(F14:AM14,"am") -> 0 | AP14: =COUNTIF(F14:AM14,"pm") -> 0 | AQ14: =SUM((COUNTIF(F14:AM14,"1"))+(COUNTIF(F14:AM14,"am"))+(COUNTIF(F14:AM14,"pm"))) -> 0 | AR14: =COUNTIF(F14:AM14,"x") -> 0 | AS14: =SUM(AQ14:AR14) -> 0 | AT14: =COUNTIF(F14:AM14,"NA") -> 0 | BB14: =SUM(AV14:BA14) -> 0 | BG14: =SUM(BE14:BF14) -> 0
A15: 12 | B15: Mees | C15: 18-19 a | D15: Adultus | E15: 0 | AN15: =COUNTIF(F15:AM15,"1") -> 0 | AO15: =COUNTIF(F15:AM15,"am") -> 0 | AP15: =COUNTIF(F15:AM15,"pm") -> 0 | AQ15: =SUM((COUNTIF(F15:AM15,"1"))+(COUNTIF(F15:AM15,"am"))+(COUNTIF(F15:AM15,"pm"))) -> 0 | AR15: =COUNTIF(F15:AM15,"x") -> 0 | AS15: =SUM(AQ15:AR15) -> 0 | AT15: =COUNTIF(F15:AM15,"NA") -> 0 | BB15: =SUM(AV15:BA15) -> 0 | BG15: =SUM(BE15:BF15) -> 0
A16: 13 | B16: Mees | C16: 25-35 a | D16: Adultus/Maturus | E16: 1 | G16: 1 | H16: 1 | I16: am | J16: pm | K16: pm | L16: 1 | M16: 1 | N16: pm | O16: pm | P16: pm | Q16: 1 | R16: 1 | S16: pm | T16: am | U16: 1 | V16: 1 | Y16: pm | Z16: am | AA16: pm | AB16: pm | AC16: pm | AD16: pm | AE16: pm | AF16: pm | AG16: pm | AK16: pm | AL16: pm | AN16: =COUNTIF(F16:AM16,"1") -> 8 | AO16: =COUNTIF(F16:AM16,"am") -> 3 | AP16: =COUNTIF(F16:AM16,"pm") -> 16 | AQ16: =SUM((COUNTIF(F16:AM16,"1"))+(COUNTIF(F16:AM16,"am"))+(COUNTIF(F16:AM16,"pm"))) -> 27 | AR16: =COUNTIF(F16:AM16,"x") -> 0 | AS16: =SUM(AQ16:AR16) -> 27 | AT16: =COUNTIF(F16:AM16,"NA") -> 0 | AU16: 1 | AV16: 1 | AW16: 1 | AX16: 1 | AZ16: 1 | BA16: 1 | BB16: =SUM(AV16:BA16) -> 5 | BD16: p I2 emailist o-pinnast tükid väljas | BF16: 8 | BG16: =SUM(BE16:BF16) -> 8
A17: 14 | B17: Naine | C17: 50+ a | D17: Senilis | E17: 1 | G17: 1 | H17: 1 | I17: am | J17: 1 | K17: 1 | L17: 1 | M17: pm | N17: 1 | O17: 1 | P17: 1 | Q17: 1 | R17: 1 | S17: am | T17: 1 | U17: am | V17: 1 | X17: NA | Y17: am | Z17: am | AA17: 1 | AB17: 1 | AC17: 1 | AD17: 1 | AE17: pm | AF17: 1 | AG17: 1 | AH17: 1 | AI17: 1 | AJ17: pm | AK17: am | AL17: am | AM17: NA | AN17: =COUNTIF(F17:AM17,"1") -> 20 | AO17: =COUNTIF(F17:AM17,"am") -> 7 | AP17: =COUNTIF(F17:AM17,"pm") -> 3 | AQ17: =SUM((COUNTIF(F17:AM17,"1"))+(COUNTIF(F17:AM17,"am"))+(COUNTIF(F17:AM17,"pm"))) -> 30 | AR17: =COUNTIF(F17:AM17,"x") -> 0 | AS17: =SUM(AQ17:AR17) -> 30 | AT17: =COUNTIF(F17:AM17,"NA") -> 2 | AU17: 1 | AV17: 1 | AW17: 1 | AY17: 1 | AZ17: 1 | BA17: 1 | BB17: =SUM(AV17:BA17) -> 5 | BD17: Ülalõualuu lõike-, silma- ja I eespurihammaste hambakroonid on juurteni kulunud | BF17: 20 | BG17: =SUM(BE17:BF17) -> 20
A18: 15 | B18: Mees | C18: 39-44 a | D18: Maturus | E18: 1 | H18: 1 | I18: pm | J18: X | K18: 1 | L18: 1 | M18: pm | N18: pm | O18: pm | P18: am | Q18: pm | R18: 1 | S18: 1 | T18: 1 | U18: pm | X18: NA | Y18: am | Z18: pm | AA18: 1 | AB18: 1 | AC18: 1 | AD18: 1 | AE18: 1 | AF18: 1 | AG18: 1 | AH18: 1 | AI18: 1 | AJ18: 1 | AK18: am | AL18: am | AM18: NA | AN18: =COUNTIF(F18:AM18,"1") -> 16 | AO18: =COUNTIF(F18:AM18,"am") -> 4 | AP18: =COUNTIF(F18:AM18,"pm") -> 7 | AQ18: =SUM((COUNTIF(F18:AM18,"1"))+(COUNTIF(F18:AM18,"am"))+(COUNTIF(F18:AM18,"pm"))) -> 27 | AR18: =COUNTIF(F18:AM18,"x") -> 1 | AS18: =SUM(AQ18:AR18) -> 28 | AT18: =COUNTIF(F18:AM18,"NA") -> 2 | AU18: 1 | AV18: 1 | AX18: 1 | AY18: 1 | AZ18: 1 | BA18: 1 | BB18: =SUM(AV18:BA18) -> 5 | BD18: 1I ja 2I emaili o-pinnast tükid väljast | BF18: 16 | BG18: =SUM(BE18:BF18) -> 16
A19: 16 | B19: Naine | C19: 25-35 a | D19: Adultus/Maturus | E19: 1 | H19: 1 | I19: 1 | J19: 1 | K19: 1 | L19: 1 | M19: 1 | N19: 1 | O19: 1 | P19: 1 | Q19: 1 | R19: 1 | S19: 1 | T19: 1 | U19: 1 | X19: 1 | Y19: 1 | Z19: pm | AA19: am | AB19: 1 | AC19: 1 | AD19: 1 | AE19: 1 | AF19: 1 | AG19: 1 | AH19: 1 | AI19: 1 | AJ19: 1 | AK19: 1 | AL19: 1 | AM19: 1 | AN19: =COUNTIF(F19:AM19,"1") -> 28 | AO19: =COUNTIF(F19:AM19,"am") -> 1 | AP19: =COUNTIF(F19:AM19,"pm") -> 1 | AQ19: =SUM((COUNTIF(F19:AM19,"1"))+(COUNTIF(F19:AM19,"am"))+(COUNTIF(F19:AM19,"pm"))) -> 30 | AR19: =COUNTIF(F19:AM19,"x") -> 0 | AS19: =SUM(AQ19:AR19) -> 30 | AT19: =COUNTIF(F19:AM19,"NA") -> 0 | AU19: 1 | AV19: 1 | AW19: 1 | AX19: 1 | AY19: 1 | AZ19: 1 | BB19: =SUM(AV19:BA19) -> 5 | BF19: 28 | BG19: =SUM(BE19:BF19) -> 28
A20: 17 | B20: Mees | C20: 25-35 a | D20: Adultus/Maturus | E20: 1 | G20: 1 | H20: 1 | I20: 1 | J20: 1 | K20: 1 | L20: 1 | M20: 1 | N20: 1 | O20: 1 | P20: 1 | Q20: 1 | R20: 1 | S20: 1 | T20: 1 | U20: 1 | V20: 1 | X20: 1 | Y20: 1 | Z20: 1 | AA20: 1 | AB20: 1 | AC20: 1 | AD20: 1 | AE20: 1 | AF20: 1 | AG20: 1 | AH20: 1 | AI20: 1 | AJ20: 1 | AK20: 1 | AL20: 1 | AM20: 1 | AN20: =COUNTIF(F20:AM20,"1") -> 32 | AO20: =COUNTIF(F20:AM20,"am") -> 0 | AP20: =COUNTIF(F20:AM20,"pm") -> 0 | AQ20: =SUM((COUNTIF(F20:AM20,"1"))+(COUNTIF(F20:AM20,"am"))+(COUNTIF(F20:AM20,"pm"))) -> 32 | AR20: =COUNTIF(F20:AM20,"x") -> 0 | AS20: =SUM(AQ20:AR20) -> 32 | AT20: =COUNTIF(F20:AM20,"NA") -> 0 | AU20: 1 | AV20: 1 | AW20: 1 | AX20: 1 | AY20: 1 | BB20: =SUM(AV20:BA20) -> 4 | BD20: P ja v I1 hambakrooni ant-med oAlaealinest tükk väljas. Kerge hambakivi. P I1 o pinnast tükid väljas. V I1 emailist tükid väljas. | BF20: 32 | BG20: =SUM(BE20:BF20) -> 32
A21: 18 | B21: Mees | C21: 44-50 a | D21: Maturus/Senilis | E21: 1 | G21: 1 | H21: 1 | I21: 1 | P21: 1 | Q21: 1 | R21: 1 | S21: 1 | T21: 1 | U21: 1 | X21: 1 | Y21: 1 | Z21: 1 | AA21: 1 | AB21: 1 | AC21: 1 | AD21: 1 | AE21: 1 | AF21: 1 | AG21: 1 | AH21: 1 | AI21: 1 | AJ21: 1 | AK21: 1 | AL21: 1 | AM21: 1 | AN21: =COUNTIF(F21:AM21,"1") -> 25 | AO21: =COUNTIF(F21:AM21,"am") -> 0 | AP21: =COUNTIF(F21:AM21,"pm") -> 0 | AQ21: =SUM((COUNTIF(F21:AM21,"1"))+(COUNTIF(F21:AM21,"am"))+(COUNTIF(F21:AM21,"pm"))) -> 25 | AR21: =COUNTIF(F21:AM21,"x") -> 0 | AS21: =SUM(AQ21:AR21) -> 25 | AT21: =COUNTIF(F21:AM21,"NA") -> 0 | AU21: 1 | AV21: 1 | AX21: 1 | BB21: =SUM(AV21:BA21) -> 2 | BF21: 25 | BG21: =SUM(BE21:BF21) -> 25
A22: 19 | B22: Mees ? | C22: 39-44 a | D22: Maturus | E22: 1 | G22: 1 | H22: 1 | I22: 1 | J22: 1 | K22: 1 | O22: pm | P22: pm | Q22: 1 | R22: 1 | S22: 1 | T22: 1 | U22: 1 | V22: 1 | Y22: 1 | Z22: 1 | AB22: 1 | AC22: 1 | AD22: 1 | AE22: 1 | AF22: 1 | AG22: 1 | AH22: 1 | AI22: 1 | AJ22: am | AK22: 1 | AL22: 1 | AN22: =COUNTIF(F22:AM22,"1") -> 23 | AO22: =COUNTIF(F22:AM22,"am") -> 1 | AP22: =COUNTIF(F22:AM22,"pm") -> 2 | AQ22: =SUM((COUNTIF(F22:AM22,"1"))+(COUNTIF(F22:AM22,"am"))+(COUNTIF(F22:AM22,"pm"))) -> 26 | AR22: =COUNTIF(F22:AM22,"x") -> 0 | AS22: =SUM(AQ22:AR22) -> 26 | AT22: =COUNTIF(F22:AM22,"NA") -> 0 | AU22: 1 | AV22: 1 | AW22: 1 | AZ22: 1 | BB22: =SUM(AV22:BA22) -> 3 | BD22: p PM2 ei ole olemas; p PM1 on viltu lõikunud | BF22: 23 | BG22: =SUM(BE22:BF22) -> 23
A23: 20 | B23: Mees | C23: 22-24 a | D23: Adultus | E23: 0 | AN23: =COUNTIF(F23:AM23,"1") -> 0 | AO23: =COUNTIF(F23:AM23,"am") -> 0 | AP23: =COUNTIF(F23:AM23,"pm") -> 0 | AQ23: =SUM((COUNTIF(F23:AM23,"1"))+(COUNTIF(F23:AM23,"am"))+(COUNTIF(F23:AM23,"pm"))) -> 0 | AR23: =COUNTIF(F23:AM23,"x") -> 0 | AS23: =SUM(AQ23:AR23) -> 0 | AT23: =COUNTIF(F23:AM23,"NA") -> 0 | BB23: =SUM(AV23:BA23) -> 0 | BG23: =SUM(BE23:BF23) -> 0
A24: 21 | B24: Naine | C24: 40+ a | D24: Maturus/Senilis | E24: 1 | G24: 1 | H24: 1 | I24: 1 | J24: 1 | K24: 1 | L24: 1 | M24: 1 | N24: 1 | O24: 1 | P24: 1 | Q24: 1 | R24: 1 | S24: 1 | T24: am | U24: 1 | V24: 1 | Y24: 1 | Z24: 1 | AA24: 1 | AB24: 1 | AC24: 1 | AD24: 1 | AE24: 1 | AF24: 1 | AG24: 1 | AH24: 1 | AI24: 1 | AJ24: 1 | AK24: 1 | AL24: 1 | AN24: =COUNTIF(F24:AM24,"1") -> 29 | AO24: =COUNTIF(F24:AM24,"am") -> 1 | AP24: =COUNTIF(F24:AM24,"pm") -> 0 | AQ24: =SUM((COUNTIF(F24:AM24,"1"))+(COUNTIF(F24:AM24,"am"))+(COUNTIF(F24:AM24,"pm"))) -> 30 | AR24: =COUNTIF(F24:AM24,"x") -> 0 | AS24: =SUM(AQ24:AR24) -> 30 | AT24: =COUNTIF(F24:AM24,"NA") -> 0 | AU24: 1 | AV24: 1 | AW24: 1 | AY24: 1 | AZ24: 1 | BA24: 1 | BB24: =SUM(AV24:BA24) -> 5 | BF24: 29 | BG24: =SUM(BE24:BF24) -> 29
A25: 22 | B25: Mees ? | C25: 25-35 a | D25: Adultus/Maturus | E25: 1 | G25: 1 | H25: 1 | I25: 1 | J25: 1 | K25: 1 | L25: 1 | M25: 1 | N25: 1 | O25: 1 | P25: 1 | Q25: 1 | R25: 1 | S25: 1 | T25: 1 | U25: 1 | V25: 1 | Y25: 1 | Z25: 1 | AA25: 1 | AB25: 1 | AC25: 1 | AD25: 1 | AE25: 1 | AF25: 1 | AG25: 1 | AH25: 1 | AI25: 1 | AJ25: 1 | AK25: 1 | AL25: 1 | AM25: 1 | AN25: =COUNTIF(F25:AM25,"1") -> 31 | AO25: =COUNTIF(F25:AM25,"am") -> 0 | AP25: =COUNTIF(F25:AM25,"pm") -> 0 | AQ25: =SUM((COUNTIF(F25:AM25,"1"))+(COUNTIF(F25:AM25,"am"))+(COUNTIF(F25:AM25,"pm"))) -> 31 | AR25: =COUNTIF(F25:AM25,"x") -> 0 | AS25: =SUM(AQ25:AR25) -> 31 | AT25: =COUNTIF(F25:AM25,"NA") -> 0 | AU25: 1 | AV25: 1 | AW25: 1 | AY25: 1 | BB25: =SUM(AV25:BA25) -> 3 | BD25: P I1, v I2 emailist o-pinnast tükid väljas | BF25: 31 | BG25: =SUM(BE25:BF25) -> 31
A26: 23 | B26: Mees | C26: 50+ a | D26: Senilis | E26: 1 | G26: 1 | H26: 1 | I26: 1 | J26: 1 | K26: 1 | L26: 1 | M26: 1 | N26: 1 | O26: 1 | P26: 1 | Q26: 1 | R26: 1 | S26: 1 | T26: 1 | U26: 1 | V26: pm | X26: 1 | Y26: 1 | Z26: 1 | AA26: 1 | AB26: 1 | AC26: 1 | AD26: 1 | AE26: 1 | AF26: 1 | AG26: 1 | AH26: 1 | AI26: 1 | AJ26: 1 | AK26: 1 | AL26: 1 | AN26: =COUNTIF(F26:AM26,"1") -> 30 | AO26: =COUNTIF(F26:AM26,"am") -> 0 | AP26: =COUNTIF(F26:AM26,"pm") -> 1 | AQ26: =SUM((COUNTIF(F26:AM26,"1"))+(COUNTIF(F26:AM26,"am"))+(COUNTIF(F26:AM26,"pm"))) -> 31 | AR26: =COUNTIF(F26:AM26,"x") -> 0 | AS26: =SUM(AQ26:AR26) -> 31 | AT26: =COUNTIF(F26:AM26,"NA") -> 0 | AU26: 1 | AV26: 1 | AW26: 1 | AX26: 1 | AY26: 1 | BA26: 1 | BB26: =SUM(AV26:BA26) -> 5 | BD26: P I2, C1, V I1, I2, C1 emaili o-pinnast tükid väljas | BF26: 30 | BG26: =SUM(BE26:BF26) -> 30
A27: 25 | B27: Naine ? | C27: Täisk | D27: Täisk | E27: 0 | AN27: =COUNTIF(F27:AM27,"1") -> 0 | AO27: =COUNTIF(F27:AM27,"am") -> 0 | AP27: =COUNTIF(F27:AM27,"pm") -> 0 | AQ27: =SUM((COUNTIF(F27:AM27,"1"))+(COUNTIF(F27:AM27,"am"))+(COUNTIF(F27:AM27,"pm"))) -> 0 | AR27: =COUNTIF(F27:AM27,"x") -> 0 | AS27: =SUM(AQ27:AR27) -> 0 | AT27: =COUNTIF(F27:AM27,"NA") -> 0 | BB27: =SUM(AV27:BA27) -> 0 | BG27: =SUM(BE27:BF27) -> 0
A28: 26 | B28: Alaealine | C28: 5-9 a | D28: Infans | E28: 0 | AN28: =COUNTIF(F28:AM28,"1") -> 0 | AO28: =COUNTIF(F28:AM28,"am") -> 0 | AP28: =COUNTIF(F28:AM28,"pm") -> 0 | AQ28: =SUM((COUNTIF(F28:AM28,"1"))+(COUNTIF(F28:AM28,"am"))+(COUNTIF(F28:AM28,"pm"))) -> 0 | AR28: =COUNTIF(F28:AM28,"x") -> 0 | AS28: =SUM(AQ28:AR28) -> 0 | AT28: =COUNTIF(F28:AM28,"NA") -> 0 | BB28: =SUM(AV28:BA28) -> 0 | BG28: =SUM(BE28:BF28) -> 0
A29: 27 | B29: Naine ? | C29: Täisk | D29: Täisk | E29: 0 | AN29: =COUNTIF(F29:AM29,"1") -> 0 | AO29: =COUNTIF(F29:AM29,"am") -> 0 | AP29: =COUNTIF(F29:AM29,"pm") -> 0 | AQ29: =SUM((COUNTIF(F29:AM29,"1"))+(COUNTIF(F29:AM29,"am"))+(COUNTIF(F29:AM29,"pm"))) -> 0 | AR29: =COUNTIF(F29:AM29,"x") -> 0 | AS29: =SUM(AQ29:AR29) -> 0 | AT29: =COUNTIF(F29:AM29,"NA") -> 0 | BB29: =SUM(AV29:BA29) -> 0 | BG29: =SUM(BE29:BF29) -> 0
A30: 28 | B30: Mees | C30: 18-19 a | D30: Adultus | E30: 1 | G30: 1 | H30: 1 | I30: 1 | J30: 1 | K30: 1 | L30: 1 | M30: 1 | N30: 1 | O30: 1 | P30: 1 | Q30: 1 | R30: 1 | S30: 1 | T30: 1 | U30: 1 | V30: 1 | X30: 1 | Y30: 1 | Z30: 1 | AA30: 1 | AB30: 1 | AC30: 1 | AD30: 1 | AE30: 1 | AF30: 1 | AG30: 1 | AH30: 1 | AI30: 1 | AJ30: 1 | AK30: 1 | AL30: 1 | AM30: 1 | AN30: =COUNTIF(F30:AM30,"1") -> 32 | AO30: =COUNTIF(F30:AM30,"am") -> 0 | AP30: =COUNTIF(F30:AM30,"pm") -> 0 | AQ30: =SUM((COUNTIF(F30:AM30,"1"))+(COUNTIF(F30:AM30,"am"))+(COUNTIF(F30:AM30,"pm"))) -> 32 | AR30: =COUNTIF(F30:AM30,"x") -> 0 | AS30: =SUM(AQ30:AR30) -> 32 | AT30: =COUNTIF(F30:AM30,"NA") -> 0 | AU30: 1 | AV30: 1 | AW30: 1 | AX30: 1 | AY30: 1 | BB30: =SUM(AV30:BA30) -> 4 | BF30: 32 | BG30: =SUM(BE30:BF30) -> 32
A31: 29 | B31: Naine ? | C31: Täisk | D31: Täisk | E31: 0 | AN31: =COUNTIF(F31:AM31,"1") -> 0 | AO31: =COUNTIF(F31:AM31,"am") -> 0 | AP31: =COUNTIF(F31:AM31,"pm") -> 0 | AQ31: =SUM((COUNTIF(F31:AM31,"1"))+(COUNTIF(F31:AM31,"am"))+(COUNTIF(F31:AM31,"pm"))) -> 0 | AR31: =COUNTIF(F31:AM31,"x") -> 0 | AS31: =SUM(AQ31:AR31) -> 0 | AT31: =COUNTIF(F31:AM31,"NA") -> 0 | BB31: =SUM(AV31:BA31) -> 0 | BG31: =SUM(BE31:BF31) -> 0
A32: 30 | B32: Mees | C32: 19-34 a | D32: Adultus | E32: 1 | G32: 1 | H32: 1 | I32: 1 | J32: 1 | K32: 1 | L32: 1 | M32: 1 | N32: 1 | O32: 1 | P32: 1 | Q32: 1 | R32: 1 | S32: 1 | T32: 1 | U32: 1 | V32: 1 | X32: 1 | Y32: 1 | Z32: 1 | AA32: 1 | AB32: 1 | AC32: 1 | AD32: 1 | AE32: 1 | AF32: pm | AG32: 1 | AH32: 1 | AI32: 1 | AJ32: 1 | AK32: 1 | AL32: 1 | AM32: 1 | AN32: =COUNTIF(F32:AM32,"1") -> 31 | AO32: =COUNTIF(F32:AM32,"am") -> 0 | AP32: =COUNTIF(F32:AM32,"pm") -> 1 | AQ32: =SUM((COUNTIF(F32:AM32,"1"))+(COUNTIF(F32:AM32,"am"))+(COUNTIF(F32:AM32,"pm"))) -> 32 | AR32: =COUNTIF(F32:AM32,"x") -> 0 | AS32: =SUM(AQ32:AR32) -> 32 | AT32: =COUNTIF(F32:AM32,"NA") -> 0 | AU32: 1 | AV32: 1 | AW32: 1 | AX32: 1 | AY32: 1 | BB32: =SUM(AV32:BA32) -> 4 | BD32: p I1, I2, v I1, I2 emailist o-pinnast tükk väljas; p M1, M2 emailist b-pinnal tükk väljas | BF32: 31 | BG32: =SUM(BE32:BF32) -> 31
A33: 31 | B33: Mees | C33: 39-44 a | D33: Maturus | E33: 1 | G33: 1 | H33: 1 | I33: 1 | J33: 1 | K33: 1 | L33: 1 | M33: 1 | N33: 1 | O33: 1 | P33: 1 | Q33: 1 | R33: 1 | S33: 1 | T33: 1 | U33: 1 | V33: 1 | X33: 1 | Y33: 1 | Z33: 1 | AA33: 1 | AB33: 1 | AC33: 1 | AD33: 1 | AE33: 1 | AF33: 1 | AG33: 1 | AH33: 1 | AI33: 1 | AJ33: 1 | AK33: 1 | AL33: 1 | AN33: =COUNTIF(F33:AM33,"1") -> 31 | AO33: =COUNTIF(F33:AM33,"am") -> 0 | AP33: =COUNTIF(F33:AM33,"pm") -> 0 | AQ33: =SUM((COUNTIF(F33:AM33,"1"))+(COUNTIF(F33:AM33,"am"))+(COUNTIF(F33:AM33,"pm"))) -> 31 | AR33: =COUNTIF(F33:AM33,"x") -> 0 | AS33: =SUM(AQ33:AR33) -> 31 | AT33: =COUNTIF(F33:AM33,"NA") -> 0 | AU33: 1 | AV33: 1 | AW33: 1 | AX33: 1 | AY33: 1 | BA33: 1 | BB33: =SUM(AV33:BA33) -> 5 | BD33: P PM2 asub C1 kohal, C1 asub PM1 kohal, PM1 asub PM2 kohal; p ja v C1 emailist o-pinnal tükid väljas | BF33: 31 | BG33: =SUM(BE33:BF33) -> 31
A34: 32 | B34: Alaealine | C34: 15-18 a | D34: Juvenilis 2 | E34: 0 | AN34: =COUNTIF(F34:AM34,"1") -> 0 | AO34: =COUNTIF(F34:AM34,"am") -> 0 | AP34: =COUNTIF(F34:AM34,"pm") -> 0 | AQ34: =SUM((COUNTIF(F34:AM34,"1"))+(COUNTIF(F34:AM34,"am"))+(COUNTIF(F34:AM34,"pm"))) -> 0 | AR34: =COUNTIF(F34:AM34,"x") -> 0 | AS34: =SUM(AQ34:AR34) -> 0 | AT34: =COUNTIF(F34:AM34,"NA") -> 0 | BB34: =SUM(AV34:BA34) -> 0 | BG34: =SUM(BE34:BF34) -> 0
A35: 33 | B35: Mees | C35: 40+ a | D35: Maturus/Senilis | E35: 0 | AN35: =COUNTIF(F35:AM35,"1") -> 0 | AO35: =COUNTIF(F35:AM35,"am") -> 0 | AP35: =COUNTIF(F35:AM35,"pm") -> 0 | AQ35: =SUM((COUNTIF(F35:AM35,"1"))+(COUNTIF(F35:AM35,"am"))+(COUNTIF(F35:AM35,"pm"))) -> 0 | AR35: =COUNTIF(F35:AM35,"x") -> 0 | AS35: =SUM(AQ35:AR35) -> 0 | AT35: =COUNTIF(F35:AM35,"NA") -> 0 | BB35: =SUM(AV35:BA35) -> 0 | BG35: =SUM(BE35:BF35) -> 0
A36: 34 | B36: Mees | C36: 39-44 a | D36: Maturus | E36: 0 | AN36: =COUNTIF(F36:AM36,"1") -> 0 | AO36: =COUNTIF(F36:AM36,"am") -> 0 | AP36: =COUNTIF(F36:AM36,"pm") -> 0 | AQ36: =SUM((COUNTIF(F36:AM36,"1"))+(COUNTIF(F36:AM36,"am"))+(COUNTIF(F36:AM36,"pm"))) -> 0 | AR36: =COUNTIF(F36:AM36,"x") -> 0 | AS36: =SUM(AQ36:AR36) -> 0 | AT36: =COUNTIF(F36:AM36,"NA") -> 0 | BB36: =SUM(AV36:BA36) -> 0 | BG36: =SUM(BE36:BF36) -> 0
A37: 35 | B37: Alaealine | C37: 5 a ± 16 k | D37: Infans | E37: 1 | H37: X | I37: 1 | J37: 1 | K37: 1 | L37: 1 | M37: 1 | N37: pm | O37: pm | P37: pm | Q37: pm | R37: 1 | S37: 1 | T37: 1 | U37: X | Y37: X | Z37: 1 | AA37: 1 | AB37: 1 | AC37: 1 | AD37: 1 | AE37: pm | AF37: pm | AG37: 1 | AH37: pm | AI37: 1 | AJ37: 1 | AK37: 1 | AL37: X | AN37: =COUNTIF(F37:AM37,"1") -> 17 | AO37: =COUNTIF(F37:AM37,"am") -> 0 | AP37: =COUNTIF(F37:AM37,"pm") -> 7 | AQ37: =SUM((COUNTIF(F37:AM37,"1"))+(COUNTIF(F37:AM37,"am"))+(COUNTIF(F37:AM37,"pm"))) -> 24 | AR37: =COUNTIF(F37:AM37,"x") -> 4 | AS37: =SUM(AQ37:AR37) -> 28 | AT37: =COUNTIF(F37:AM37,"NA") -> 0 | AU37: 1 | AV37: 1 | BB37: =SUM(AV37:BA37) -> 1 | BE37: 13 | BF37: 4 | BG37: =SUM(BE37:BF37) -> 17
A38: 36 | B38: Mees | C38: 44-50 a | D38: Maturus/Senilis | E38: 0 | AN38: =COUNTIF(F38:AM38,"1") -> 0 | AO38: =COUNTIF(F38:AM38,"am") -> 0 | AP38: =COUNTIF(F38:AM38,"pm") -> 0 | AQ38: =SUM((COUNTIF(F38:AM38,"1"))+(COUNTIF(F38:AM38,"am"))+(COUNTIF(F38:AM38,"pm"))) -> 0 | AR38: =COUNTIF(F38:AM38,"x") -> 0 | AS38: =SUM(AQ38:AR38) -> 0 | AT38: =COUNTIF(F38:AM38,"NA") -> 0 | BB38: =SUM(AV38:BA38) -> 0 | BG38: =SUM(BE38:BF38) -> 0
A39: 37 | B39: Naine | C39: 39-44 a | D39: Maturus | E39: 0 | AN39: =COUNTIF(F39:AM39,"1") -> 0 | AO39: =COUNTIF(F39:AM39,"am") -> 0 | AP39: =COUNTIF(F39:AM39,"pm") -> 0 | AQ39: =SUM((COUNTIF(F39:AM39,"1"))+(COUNTIF(F39:AM39,"am"))+(COUNTIF(F39:AM39,"pm"))) -> 0 | AR39: =COUNTIF(F39:AM39,"x") -> 0 | AS39: =SUM(AQ39:AR39) -> 0 | AT39: =COUNTIF(F39:AM39,"NA") -> 0 | BB39: =SUM(AV39:BA39) -> 0 | BG39: =SUM(BE39:BF39) -> 0
A40: 38 | B40: Naine | C40: 25-40 a | D40: Adultus/Maturus | E40: 0 | AN40: =COUNTIF(F40:AM40,"1") -> 0 | AO40: =COUNTIF(F40:AM40,"am") -> 0 | AP40: =COUNTIF(F40:AM40,"pm") -> 0 | AQ40: =SUM((COUNTIF(F40:AM40,"1"))+(COUNTIF(F40:AM40,"am"))+(COUNTIF(F40:AM40,"pm"))) -> 0 | AR40: =COUNTIF(F40:AM40,"x") -> 0 | AS40: =SUM(AQ40:AR40) -> 0 | AT40: =COUNTIF(F40:AM40,"NA") -> 0 | BB40: =SUM(AV40:BA40) -> 0 | BG40: =SUM(BE40:BF40) -> 0
...

Sheet DC
D1: Hambakivi asukoht ja ulatus
D2: Ülalõug | T2: Alalõug
D3: Parem | L3: Vasak | T3: Parem | AB3: Vasak | AO3: Hambakivi aste | AT3: Hambakivi asukoht
A4: Nr | B4: Sugu | C4: Vanus | D4: 8 | E4: 7 | F4: 6 | G4: 5 | H4: 4 | I4: 3 | J4: 2 | K4: 1 | L4: 1 | M4: 2 | N4: 3 | O4: 4 | P4: 5 | Q4: 6 | R4: 7 | S4: 8 | T4: 8 | U4: 7 | V4: 6 | W4: 5 | X4: 4 | Y4: 3 | Z4: 2 | AA4: 1 | AB4: 1 | AC4: 2 | AD4: 3 | AE4: 4 | AF4: 5 | AG4: 6 | AH4: 7 | AI4: 8 | AK4: DC hammaste arv | AL4: Säil. hammaste arv | AM4: DC hammaste osakaal | AO4: 1 | AP4: 2 | AQ4: 3 | AR4: Kokku | AT4: m | AU4: d | AV4: b | AW4: l | AX4: o | AY4: Kokku
A5: 1 | B5: ♂ | C5: 40-50 a | AK5: =COUNTA(D5:AI5) -> 0 | AL5: =Üldinfo!AN4 -> 1 | AM5: =AK5/AL5 -> 0 | AO5: =LEN(D5&E5&F5&G5&H5&I5&J5&K5&L5&M5&N5&O5&P5&Q5&R5&S5&T5&U5&V5&W5&X5&Y5&Z5&AA5&AB5&AC5&AD5&AE5&AF5&AG5&AH5&AI5)-LEN(SUBSTITUTE(D5&E5&F5&G5&H5&I5&J5&K5&L5&M5&N5&O5&P5&Q5&R5&S5&T5&U5&V5&W5&X5&Y5&Z5&AA5&AB5&AC5&AD5&AE5&AF5&AG5&AH5&AI5,"1","")) -> 0 | AP5: =LEN(D5&E5&F5&G5&H5&I5&J5&K5&L5&M5&N5&O5&P5&Q5&R5&S5&T5&U5&V5&W5&X5&Y5&Z5&AA5&AB5&AC5&AD5&AE5&AF5&AG5&AH5&AI5)-LEN(SUBSTITUTE(D5&E5&F5&G5&H5&I5&J5&K5&L5&M5&N5&O5&P5&Q5&R5&S5&T5&U5&V5&W5&X5&Y5&Z5&AA5&AB5&AC5&AD5&AE5&AF5&AG5&AH5&AI5,"2","")) -> 0 | AQ5: =LEN(D5&E5&F5&G5&H5&I5&J5&K5&L5&M5&N5&O5&P5&Q5&R5&S5&T5&U5&V5&W5&X5&Y5&Z5&AA5&AB5&AC5&AD5&AE5&AF5&AG5&AH5&AI5)-LEN(SUBSTITUTE(D5&E5&F5&G5&H5&I5&J5&K5&L5&M5&N5&O5&P5&Q5&R5&S5&T5&U5&V5&W5&X5&Y5&Z5&AA5&AB5&AC5&AD5&AE5&AF5&AG5&AH5&AI5,"3","")) -> 0 | AR5: =SUM(AO5:AQ5) -> 0 | AT5: =COUNTIF(D5:AI5,"*m*") -> 0 | AU5: =COUNTIF(D5:AI5,"*d*") -> 0 | AV5: =COUNTIF(D5:AI5,"*b*") -> 0 | AW5: =COUNTIF(D5:AI5,"*l*") -> 0 | AX5: =COUNTIF(D5:AI5,"*o*") -> 0 | AY5: =SUM(AT5:AX5) -> 0
A6: 2 | B6: ♀ | C6: 35-45 a | S6: 1d | T6: 1d1l | U6: 1m1l | W6: 1b1m1d1l | X6: 1b1m1d1l | Y6: 1b1m1d1l | AH6: 1b1m1d1l | AI6: 1l1d | AJ6: 1 | AK6: =COUNTA(D6:AI6) -> 8 | AL6: =Üldinfo!AN5 -> 8 | AM6: =AK6/AL6 -> 1 | AO6: =LEN(D6&E6&F6&G6&H6&I6&J6&K6&L6&M6&N6&O6&P6&Q6&R6&S6&T6&U6&V6&W6&X6&Y6&Z6&AA6&AB6&AC6&AD6&AE6&AF6&AG6&AH6&AI6)-LEN(SUBSTITUTE(D6&E6&F6&G6&H6&I6&J6&K6&L6&M6&N6&O6&P6&Q6&R6&S6&T6&U6&V6&W6&X6&Y6&Z6&AA6&AB6&AC6&AD6&AE6&AF6&AG6&AH6&AI6,"1","")) -> 23 | AP6: =LEN(D6&E6&F6&G6&H6&I6&J6&K6&L6&M6&N6&O6&P6&Q6&R6&S6&T6&U6&V6&W6&X6&Y6&Z6&AA6&AB6&AC6&AD6&AE6&AF6&AG6&AH6&AI6)-LEN(SUBSTITUTE(D6&E6&F6&G6&H6&I6&J6&K6&L6&M6&N6&O6&P6&Q6&R6&S6&T6&U6&V6&W6&X6&Y6&Z6&AA6&AB6&AC6&AD6&AE6&AF6&AG6&AH6&AI6,"2","")) -> 0 | AQ6: =LEN(D6&E6&F6&G6&H6&I6&J6&K6&L6&M6&N6&O6&P6&Q6&R6&S6&T6&U6&V6&W6&X6&Y6&Z6&AA6&AB6&AC6&AD6&AE6&AF6&AG6&AH6&AI6)-LEN(SUBSTITUTE(D6&E6&F6&G6&H6&I6&J6&K6&L6&M6&N6&O6&P6&Q6&R6&S6&T6&U6&V6&W6&X6&Y6&Z6&AA6&AB6&AC6&AD6&AE6&AF6&AG6&AH6&AI6,"3","")) -> 0 | AR6: =SUM(AO6:AQ6) -> 23 | AT6: =COUNTIF(D6:AI6,"*m*") -> 5 | AU6: =COUNTIF(D6:AI6,"*d*") -> 7 | AV6: =COUNTIF(D6:AI6,"*b*") -> 4 | AW6: =COUNTIF(D6:AI6,"*l*") -> 7 | AX6: =COUNTIF(D6:AI6,"*o*") -> 0 | AY6: =SUM(AT6:AX6) -> 23
A7: 3 | B7: ♂ | C7: Täisk | AK7: =COUNTA(D7:AI7) -> 0 | AL7: =Üldinfo!AN6 -> 0 | AM7: =AK7/AL7 -> #DIV/0! | AO7: =LEN(D7&E7&F7&G7&H7&I7&J7&K7&L7&M7&N7&O7&P7&Q7&R7&S7&T7&U7&V7&W7&X7&Y7&Z7&AA7&AB7&AC7&AD7&AE7&AF7&AG7&AH7&AI7)-LEN(SUBSTITUTE(D7&E7&F7&G7&H7&I7&J7&K7&L7&M7&N7&O7&P7&Q7&R7&S7&T7&U7&V7&W7&X7&Y7&Z7&AA7&AB7&AC7&AD7&AE7&AF7&AG7&AH7&AI7,"1","")) -> 0 | AP7: =LEN(D7&E7&F7&G7&H7&I7&J7&K7&L7&M7&N7&O7&P7&Q7&R7&S7&T7&U7&V7&W7&X7&Y7&Z7&AA7&AB7&AC7&AD7&AE7&AF7&AG7&AH7&AI7)-LEN(SUBSTITUTE(D7&E7&F7&G7&H7&I7&J7&K7&L7&M7&N7&O7&P7&Q7&R7&S7&T7&U7&V7&W7&X7&Y7&Z7&AA7&AB7&AC7&AD7&AE7&AF7&AG7&AH7&AI7,"2","")) -> 0 | AQ7: =LEN(D7&E7&F7&G7&H7&I7&J7&K7&L7&M7&N7&O7&P7&Q7&R7&S7&T7&U7&V7&W7&X7&Y7&Z7&AA7&AB7&AC7&AD7&AE7&AF7&AG7&AH7&AI7)-LEN(SUBSTITUTE(D7&E7&F7&G7&H7&I7&J7&K7&L7&M7&N7&O7&P7&Q7&R7&S7&T7&U7&V7&W7&X7&Y7&Z7&AA7&AB7&AC7&AD7&AE7&AF7&AG7&AH7&AI7,"3","")) -> 0 | AR7: =SUM(AO7:AQ7) -> 0 | AT7: =COUNTIF(D7:AI7,"*m*") -> 0 | AU7: =COUNTIF(D7:AI7,"*d*") -> 0 | AV7: =COUNTIF(D7:AI7,"*b*") -> 0 | AW7: =COUNTIF(D7:AI7,"*l*") -> 0 | AX7: =COUNTIF(D7:AI7,"*o*") -> 0 | AY7: =SUM(AT7:AX7) -> 0
A8: 4 | B8: ♀ | C8: 18-20 a | F8: 1b | G8: 1b1d | H8: 1m1d | I8: 1b1m1d | J8: 1m1d | K8: 1l | L8: 1l | M8: 1b1m1d | N8: 1b1m | O8: 1b1m | Q8: 1b | R8: 1l | W8: 1m1d | X8: 1m1l | Y8: 1b1m1d1l | Z8: 2b1m1d1l | AA8: 1m1b1l1d | AB8: 1b1m1d1l | AC8: 2b1m1d1l | AD8: 2m1b1d1l | AE8: 1m1d | AF8: 1m | AJ8: 1 | AK8: =COUNTA(D8:AI8) -> 22 | AL8: =Üldinfo!AN7 -> 30 | AM8: =AK8/AL8 -> 0.73333333 | AO8: =LEN(D8&E8&F8&G8&H8&I8&J8&K8&L8&M8&N8&O8&P8&Q8&R8&S8&T8&U8&V8&W8&X8&Y8&Z8&AA8&AB8&AC8&AD8&AE8&AF8&AG8&AH8&AI8)-LEN(SUBSTITUTE(D8&E8&F8&G8&H8&I8&J8&K8&L8&M8&N8&O8&P8&Q8&R8&S8&T8&U8&V8&W8&X8&Y8&Z8&AA8&AB8&AC8&AD8&AE8&AF8&AG8&AH8&AI8,"1","")) -> 49 | AP8: =LEN(D8&E8&F8&G8&H8&I8&J8&K8&L8&M8&N8&O8&P8&Q8&R8&S8&T8&U8&V8&W8&X8&Y8&Z8&AA8&AB8&AC8&AD8&AE8&AF8&AG8&AH8&AI8)-LEN(SUBSTITUTE(D8&E8&F8&G8&H8&I8&J8&K8&L8&M8&N8&O8&P8&Q8&R8&S8&T8&U8&V8&W8&X8&Y8&Z8&AA8&AB8&AC8&AD8&AE8&AF8&AG8&AH8&AI8,"2","")) -> 3 | AQ8: =LEN(D8&E8&F8&G8&H8&I8&J8&K8&L8&M8&N8&O8&P8&Q8&R8&S8&T8&U8&V8&W8&X8&Y8&Z8&AA8&AB8&AC8&AD8&AE8&AF8&AG8&AH8&AI8)-LEN(SUBSTITUTE(D8&E8&F8&G8&H8&I8&J8&K8&L8&M8&N8&O8&P8&Q8&R8&S8&T8&U8&V8&W8&X8&Y8&Z8&AA8&AB8&AC8&AD8&AE8&AF8&AG8&AH8&AI8,"3","")) -> 0 | AR8: =SUM(AO8:AQ8) -> 52 | AT8: =COUNTIF(D8:AI8,"*m*") -> 16 | AU8: =COUNTIF(D8:AI8,"*d*") -> 13 | AV8: =COUNTIF(D8:AI8,"*b*") -> 13 | AW8: =COUNTIF(D8:AI8,"*l*") -> 10 | AX8: =COUNTIF(D8:AI8,"*o*") -> 0 | AY8: =SUM(AT8:AX8) -> 52
A9: 5 | B9: ♀ | C9: 45+ a | G9: 1b | H9: 2b2m2d1l | I9: 1b1m1d1l | J9: 2b1m1d1l | K9: 1l | L9: 1b1m1d1l | M9: 2b2m1d1l | N9: 1d1m1l | O9: 1b1m1d | P9: 1b | R9: 1m1d | U9: 1m1l | X9: 1m1b1d1l | Y9: 2b1m1d1l | Z9: 1m1b1d1l | AA9: 1m1b1d1l | AD9: 1m1d1l | AE9: 1l | AH9: 1m1l | AJ9: 1 | AK9: =COUNTA(D9:AI9) -> 19 | AL9: =Üldinfo!AN8 -> 20 | AM9: =AK9/AL9 -> 0.95 | AO9: =LEN(D9&E9&F9&G9&H9&I9&J9&K9&L9&M9&N9&O9&P9&Q9&R9&S9&T9&U9&V9&W9&X9&Y9&Z9&AA9&AB9&AC9&AD9&AE9&AF9&AG9&AH9&AI9)-LEN(SUBSTITUTE(D9&E9&F9&G9&H9&I9&J9&K9&L9&M9&N9&O9&P9&Q9&R9&S9&T9&U9&V9&W9&X9&Y9&Z9&AA9&AB9&AC9&AD9&AE9&AF9&AG9&AH9&AI9,"1","")) -> 48 | AP9: =LEN(D9&E9&F9&G9&H9&I9&J9&K9&L9&M9&N9&O9&P9&Q9&R9&S9&T9&U9&V9&W9&X9&Y9&Z9&AA9&AB9&AC9&AD9&AE9&AF9&AG9&AH9&AI9)-LEN(SUBSTITUTE(D9&E9&F9&G9&H9&I9&J9&K9&L9&M9&N9&O9&P9&Q9&R9&S9&T9&U9&V9&W9&X9&Y9&Z9&AA9&AB9&AC9&AD9&AE9&AF9&AG9&AH9&AI9,"2","")) -> 7 | AQ9: =LEN(D9&E9&F9&G9&H9&I9&J9&K9&L9&M9&N9&O9&P9&Q9&R9&S9&T9&U9&V9&W9&X9&Y9&Z9&AA9&AB9&AC9&AD9&AE9&AF9&AG9&AH9&AI9)-LEN(SUBSTITUTE(D9&E9&F9&G9&H9&I9&J9&K9&L9&M9&N9&O9&P9&Q9&R9&S9&T9&U9&V9&W9&X9&Y9&Z9&AA9&AB9&AC9&AD9&AE9&AF9&AG9&AH9&AI9,"3","")) -> 0 | AR9: =SUM(AO9:AQ9) -> 55 | AT9: =COUNTIF(D9:AI9,"*m*") -> 15 | AU9: =COUNTIF(D9:AI9,"*d*") -> 13 | AV9: =COUNTIF(D9:AI9,"*b*") -> 12 | AW9: =COUNTIF(D9:AI9,"*l*") -> 15 | AX9: =COUNTIF(D9:AI9,"*o*") -> 0 | AY9: =SUM(AT9:AX9) -> 55
A10: 6 | B10: ♀ | C10: 40-50 a | D10: 1d1l | I10: 1b | J10: 1b | S10: 1l1b1d | U10: 1m1d1l | V10: 1m1b1d1l | W10: 1m1b1d1l | X10: 1m1b1d1l | Y10: 1m1b1d1l | Z10: 1m1d1l | AB10: 1b1d | AC10: 1b1l | AD10: 1b1d1l | AE10: 1m1l | AF10: 1m1b1d1l | AG10: 1m1b1d1l | AJ10: 1 | AK10: =COUNTA(D10:AI10) -> 16 | AL10: =Üldinfo!AN9 -> 18 | AM10: =AK10/AL10 -> 0.88888889 | AO10: =LEN(D10&E10&F10&G10&H10&I10&J10&K10&L10&M10&N10&O10&P10&Q10&R10&S10&T10&U10&V10&W10&X10&Y10&Z10&AA10&AB10&AC10&AD10&AE10&AF10&AG10&AH10&AI10)-LEN(SUBSTITUTE(D10&E10&F10&G10&H10&I10&J10&K10&L10&M10&N10&O10&P10&Q10&R10&S10&T10&U10&V10&W10&X10&Y10&Z10&AA10&AB10&AC10&AD10&AE10&AF10&AG10&AH10&AI10,"1","")) -> 46 | AP10: =LEN(D10&E10&F10&G10&H10&I10&J10&K10&L10&M10&N10&O10&P10&Q10&R10&S10&T10&U10&V10&W10&X10&Y10&Z10&AA10&AB10&AC10&AD10&AE10&AF10&AG10&AH10&AI10)-LEN(SUBSTITUTE(D10&E10&F10&G10&H10&I10&J10&K10&L10&M10&N10&O10&P10&Q10&R10&S10&T10&U10&V10&W10&X10&Y10&Z10&AA10&AB10&AC10&AD10&AE10&AF10&AG10&AH10&AI10,"2","")) -> 0 | AQ10: =LEN(D10&E10&F10&G10&H10&I10&J10&K10&L10&M10&N10&O10&P10&Q10&R10&S10&T10&U10&V10&W10&X10&Y10&Z10&AA10&AB10&AC10&AD10&AE10&AF10&AG10&AH10&AI10)-LEN(SUBSTITUTE(D10&E10&F10&G10&H10&I10&J10&K10&L10&M10&N10&O10&P10&Q10&R10&S10&T10&U10&V10&W10&X10&Y10&Z10&AA10&AB10&AC10&AD10&AE10&AF10&AG10&AH10&AI10,"3","")) -> 0 | AR10: =SUM(AO10:AQ10) -> 46 | AT10: =COUNTIF(D10:AI10,"*m*") -> 9 | AU10: =COUNTIF(D10:AI10,"*d*") -> 12 | AV10: =COUNTIF(D10:AI10,"*b*") -> 12 | AW10: =COUNTIF(D10:AI10,"*l*") -> 13 | AX10: =COUNTIF(D10:AI10,"*o*") -> 0 | AY10: =SUM(AT10:AX10) -> 46
A11: 7 | B11: SA | C11: 12-16 a | F11: 1m | G11: 1m | H11: 1b | L11: 1b | N11: 1m | O11: 1b1m | P11: 1b | Q11: 1b1d | X11: 1b1d | Y11: 1m1b1d1l | Z11: 1m1b1d1l | AA11: 1m1b1d1l | AB11: 1m1b1d1l | AC11: 1m1b1d1l | AD11: 1m1b1d1l | AE11: 1m1l | AJ11: 1 | AK11: =COUNTA(D11:AI11) -> 16 | AL11: =Üldinfo!AN10 -> 26 | AM11: =AK11/AL11 -> 0.61538462 | AO11: =LEN(D11&E11&F11&G11&H11&I11&J11&K11&L11&M11&N11&O11&P11&Q11&R11&S11&T11&U11&V11&W11&X11&Y11&Z11&AA11&AB11&AC11&AD11&AE11&AF11&AG11&AH11&AI11)-LEN(SUBSTITUTE(D11&E11&F11&G11&H11&I11&J11&K11&L11&M11&N11&O11&P11&Q11&R11&S11&T11&U11&V11&W11&X11&Y11&Z11&AA11&AB11&AC11&AD11&AE11&AF11&AG11&AH11&AI11,"1","")) -> 38 | AP11: =LEN(D11&E11&F11&G11&H11&I11&J11&K11&L11&M11&N11&O11&P11&Q11&R11&S11&T11&U11&V11&W11&X11&Y11&Z11&AA11&AB11&AC11&AD11&AE11&AF11&AG11&AH11&AI11)-LEN(SUBSTITUTE(D11&E11&F11&G11&H11&I11&J11&K11&L11&M11&N11&O11&P11&Q11&R11&S11&T11&U11&V11&W11&X11&Y11&Z11&AA11&AB11&AC11&AD11&AE11&AF11&AG11&AH11&AI11,"2","")) -> 0 | AQ11: =LEN(D11&E11&F11&G11&H11&I11&J11&K11&L11&M11&N11&O11&P11&Q11&R11&S11&T11&U11&V11&W11&X11&Y11&Z11&AA11&AB11&AC11&AD11&AE11&AF11&AG11&AH11&AI11)-LEN(SUBSTITUTE(D11&E11&F11&G11&H11&I11&J11&K11&L11&M11&N11&O11&P11&Q11&R11&S11&T11&U11&V11&W11&X11&Y11&Z11&AA11&AB11&AC11&AD11&AE11&AF11&AG11&AH11&AI11,"3","")) -> 0 | AR11: =SUM(AO11:AQ11) -> 38 | AT11: =COUNTIF(D11:AI11,"*m*") -> 11 | AU11: =COUNTIF(D11:AI11,"*d*") -> 8 | AV11: =COUNTIF(D11:AI11,"*b*") -> 12 | AW11: =COUNTIF(D11:AI11,"*l*") -> 7 | AX11: =COUNTIF(D11:AI11,"*o*") -> 0 | AY11: =SUM(AT11:AX11) -> 38
A12: 8 | B12: ♂ | C12: 35-45 a | D12: 1b1d1l | E12: 1b1l | G12: 1b | H12: 1b | I12: 1b1l | L12: 1b | M12: 1m1b1d | N12: 1m1b1d | O12: 1m1b | P12: 1b | S12: 1m1b1d1l | T12: 1l1d | U12: 1m1l | W12: 1m1d1l | X12: 1m1b1d1l | Y12: 1m1b1d1l | Z12: 1m1b1d | AA12: 1m1b1d1l | AB12: 1m1b1d1l | AC12: 1m1b1d1l | AD12: 1m1d1l | AE12: 1m1d1l | AF12: 1m1l | AG12: 1b1d1l | AH12: 1m1d1l | AI12: 1d1l | AJ12: 1 | AK12: =COUNTA(D12:AI12) -> 26 | AL12: =Üldinfo!AN11 -> 31 | AM12: =AK12/AL12 -> 0.83870968 | AO12: =LEN(D12&E12&F12&G12&H12&I12&J12&K12&L12&M12&N12&O12&P12&Q12&R12&S12&T12&U12&V12&W12&X12&Y12&Z12&AA12&AB12&AC12&AD12&AE12&AF12&AG12&AH12&AI12)-LEN(SUBSTITUTE(D12&E12&F12&G12&H12&I12&J12&K12&L12&M12&N12&O12&P12&Q12&R12&S12&T12&U12&V12&W12&X12&Y12&Z12&AA12&AB12&AC12&AD12&AE12&AF12&AG12&AH12&AI12,"1","")) -> 69 | AP12: =LEN(D12&E12&F12&G12&H12&I12&J12&K12&L12&M12&N12&O12&P12&Q12&R12&S12&T12&U12&V12&W12&X12&Y12&Z12&AA12&AB12&AC12&AD12&AE12&AF12&AG12&AH12&AI12)-LEN(SUBSTITUTE(D12&E12&F12&G12&H12&I12&J12&K12&L12&M12&N12&O12&P12&Q12&R12&S12&T12&U12&V12&W12&X12&Y12&Z12&AA12&AB12&AC12&AD12&AE12&AF12&AG12&AH12&AI12,"2","")) -> 0 | AQ12: =LEN(D12&E12&F12&G12&H12&I12&J12&K12&L12&M12&N12&O12&P12&Q12&R12&S12&T12&U12&V12&W12&X12&Y12&Z12&AA12&AB12&AC12&AD12&AE12&AF12&AG12&AH12&AI12)-LEN(SUBSTITUTE(D12&E12&F12&G12&H12&I12&J12&K12&L12&M12&N12&O12&P12&Q12&R12&S12&T12&U12&V12&W12&X12&Y12&Z12&AA12&AB12&AC12&AD12&AE12&AF12&AG12&AH12&AI12,"3","")) -> 0 | AR12: =SUM(AO12:AQ12) -> 69 | AT12: =COUNTIF(D12:AI12,"*m*") -> 16 | AU12: =COUNTIF(D12:AI12,"*d*") -> 17 | AV12: =COUNTIF(D12:AI12,"*b*") -> 18 | AW12: =COUNTIF(D12:AI12,"*l*") -> 18 | AX12: =COUNTIF(D12:AI12,"*o*") -> 0 | AY12: =SUM(AT12:AX12) -> 69
A13: 9 | B13: ♂ | C13: 40-50 a | R13: 1b | S13: 1b1o | AJ13: 1 | AK13: =COUNTA(D13:AI13) -> 2 | AL13: =Üldinfo!AN12 -> 9 | AM13: =AK13/AL13 -> 0.22222222 | AO13: =LEN(D13&E13&F13&G13&H13&I13&J13&K13&L13&M13&N13&O13&P13&Q13&R13&S13&T13&U13&V13&W13&X13&Y13&Z13&AA13&AB13&AC13&AD13&AE13&AF13&AG13&AH13&AI13)-LEN(SUBSTITUTE(D13&E13&F13&G13&H13&I13&J13&K13&L13&M13&N13&O13&P13&Q13&R13&S13&T13&U13&V13&W13&X13&Y13&Z13&AA13&AB13&AC13&AD13&AE13&AF13&AG13&AH13&AI13,"1","")) -> 3 | AP13: =LEN(D13&E13&F13&G13&H13&I13&J13&K13&L13&M13&N13&O13&P13&Q13&R13&S13&T13&U13&V13&W13&X13&Y13&Z13&AA13&AB13&AC13&AD13&AE13&AF13&AG13&AH13&AI13)-LEN(SUBSTITUTE(D13&E13&F13&G13&H13&I13&J13&K13&L13&M13&N13&O13&P13&Q13&R13&S13&T13&U13&V13&W13&X13&Y13&Z13&AA13&AB13&AC13&AD13&AE13&AF13&AG13&AH13&AI13,"2","")) -> 0 | AQ13: =LEN(D13&E13&F13&G13&H13&I13&J13&K13&L13&M13&N13&O13&P13&Q13&R13&S13&T13&U13&V13&W13&X13&Y13&Z13&AA13&AB13&AC13&AD13&AE13&AF13&AG13&AH13&AI13)-LEN(SUBSTITUTE(D13&E13&F13&G13&H13&I13&J13&K13&L13&M13&N13&O13&P13&Q13&R13&S13&T13&U13&V13&W13&X13&Y13&Z13&AA13&AB13&AC13&AD13&AE13&AF13&AG13&AH13&AI13,"3","")) -> 0 | AR13: =SUM(AO13:AQ13) -> 3 | AT13: =COUNTIF(D13:AI13,"*m*") -> 0 | AU13: =COUNTIF(D13:AI13,"*d*") -> 0 | AV13: =COUNTIF(D13:AI13,"*b*") -> 2 | AW13: =COUNTIF(D13:AI13,"*l*") -> 0 | AX13: =COUNTIF(D13:AI13,"*o*") -> 1 | AY13: =SUM(AT13:AX13) -> 3
A14: 10 | B14: ♂ | C14: 45+ a | D14: 2d1m1b1l | E14: 1b1l | G14: 1d | I14: 1m1b1d1l | J14: 1b | R14: 1l | S14: 2d2b2l1m | W14: 1m1b1d | X14: 1m1b1d | Y14: 3b2m1l1d | Z14: 3b1m1d | AB14: 3b3m2l1d | AC14: 3b3d2m1l | AE14: 2b1m1d1l | AF14: 1m1b1d1l | AG14: 1m1b1d | AH14: 1m1b | AJ14: 1 | AK14: =COUNTA(D14:AI14) -> 17 | AL14: =Üldinfo!AN13 -> 22 | AM14: =AK14/AL14 -> 0.77272727 | AO14: =LEN(D14&E14&F14&G14&H14&I14&J14&K14&L14&M14&N14&O14&P14&Q14&R14&S14&T14&U14&V14&W14&X14&Y14&Z14&AA14&AB14&AC14&AD14&AE14&AF14&AG14&AH14&AI14)-LEN(SUBSTITUTE(D14&E14&F14&G14&H14&I14&J14&K14&L14&M14&N14&O14&P14&Q14&R14&S14&T14&U14&V14&W14&X14&Y14&Z14&AA14&AB14&AC14&AD14&AE14&AF14&AG14&AH14&AI14,"1","")) -> 37 | AP14: =LEN(D14&E14&F14&G14&H14&I14&J14&K14&L14&M14&N14&O14&P14&Q14&R14&S14&T14&U14&V14&W14&X14&Y14&Z14&AA14&AB14&AC14&AD14&AE14&AF14&AG14&AH14&AI14)-LEN(SUBSTITUTE(D14&E14&F14&G14&H14&I14&J14&K14&L14&M14&N14&O14&P14&Q14&R14&S14&T14&U14&V14&W14&X14&Y14&Z14&AA14&AB14&AC14&AD14&AE14&AF14&AG14&AH14&AI14,"2","")) -> 8 | AQ14: =LEN(D14&E14&F14&G14&H14&I14&J14&K14&L14&M14&N14&O14&P14&Q14&R14&S14&T14&U14&V14&W14&X14&Y14&Z14&AA14&AB14&AC14&AD14&AE14&AF14&AG14&AH14&AI14)-LEN(SUBSTITUTE(D14&E14&F14&G14&H14&I14&J14&K14&L14&M14&N14&O14&P14&Q14&R14&S14&T14&U14&V14&W14&X14&Y14&Z14&AA14&AB14&AC14&AD14&AE14&AF14&AG14&AH14&AI14,"3","")) -> 6 | AR14: =SUM(AO14:AQ14) -> 51 | AT14: =COUNTIF(D14:AI14,"*m*") -> 13 | AU14: =COUNTIF(D14:AI14,"*d*") -> 13 | AV14: =COUNTIF(D14:AI14,"*b*") -> 15 | AW14: =COUNTIF(D14:AI14,"*l*") -> 10 | AX14: =COUNTIF(D14:AI14,"*o*") -> 0 | AY14: =SUM(AT14:AX14) -> 51
A15: 11 | B15: ♀ | C15: 40+ a | AK15: =COUNTA(D15:AI15) -> 0 | AL15: =Üldinfo!AN14 -> 0 | AM15: =AK15/AL15 -> #DIV/0! | AO15: =LEN(D15&E15&F15&G15&H15&I15&J15&K15&L15&M15&N15&O15&P15&Q15&R15&S15&T15&U15&V15&W15&X15&Y15&Z15&AA15&AB15&AC15&AD15&AE15&AF15&AG15&AH15&AI15)-LEN(SUBSTITUTE(D15&E15&F15&G15&H15&I15&J15&K15&L15&M15&N15&O15&P15&Q15&R15&S15&T15&U15&V15&W15&X15&Y15&Z15&AA15&AB15&AC15&AD15&AE15&AF15&AG15&AH15&AI15,"1","")) -> 0 | AP15: =LEN(D15&E15&F15&G15&H15&I15&J15&K15&L15&M15&N15&O15&P15&Q15&R15&S15&T15&U15&V15&W15&X15&Y15&Z15&AA15&AB15&AC15&AD15&AE15&AF15&AG15&AH15&AI15)-LEN(SUBSTITUTE(D15&E15&F15&G15&H15&I15&J15&K15&L15&M15&N15&O15&P15&Q15&R15&S15&T15&U15&V15&W15&X15&Y15&Z15&AA15&AB15&AC15&AD15&AE15&AF15&AG15&AH15&AI15,"2","")) -> 0 | AQ15: =LEN(D15&E15&F15&G15&H15&I15&J15&K15&L15&M15&N15&O15&P15&Q15&R15&S15&T15&U15&V15&W15&X15&Y15&Z15&AA15&AB15&AC15&AD15&AE15&AF15&AG15&AH15&AI15)-LEN(SUBSTITUTE(D15&E15&F15&G15&H15&I15&J15&K15&L15&M15&N15&O15&P15&Q15&R15&S15&T15&U15&V15&W15&X15&Y15&Z15&AA15&AB15&AC15&AD15&AE15&AF15&AG15&AH15&AI15,"3","")) -> 0 | AR15: =SUM(AO15:AQ15) -> 0 | AT15: =COUNTIF(D15:AI15,"*m*") -> 0 | AU15: =COUNTIF(D15:AI15,"*d*") -> 0 | AV15: =COUNTIF(D15:AI15,"*b*") -> 0 | AW15: =COUNTIF(D15:AI15,"*l*") -> 0 | AX15: =COUNTIF(D15:AI15,"*o*") -> 0 | AY15: =SUM(AT15:AX15) -> 0
A16: 12 | B16: ♂ | C16: 18-19 a | AK16: =COUNTA(D16:AI16) -> 0 | AL16: =Üldinfo!AN15 -> 0 | AM16: =AK16/AL16 -> #DIV/0! | AO16: =LEN(D16&E16&F16&G16&H16&I16&J16&K16&L16&M16&N16&O16&P16&Q16&R16&S16&T16&U16&V16&W16&X16&Y16&Z16&AA16&AB16&AC16&AD16&AE16&AF16&AG16&AH16&AI16)-LEN(SUBSTITUTE(D16&E16&F16&G16&H16&I16&J16&K16&L16&M16&N16&O16&P16&Q16&R16&S16&T16&U16&V16&W16&X16&Y16&Z16&AA16&AB16&AC16&AD16&AE16&AF16&AG16&AH16&AI16,"1","")) -> 0 | AP16: =LEN(D16&E16&F16&G16&H16&I16&J16&K16&L16&M16&N16&O16&P16&Q16&R16&S16&T16&U16&V16&W16&X16&Y16&Z16&AA16&AB16&AC16&AD16&AE16&AF16&AG16&AH16&AI16)-LEN(SUBSTITUTE(D16&E16&F16&G16&H16&I16&J16&K16&L16&M16&N16&O16&P16&Q16&R16&S16&T16&U16&V16&W16&X16&Y16&Z16&AA16&AB16&AC16&AD16&AE16&AF16&AG16&AH16&AI16,"2","")) -> 0 | AQ16: =LEN(D16&E16&F16&G16&H16&I16&J16&K16&L16&M16&N16&O16&P16&Q16&R16&S16&T16&U16&V16&W16&X16&Y16&Z16&AA16&AB16&AC16&AD16&AE16&AF16&AG16&AH16&AI16)-LEN(SUBSTITUTE(D16&E16&F16&G16&H16&I16&J16&K16&L16&M16&N16&O16&P16&Q16&R16&S16&T16&U16&V16&W16&X16&Y16&Z16&AA16&AB16&AC16&AD16&AE16&AF16&AG16&AH16&AI16,"3","")) -> 0 | AR16: =SUM(AO16:AQ16) -> 0 | AT16: =COUNTIF(D16:AI16,"*m*") -> 0 | AU16: =COUNTIF(D16:AI16,"*d*") -> 0 | AV16: =COUNTIF(D16:AI16,"*b*") -> 0 | AW16: =COUNTIF(D16:AI16,"*l*") -> 0 | AX16: =COUNTIF(D16:AI16,"*o*") -> 0 | AY16: =SUM(AT16:AX16) -> 0
A17: 13 | B17: ♂ | C17: 25-35 a | D17: 1b1d1l | E17: 1m1b1l | I17: 3b1l | J17: 1b1l | N17: 3b1d1l | O17: 2b1m1d1l | R17: 2m2l | S17: 1d1l | AJ17: 1 | AK17: =COUNTA(D17:AI17) -> 8 | AL17: =Üldinfo!AN16 -> 8 | AM17: =AK17/AL17 -> 1 | AO17: =LEN(D17&E17&F17&G17&H17&I17&J17&K17&L17&M17&N17&O17&P17&Q17&R17&S17&T17&U17&V17&W17&X17&Y17&Z17&AA17&AB17&AC17&AD17&AE17&AF17&AG17&AH17&AI17)-LEN(SUBSTITUTE(D17&E17&F17&G17&H17&I17&J17&K17&L17&M17&N17&O17&P17&Q17&R17&S17&T17&U17&V17&W17&X17&Y17&Z17&AA17&AB17&AC17&AD17&AE17&AF17&AG17&AH17&AI17,"1","")) -> 16 | AP17: =LEN(D17&E17&F17&G17&H17&I17&J17&K17&L17&M17&N17&O17&P17&Q17&R17&S17&T17&U17&V17&W17&X17&Y17&Z17&AA17&AB17&AC17&AD17&AE17&AF17&AG17&AH17&AI17)-LEN(SUBSTITUTE(D17&E17&F17&G17&H17&I17&J17&K17&L17&M17&N17&O17&P17&Q17&R17&S17&T17&U17&V17&W17&X17&Y17&Z17&AA17&AB17&AC17&AD17&AE17&AF17&AG17&AH17&AI17,"2","")) -> 3 | AQ17: =LEN(D17&E17&F17&G17&H17&I17&J17&K17&L17&M17&N17&O17&P17&Q17&R17&S17&T17&U17&V17&W17&X17&Y17&Z17&AA17&AB17&AC17&AD17&AE17&AF17&AG17&AH17&AI17)-LEN(SUBSTITUTE(D17&E17&F17&G17&H17&I17&J17&K17&L17&M17&N17&O17&P17&Q17&R17&S17&T17&U17&V17&W17&X17&Y17&Z17&AA17&AB17&AC17&AD17&AE17&AF17&AG17&AH17&AI17,"3","")) -> 2 | AR17: =SUM(AO17:AQ17) -> 21 | AT17: =COUNTIF(D17:AI17,"*m*") -> 3 | AU17: =COUNTIF(D17:AI17,"*d*") -> 4 | AV17: =COUNTIF(D17:AI17,"*b*") -> 6 | AW17: =COUNTIF(D17:AI17,"*l*") -> 8 | AX17: =COUNTIF(D17:AI17,"*o*") -> 0 | AY17: =SUM(AT17:AX17) -> 21
A18: 14 | B18: ♀ | C18: 50+ a | D18: 3b2m2d2o1l | E18: 1m1b1d1l1o | I18: 1b | Q18: 1m1b1d1l | S18: 1m1b1d1l1o | W18: 1m1b1l | X18: 1m1b1d1l | Y18: 1m1b1d1l | AB18: 1m1b1d1l | AC18: 1l1d | AD18: 1b1d1l | AE18: 1l1d | AJ18: 1 | AK18: =COUNTA(D18:AI18) -> 12 | AL18: =Üldinfo!AN17 -> 20 | AM18: =AK18/AL18 -> 0.6 | AO18: =LEN(D18&E18&F18&G18&H18&I18&J18&K18&L18&M18&N18&O18&P18&Q18&R18&S18&T18&U18&V18&W18&X18&Y18&Z18&AA18&AB18&AC18&AD18&AE18&AF18&AG18&AH18&AI18)-LEN(SUBSTITUTE(D18&E18&F18&G18&H18&I18&J18&K18&L18&M18&N18&O18&P18&Q18&R18&S18&T18&U18&V18&W18&X18&Y18&Z18&AA18&AB18&AC18&AD18&AE18&AF18&AG18&AH18&AI18,"1","")) -> 38 | AP18: =LEN(D18&E18&F18&G18&H18&I18&J18&K18&L18&M18&N18&O18&P18&Q18&R18&S18&T18&U18&V18&W18&X18&Y18&Z18&AA18&AB18&AC18&AD18&AE18&AF18&AG18&AH18&AI18)-LEN(SUBSTITUTE(D18&E18&F18&G18&H18&I18&J18&K18&L18&M18&N18&O18&P18&Q18&R18&S18&T18&U18&V18&W18&X18&Y18&Z18&AA18&AB18&AC18&AD18&AE18&AF18&AG18&AH18&AI18,"2","")) -> 3 | AQ18: =LEN(D18&E18&F18&G18&H18&I18&J18&K18&L18&M18&N18&O18&P18&Q18&R18&S18&T18&U18&V18&W18&X18&Y18&Z18&AA18&AB18&AC18&AD18&AE18&AF18&AG18&AH18&AI18)-LEN(SUBSTITUTE(D18&E18&F18&G18&H18&I18&J18&K18&L18&M18&N18&O18&P18&Q18&R18&S18&T18&U18&V18&W18&X18&Y18&Z18&AA18&AB18&AC18&AD18&AE18&AF18&AG18&AH18&AI18,"3","")) -> 1 | AR18: =SUM(AO18:AQ18) -> 42 | AT18: =COUNTIF(D18:AI18,"*m*") -> 8 | AU18: =COUNTIF(D18:AI18,"*d*") -> 10 | AV18: =COUNTIF(D18:AI18,"*b*") -> 10 | AW18: =COUNTIF(D18:AI18,"*l*") -> 11 | AX18: =COUNTIF(D18:AI18,"*o*") -> 3 | AY18: =SUM(AT18:AX18) -> 42
A19: 15 | B19: ♂ | C19: 39-44 a | E19: 2m2b2d2l2o | H19: 1d | I19: 2b1l | O19: 2b2d1l | Q19: 2b2l1d | W19: 1m1l | X19: 1m1b1d1l | Y19: 3l1m1b1d | Z19: 3b3l1m1d | AA19: 2b3l | AB19: 1m1b1d3l | AC19: 1m1b1d2l | AD19: 1m1b1d1l | AE19: 1m1b1d2l | AF19: 1m1b1d1l | AJ19: 1 | AK19: =COUNTA(D19:AI19) -> 15 | AL19: =Üldinfo!AN18 -> 16 | AM19: =AK19/AL19 -> 0.9375 | AO19: =LEN(D19&E19&F19&G19&H19&I19&J19&K19&L19&M19&N19&O19&P19&Q19&R19&S19&T19&U19&V19&W19&X19&Y19&Z19&AA19&AB19&AC19&AD19&AE19&AF19&AG19&AH19&AI19)-LEN(SUBSTITUTE(D19&E19&F19&G19&H19&I19&J19&K19&L19&M19&N19&O19&P19&Q19&R19&S19&T19&U19&V19&W19&X19&Y19&Z19&AA19&AB19&AC19&AD19&AE19&AF19&AG19&AH19&AI19,"1","")) -> 32 | AP19: =LEN(D19&E19&F19&G19&H19&I19&J19&K19&L19&M19&N19&O19&P19&Q19&R19&S19&T19&U19&V19&W19&X19&Y19&Z19&AA19&AB19&AC19&AD19&AE19&AF19&AG19&AH19&AI19)-LEN(SUBSTITUTE(D19&E19&F19&G19&H19&I19&J19&K19&L19&M19&N19&O19&P19&Q19&R19&S19&T19&U19&V19&W19&X19&Y19&Z19&AA19&AB19&AC19&AD19&AE19&AF19&AG19&AH19&AI19,"2","")) -> 13 | AQ19: =LEN(D19&E19&F19&G19&H19&I19&J19&K19&L19&M19&N19&O19&P19&Q19&R19&S19&T19&U19&V19&W19&X19&Y19&Z19&AA19&AB19&AC19&AD19&AE19&AF19&AG19&AH19&AI19)-LEN(SUBSTITUTE(D19&E19&F19&G19&H19&I19&J19&K19&L19&M19&N19&O19&P19&Q19&R19&S19&T19&U19&V19&W19&X19&Y19&Z19&AA19&AB19&AC19&AD19&AE19&AF19&AG19&AH19&AI19,"3","")) -> 5 | AR19: =SUM(AO19:AQ19) -> 50 | AT19: =COUNTIF(D19:AI19,"*m*") -> 10 | AU19: =COUNTIF(D19:AI19,"*d*") -> 12 | AV19: =COUNTIF(D19:AI19,"*b*") -> 13 | AW19: =COUNTIF(D19:AI19,"*l*") -> 14 | AX19: =COUNTIF(D19:AI19,"*o*") -> 1 | AY19: =SUM(AT19:AX19) -> 50
A20: 16 | B20: ♀ | C20: 25-35 a | E20: 1b | F20: 1b | G20: 1b1d | H20: 1b | I20: 1b | M20: 1b | N20: 1b1m1d | O20: 1m1d | AJ20: 1 | AK20: =COUNTA(D20:AI20) -> 8 | AL20: =Üldinfo!AN19 -> 28 | AM20: =AK20/AL20 -> 0.28571429 | AO20: =LEN(D20&E20&F20&G20&H20&I20&J20&K20&L20&M20&N20&O20&P20&Q20&R20&S20&T20&U20&V20&W20&X20&Y20&Z20&AA20&AB20&AC20&AD20&AE20&AF20&AG20&AH20&AI20)-LEN(SUBSTITUTE(D20&E20&F20&G20&H20&I20&J20&K20&L20&M20&N20&O20&P20&Q20&R20&S20&T20&U20&V20&W20&X20&Y20&Z20&AA20&AB20&AC20&AD20&AE20&AF20&AG20&AH20&AI20,"1","")) -> 12 | AP20: =LEN(D20&E20&F20&G20&H20&I20&J20&K20&L20&M20&N20&O20&P20&Q20&R20&S20&T20&U20&V20&W20&X20&Y20&Z20&AA20&AB20&AC20&AD20&AE20&AF20&AG20&AH20&AI20)-LEN(SUBSTITUTE(D20&E20&F20&G20&H20&I20&J20&K20&L20&M20&N20&O20&P20&Q20&R20&S20&T20&U20&V20&W20&X20&Y20&Z20&AA20&AB20&AC20&AD20&AE20&AF20&AG20&AH20&AI20,"2","")) -> 0 | AQ20: =LEN(D20&E20&F20&G20&H20&I20&J20&K20&L20&M20&N20&O20&P20&Q20&R20&S20&T20&U20&V20&W20&X20&Y20&Z20&AA20&AB20&AC20&AD20&AE20&AF20&AG20&AH20&AI20)-LEN(SUBSTITUTE(D20&E20&F20&G20&H20&I20&J20&K20&L20&M20&N20&O20&P20&Q20&R20&S20&T20&U20&V20&W20&X20&Y20&Z20&AA20&AB20&AC20&AD20&AE20&AF20&AG20&AH20&AI20,"3","")) -> 0 | AR20: =SUM(AO20:AQ20) -> 12 | AT20: =COUNTIF(D20:AI20,"*m*") -> 2 | AU20: =COUNTIF(D20:AI20,"*d*") -> 3 | AV20: =COUNTIF(D20:AI20,"*b*") -> 7 | AW20: =COUNTIF(D20:AI20,"*l*") -> 0 | AX20: =COUNTIF(D20:AI20,"*o*") -> 0 | AY20: =SUM(AT20:AX20) -> 12
A21: 17 | B21: ♂ | C21: 25-35 a | D21: 1b1d1l | F21: 1b1m1d | H21: 1m1b | I21: 1m1b1d | J21: 1b | K21: 1b | L21: 1b | M21: 1b1d | N21: 2b1m | O21: 1b | P21: 1m1b1d | Q21: 1b1d | S21: 1d | T21: 1m | U21: 1m1b1d1l | V21: 1l1b1d | W21: 1l1b1d | X21: 1b1l | Y21: 1l1m1b | Z21: 1m1b1d1l | AA21: 1m1b1d1l | AB21: 1m1b1d | AC21: 1m1b1d1l | AD21: 1ml1b | AE21: 1m1d | AF21: 1m | AG21: 1b | AH21: 1b | AI21: 1m1b1d1l | AJ21: 1 | AK21: =COUNTA(D21:AI21) -> 29 | AL21: =Üldinfo!AN20 -> 32 | AM21: =AK21/AL21 -> 0.90625 | AO21: =LEN(D21&E21&F21&G21&H21&I21&J21&K21&L21&M21&N21&O21&P21&Q21&R21&S21&T21&U21&V21&W21&X21&Y21&Z21&AA21&AB21&AC21&AD21&AE21&AF21&AG21&AH21&AI21)-LEN(SUBSTITUTE(D21&E21&F21&G21&H21&I21&J21&K21&L21&M21&N21&O21&P21&Q21&R21&S21&T21&U21&V21&W21&X21&Y21&Z21&AA21&AB21&AC21&AD21&AE21&AF21&AG21&AH21&AI21,"1","")) -> 66 | AP21: =LEN(D21&E21&F21&G21&H21&I21&J21&K21&L21&M21&N21&O21&P21&Q21&R21&S21&T21&U21&V21&W21&X21&Y21&Z21&AA21&AB21&AC21&AD21&AE21&AF21&AG21&AH21&AI21)-LEN(SUBSTITUTE(D21&E21&F21&G21&H21&I21&J21&K21&L21&M21&N21&O21&P21&Q21&R21&S21&T21&U21&V21&W21&X21&Y21&Z21&AA21&AB21&AC21&AD21&AE21&AF21&AG21&AH21&AI21,"2","")) -> 1 | AQ21: =LEN(D21&E21&F21&G21&H21&I21&J21&K21&L21&M21&N21&O21&P21&Q21&R21&S21&T21&U21&V21&W21&X21&Y21&Z21&AA21&AB21&AC21&AD21&AE21&AF21&AG21&AH21&AI21)-LEN(SUBSTITUTE(D21&E21&F21&G21&H21&I21&J21&K21&L21&M21&N21&O21&P21&Q21&R21&S21&T21&U21&V21&W21&X21&Y21&Z21&AA21&AB21&AC21&AD21&AE21&AF21&AG21&AH21&AI21,"3","")) -> 0 | AR21: =SUM(AO21:AQ21) -> 67 | AT21: =COUNTIF(D21:AI21,"*m*") -> 16 | AU21: =COUNTIF(D21:AI21,"*d*") -> 16 | AV21: =COUNTIF(D21:AI21,"*b*") -> 25 | AW21: =COUNTIF(D21:AI21,"*l*") -> 11 | AX21: =COUNTIF(D21:AI21,"*o*") -> 0 | AY21: =SUM(AT21:AX21) -> 68
A22: 18 | B22: ♂ | C22: 44-50 a | M22: 1b | O22: 1b | P22: 1b | Q22: 1b | R22: 1b | T22: 1l | U22: 1l | V22: 1l | W22: 1m1d1l | X22: 1m1b1d1l | Y22: 2bm1d1l | Z22: 1m1b1d1l | AA22: 1m1b1d1l | AB22: 1m1b1d1l | AC22: 1m1b1d1l | AD22: 2b1m1d1l | AE22: 1m1l | AF22: 1l | AH22: 1l | AI22: 1l | AJ22: 1 | AK22: =COUNTA(D22:AI22) -> 20 | AL22: =Üldinfo!AN21 -> 25 | AM22: =AK22/AL22 -> 0.8 | AO22: =LEN(D22&E22&F22&G22&H22&I22&J22&K22&L22&M22&N22&O22&P22&Q22&R22&S22&T22&U22&V22&W22&X22&Y22&Z22&AA22&AB22&AC22&AD22&AE22&AF22&AG22&AH22&AI22)-LEN(SUBSTITUTE(D22&E22&F22&G22&H22&I22&J22&K22&L22&M22&N22&O22&P22&Q22&R22&S22&T22&U22&V22&W22&X22&Y22&Z22&AA22&AB22&AC22&AD22&AE22&AF22&AG22&AH22&AI22,"1","")) -> 41 | AP22: =LEN(D22&E22&F22&G22&H22&I22&J22&K22&L22&M22&N22&O22&P22&Q22&R22&S22&T22&U22&V22&W22&X22&Y22&Z22&AA22&AB22&AC22&AD22&AE22&AF22&AG22&AH22&AI22)-LEN(SUBSTITUTE(D22&E22&F22&G22&H22&I22&J22&K22&L22&M22&N22&O22&P22&Q22&R22&S22&T22&U22&V22&W22&X22&Y22&Z22&AA22&AB22&AC22&AD22&AE22&AF22&AG22&AH22&AI22,"2","")) -> 2 | AQ22: =LEN(D22&E22&F22&G22&H22&I22&J22&K22&L22&M22&N22&O22&P22&Q22&R22&S22&T22&U22&V22&W22&X22&Y22&Z22&AA22&AB22&AC22&AD22&AE22&AF22&AG22&AH22&AI22)-LEN(SUBSTITUTE(D22&E22&F22&G22&H22&I22&J22&K22&L22&M22&N22&O22&P22&Q22&R22&S22&T22&U22&V22&W22&X22&Y22&Z22&AA22&AB22&AC22&AD22&AE22&AF22&AG22&AH22&AI22,"3","")) -> 0 | AR22: =SUM(AO22:AQ22) -> 43 | AT22: =COUNTIF(D22:AI22,"*m*") -> 9 | AU22: =COUNTIF(D22:AI22,"*d*") -> 8 | AV22: =COUNTIF(D22:AI22,"*b*") -> 12 | AW22: =COUNTIF(D22:AI22,"*l*") -> 15 | AX22: =COUNTIF(D22:AI22,"*o*") -> 0 | AY22: =SUM(AT22:AX22) -> 44
A23: 19 | B23: ♂ ? | C23: 39-44 a | D23: 1b1d | E23: 1b1d | F23: 1d | G23: 1m1b1d | H23: 1m1b1d | N23: 1b | P23: 1b1d | Q23: 1m1b1d1l | R23: 1m1d | X23: 1l | Y23: 1m1l | Z23: 1m1b1d1l | AA23: 1m1b1d1l | AB23: 1m1b1d1l | AC23: 1mb1l | AD23: 1m1b | AE23: 1b | AG23: 1m1l | AH23: 1m1l | AJ23: 1 | AK23: =COUNTA(D23:AI23) -> 19 | AL23: =Üldinfo!AN22 -> 23 | AM23: =AK23/AL23 -> 0.82608696 | AO23: =LEN(D23&E23&F23&G23&H23&I23&J23&K23&L23&M23&N23&O23&P23&Q23&R23&S23&T23&U23&V23&W23&X23&Y23&Z23&AA23&AB23&AC23&AD23&AE23&AF23&AG23&AH23&AI23)-LEN(SUBSTITUTE(D23&E23&F23&G23&H23&I23&J23&K23&L23&M23&N23&O23&P23&Q23&R23&S23&T23&U23&V23&W23&X23&Y23&Z23&AA23&AB23&AC23&AD23&AE23&AF23&AG23&AH23&AI23,"1","")) -> 44 | AP23: =LEN(D23&E23&F23&G23&H23&I23&J23&K23&L23&M23&N23&O23&P23&Q23&R23&S23&T23&U23&V23&W23&X23&Y23&Z23&AA23&AB23&AC23&AD23&AE23&AF23&AG23&AH23&AI23)-LEN(SUBSTITUTE(D23&E23&F23&G23&H23&I23&J23&K23&L23&M23&N23&O23&P23&Q23&R23&S23&T23&U23&V23&W23&X23&Y23&Z23&AA23&AB23&AC23&AD23&AE23&AF23&AG23&AH23&AI23,"2","")) -> 0 | AQ23: =LEN(D23&E23&F23&G23&H23&I23&J23&K23&L23&M23&N23&O23&P23&Q23&R23&S23&T23&U23&V23&W23&X23&Y23&Z23&AA23&AB23&AC23&AD23&AE23&AF23&AG23&AH23&AI23)-LEN(SUBSTITUTE(D23&E23&F23&G23&H23&I23&J23&K23&L23&M23&N23&O23&P23&Q23&R23&S23&T23&U23&V23&W23&X23&Y23&Z23&AA23&AB23&AC23&AD23&AE23&AF23&AG23&AH23&AI23,"3","")) -> 0 | AR23: =SUM(AO23:AQ23) -> 44 | AT23: =COUNTIF(D23:AI23,"*m*") -> 12 | AU23: =COUNTIF(D23:AI23,"*d*") -> 11 | AV23: =COUNTIF(D23:AI23,"*b*") -> 13 | AW23: =COUNTIF(D23:AI23,"*l*") -> 9 | AX23: =COUNTIF(D23:AI23,"*o*") -> 0 | AY23: =SUM(AT23:AX23) -> 45
A24: 20 | B24: =Üldinfo!B23 -> Mees | C24: =Üldinfo!C23 -> 22-24 a | AK24: =COUNTA(D24:AI24) -> 0 | AL24: =Üldinfo!AN23 -> 0 | AM24: =AK24/AL24 -> #DIV/0! | AO24: =LEN(D24&E24&F24&G24&H24&I24&J24&K24&L24&M24&N24&O24&P24&Q24&R24&S24&T24&U24&V24&W24&X24&Y24&Z24&AA24&AB24&AC24&AD24&AE24&AF24&AG24&AH24&AI24)-LEN(SUBSTITUTE(D24&E24&F24&G24&H24&I24&J24&K24&L24&M24&N24&O24&P24&Q24&R24&S24&T24&U24&V24&W24&X24&Y24&Z24&AA24&AB24&AC24&AD24&AE24&AF24&AG24&AH24&AI24,"1","")) -> 0 | AP24: =LEN(D24&E24&F24&G24&H24&I24&J24&K24&L24&M24&N24&O24&P24&Q24&R24&S24&T24&U24&V24&W24&X24&Y24&Z24&AA24&AB24&AC24&AD24&AE24&AF24&AG24&AH24&AI24)-LEN(SUBSTITUTE(D24&E24&F24&G24&H24&I24&J24&K24&L24&M24&N24&O24&P24&Q24&R24&S24&T24&U24&V24&W24&X24&Y24&Z24&AA24&AB24&AC24&AD24&AE24&AF24&AG24&AH24&AI24,"2","")) -> 0 | AQ24: =LEN(D24&E24&F24&G24&H24&I24&J24&K24&L24&M24&N24&O24&P24&Q24&R24&S24&T24&U24&V24&W24&X24&Y24&Z24&AA24&AB24&AC24&AD24&AE24&AF24&AG24&AH24&AI24)-LEN(SUBSTITUTE(D24&E24&F24&G24&H24&I24&J24&K24&L24&M24&N24&O24&P24&Q24&R24&S24&T24&U24&V24&W24&X24&Y24&Z24&AA24&AB24&AC24&AD24&AE24&AF24&AG24&AH24&AI24,"3","")) -> 0 | AR24: =SUM(AO24:AQ24) -> 0 | AT24: =COUNTIF(D24:AI24,"*m*") -> 0 | AU24: =COUNTIF(D24:AI24,"*d*") -> 0 | AV24: =COUNTIF(D24:AI24,"*b*") -> 0 | AW24: =COUNTIF(D24:AI24,"*l*") -> 0 | AX24: =COUNTIF(D24:AI24,"*o*") -> 0 | AY24: =SUM(AT24:AX24) -> 0
A25: 21 | B25: =Üldinfo!B24 -> Naine | C25: =Üldinfo!C24 -> 40+ a | D25: 1m1b1d1l | E25: 1b1d1l | I25: 1b | J25: 1b1l | K25: 1b | L25: 1b1l | M25: 1b | N25: 1b | R25: 1b | S25: 1m1b1d1l | U25: 1b | X25: 1b | Y25: 1b1l | Z25: 1b1l | AA25: 1b1l | AB25: 1b1l | AC25: 1b | AD25: 1b1l | AE25: 1b1l | AF25: 1b1l | AG25: 1b1d1l | AH25: 1b1m | AK25: =COUNTA(D25:AI25) -> 22 | AL25: =Üldinfo!AN24 -> 29 | AM25: =AK25/AL25 -> 0.75862069 | AO25: =LEN(D25&E25&F25&G25&H25&I25&J25&K25&L25&M25&N25&O25&P25&Q25&R25&S25&T25&U25&V25&W25&X25&Y25&Z25&AA25&AB25&AC25&AD25&AE25&AF25&AG25&AH25&AI25)-LEN(SUBSTITUTE(D25&E25&F25&G25&H25&I25&J25&K25&L25&M25&N25&O25&P25&Q25&R25&S25&T25&U25&V25&W25&X25&Y25&Z25&AA25&AB25&AC25&AD25&AE25&AF25&AG25&AH25&AI25,"1","")) -> 42 | AP25: =LEN(D25&E25&F25&G25&H25&I25&J25&K25&L25&M25&N25&O25&P25&Q25&R25&S25&T25&U25&V25&W25&X25&Y25&Z25&AA25&AB25&AC25&AD25&AE25&AF25&AG25&AH25&AI25)-LEN(SUBSTITUTE(D25&E25&F25&G25&H25&I25&J25&K25&L25&M25&N25&O25&P25&Q25&R25&S25&T25&U25&V25&W25&X25&Y25&Z25&AA25&AB25&AC25&AD25&AE25&AF25&AG25&AH25&AI25,"2","")) -> 0 | AQ25: =LEN(D25&E25&F25&G25&H25&I25&J25&K25&L25&M25&N25&O25&P25&Q25&R25&S25&T25&U25&V25&W25&X25&Y25&Z25&AA25&AB25&AC25&AD25&AE25&AF25&AG25&AH25&AI25)-LEN(SUBSTITUTE(D25&E25&F25&G25&H25&I25&J25&K25&L25&M25&N25&O25&P25&Q25&R25&S25&T25&U25&V25&W25&X25&Y25&Z25&AA25&AB25&AC25&AD25&AE25&AF25&AG25&AH25&AI25,"3","")) -> 0 | AR25: =SUM(AO25:AQ25) -> 42 | AT25: =COUNTIF(D25:AI25,"*m*") -> 3 | AU25: =COUNTIF(D25:AI25,"*d*") -> 4 | AV25: =COUNTIF(D25:AI25,"*b*") -> 22 | AW25: =COUNTIF(D25:AI25,"*l*") -> 13 | AX25: =COUNTIF(D25:AI25,"*o*") -> 0 | AY25: =SUM(AT25:AX25) -> 42
A26: 22 | B26: =Üldinfo!B25 -> Mees ? | C26: =Üldinfo!C25 -> 25-35 a | D26: 1m1b1d | E26: 1m1b1d1l | F26: 1m1b1d1l | G26: 1b | H26: 1m1b | I26: 1b | J26: 1b | K26: 1b1l | L26: 1b1d1l | M26: 1m1b | N26: 1m | O26: 1m | Q26: 1l | R26: 1m1l | S26: 1l | U26: 1b1l | V26: 1m1b1d1l | W26: 1m1b1d1l | X26: 1m1b1d1l | Y26: 1m1b1d1l | Z26: 2b1d1l | AA26: 2b1m1d1l | AB26: 1m1b1d1l | AC26: 1m1b1d1l | AD26: 1m1b1d1l | AE26: 1m1b1d1l | AF26: 1m1d1l | AG26: 1m1b1d1l | AH26: 1m1b1d1l | AI26: 1m1b1l | AJ26: 1 | AK26: =COUNTA(D26:AI26) -> 30 | AL26: =Üldinfo!AN25 -> 31 | AM26: =AK26/AL26 -> 0.96774194 | AO26: =LEN(D26&E26&F26&G26&H26&I26&J26&K26&L26&M26&N26&O26&P26&Q26&R26&S26&T26&U26&V26&W26&X26&Y26&Z26&AA26&AB26&AC26&AD26&AE26&AF26&AG26&AH26&AI26)-LEN(SUBSTITUTE(D26&E26&F26&G26&H26&I26&J26&K26&L26&M26&N26&O26&P26&Q26&R26&S26&T26&U26&V26&W26&X26&Y26&Z26&AA26&AB26&AC26&AD26&AE26&AF26&AG26&AH26&AI26,"1","")) -> 82 | AP26: =LEN(D26&E26&F26&G26&H26&I26&J26&K26&L26&M26&N26&O26&P26&Q26&R26&S26&T26&U26&V26&W26&X26&Y26&Z26&AA26&AB26&AC26&AD26&AE26&AF26&AG26&AH26&AI26)-LEN(SUBSTITUTE(D26&E26&F26&G26&H26&I26&J26&K26&L26&M26&N26&O26&P26&Q26&R26&S26&T26&U26&V26&W26&X26&Y26&Z26&AA26&AB26&AC26&AD26&AE26&AF26&AG26&AH26&AI26,"2","")) -> 2 | AQ26: =LEN(D26&E26&F26&G26&H26&I26&J26&K26&L26&M26&N26&O26&P26&Q26&R26&S26&T26&U26&V26&W26&X26&Y26&Z26&AA26&AB26&AC26&AD26&AE26&AF26&AG26&AH26&AI26)-LEN(SUBSTITUTE(D26&E26&F26&G26&H26&I26&J26&K26&L26&M26&N26&O26&P26&Q26&R26&S26&T26&U26&V26&W26&X26&Y26&Z26&AA26&AB26&AC26&AD26&AE26&AF26&AG26&AH26&AI26,"3","")) -> 0 | AR26: =SUM(AO26:AQ26) -> 84 | AT26: =COUNTIF(D26:AI26,"*m*") -> 21 | AU26: =COUNTIF(D26:AI26,"*d*") -> 17 | AV26: =COUNTIF(D26:AI26,"*b*") -> 24 | AW26: =COUNTIF(D26:AI26,"*l*") -> 22 | AX26: =COUNTIF(D26:AI26,"*o*") -> 0 | AY26: =SUM(AT26:AX26) -> 84
A27: 23 | B27: =Üldinfo!B26 -> Mees | C27: =Üldinfo!C26 -> 50+ a | D27: 1b1d1l | E27: 1m1b | F27: 1m1b1l | G27: 1m1b1d1l | I27: 1b1l | J27: 2b1l | K27: 1m1b1d1l | L27: 1m1b1l | M27: 1m1b1d1l | N27: 1m1b1d1l | P27: 1b | Q27: 1b1l | R27: 1m1b1d1l | T27: 1m1b1d1l | U27: 1m1b1l | V27: 1m1b1d1l | W27: 1m1b1d1l | X27: 1m1b1d1l | Y27: 2b1m1d1l | Z27: 2b1m1d1l | AA27: 1m1b1d1l | AB27: 1m1b1d1l | AC27: 1m1b1d1l | AD27: 1m1b1d1l | AE27: 1m1b1d1l | AF27: 1m1d1l | AG27: 1b1l | AH27: 1b1l | AJ27: 1 | AK27: =COUNTA(D27:AI27) -> 28 | AL27: =Üldinfo!AN26 -> 30 | AM27: =AK27/AL27 -> 0.93333333 | AO27: =LEN(D27&E27&F27&G27&H27&I27&J27&K27&L27&M27&N27&O27&P27&Q27&R27&S27&T27&U27&V27&W27&X27&Y27&Z27&AA27&AB27&AC27&AD27&AE27&AF27&AG27&AH27&AI27)-LEN(SUBSTITUTE(D27&E27&F27&G27&H27&I27&J27&K27&L27&M27&N27&O27&P27&Q27&R27&S27&T27&U27&V27&W27&X27&Y27&Z27&AA27&AB27&AC27&AD27&AE27&AF27&AG27&AH27&AI27,"1","")) -> 89 | AP27: =LEN(D27&E27&F27&G27&H27&I27&J27&K27&L27&M27&N27&O27&P27&Q27&R27&S27&T27&U27&V27&W27&X27&Y27&Z27&AA27&AB27&AC27&AD27&AE27&AF27&AG27&AH27&AI27)-LEN(SUBSTITUTE(D27&E27&F27&G27&H27&I27&J27&K27&L27&M27&N27&O27&P27&Q27&R27&S27&T27&U27&V27&W27&X27&Y27&Z27&AA27&AB27&AC27&AD27&AE27&AF27&AG27&AH27&AI27,"2","")) -> 3 | AQ27: =LEN(D27&E27&F27&G27&H27&I27&J27&K27&L27&M27&N27&O27&P27&Q27&R27&S27&T27&U27&V27&W27&X27&Y27&Z27&AA27&AB27&AC27&AD27&AE27&AF27&AG27&AH27&AI27)-LEN(SUBSTITUTE(D27&E27&F27&G27&H27&I27&J27&K27&L27&M27&N27&O27&P27&Q27&R27&S27&T27&U27&V27&W27&X27&Y27&Z27&AA27&AB27&AC27&AD27&AE27&AF27&AG27&AH27&AI27,"3","")) -> 0 | AR27: =SUM(AO27:AQ27) -> 92 | AT27: =COUNTIF(D27:AI27,"*m*") -> 21 | AU27: =COUNTIF(D27:AI27,"*d*") -> 18 | AV27: =COUNTIF(D27:AI27,"*b*") -> 27 | AW27: =COUNTIF(D27:AI27,"*l*") -> 26 | AX27: =COUNTIF(D27:AI27,"*o*") -> 0 | AY27: =SUM(AT27:AX27) -> 92
