Workbook
Name Excel_BuiltIn__FilterDatabase: AM!$A$4:$AN$76
Name Excel_BuiltIn__FilterDatabase: PA!$A$4:$AN$74
Name Excel_BuiltIn__FilterDatabase: Üldinfo!$A$1:$BB$79

Sheet Üldinfo
E1: Ülalõug | U1: Alalõug
A2: Täida | E2: Parem | M2: Vasak | U2: Parem | AC2: Vasak | AM2: Kontrollarv (automaatne) | AU2: Kas esineb: tühi=ei; 1=jah | BB2: 0 kuni 6 (autom.)
A3: Nr | B3: Sugu | C3: Vanus | D3: Hambaid (1/0) | E3: M3 | F3: M2 | G3: M1 | H3: PM2 | I3: PM1 | J3: C | K3: I2 | L3: I1 | M3: I1 | N3: I2 | O3: C | P3: PM1 | Q3: PM2 | R3: M1 | S3: M2 | T3: M3 | U3: M3 | V3: M2 | W3: M1 | X3: PM2 | Y3: PM1 | Z3: C | AA3: I2 | AB3: I1 | AC3: I1 | AD3: I2 | AE3: C | AF3: PM1 | AG3: PM2 | AH3: M1 | AI3: M2 | AJ3: M3 | AK3: PH | AL3: JH | AM3: Säilinud | AN3: AM | AO3: PM | AQ3: Lõikunud | AR3: Lõikumata | AS3: KOKKU (lõikunud + lõikumata) | AT3: ? = NA | AU3: Kas? (1/0) | AV3: DC | AW3: Kaaries | AX3: DEH | AY3: PA | AZ3: AM | BA3: RED | BB3: Mitu pat. esineb | BD3: Muu hälve suus
A4: 1a | B4: Mees | C4: Täiskasvanu | D4: 0 | AK4: =COUNTIF(E4:AJ4,"PH") -> 0 | AL4: =COUNTIF(E4:AJ4,"1") -> 0 | AM4: =SUM((COUNTIF(E4:AJ4,"1"))+(COUNTIF(E4:AJ4,"PH"))) -> 0 | AN4: =COUNTIF(E4:AJ4,"am") -> 0 | AO4: =COUNTIF(E4:AJ4,"pm") -> 0 | AQ4: =SUM((COUNTIF(E4:AJ4,"1"))+(COUNTIF(E4:AJ4,"am"))+(COUNTIF(E4:AJ4,"pm"))) -> 0 | AR4: =COUNTIF(E4:AJ4,"x") -> 0 | AS4: =SUM(AQ4:AR4) -> 0 | AT4: =COUNTIF(E4:AJ4,"NA") -> 0 | BB4: =SUM(AV4:BA4) -> 0
A5: 1b | B5: Alaealine | C5: Alaealine | D5: 0 | AK5: =COUNTIF(E5:AJ5,"PH") -> 0 | AL5: =COUNTIF(E5:AJ5,"1") -> 0 | AM5: =SUM((COUNTIF(E5:AJ5,"1"))+(COUNTIF(E5:AJ5,"PH"))) -> 0 | AN5: =COUNTIF(E5:AJ5,"am") -> 0 | AO5: =COUNTIF(E5:AJ5,"pm") -> 0 | AQ5: =SUM((COUNTIF(E5:AJ5,"1"))+(COUNTIF(E5:AJ5,"am"))+(COUNTIF(E5:AJ5,"pm"))) -> 0 | AR5: =COUNTIF(E5:AJ5,"x") -> 0 | AS5: =SUM(AQ5:AR5) -> 0 | AT5: =COUNTIF(E5:AJ5,"NA") -> 0 | BB5: =SUM(AV5:BA5) -> 0
A6: 2 | B6: Naine | C6: Täiskasvanu | D6: 0 | AK6: =COUNTIF(E6:AJ6,"PH") -> 0 | AL6: =COUNTIF(E6:AJ6,"1") -> 0 | AM6: =SUM((COUNTIF(E6:AJ6,"1"))+(COUNTIF(E6:AJ6,"PH"))) -> 0 | AN6: =COUNTIF(E6:AJ6,"am") -> 0 | AO6: =COUNTIF(E6:AJ6,"pm") -> 0 | AQ6: =SUM((COUNTIF(E6:AJ6,"1"))+(COUNTIF(E6:AJ6,"am"))+(COUNTIF(E6:AJ6,"pm"))) -> 0 | AR6: =COUNTIF(E6:AJ6,"x") -> 0 | AS6: =SUM(AQ6:AR6) -> 0 | AT6: =COUNTIF(E6:AJ6,"NA") -> 0 | BB6: =SUM(AV6:BA6) -> 0
A7: 3 | B7: Alaealine | C7: 12-18 a | D7: 1 | E7: X | F7: 1 | G7: 1 | H7: 1 | I7: 1 | J7: 1 | K7: 1 | L7: 1 | M7: 1 | N7: pm | O7: pm | P7: 1 | Q7: 1 | R7: 1 | S7: 1 | T7: X | U7: X | V7: 1 | W7: 1 | X7: 1 | Y7: 1 | Z7: 1 | AA7: 1 | AB7: 1 | AC7: 1 | AD7: 1 | AE7: 1 | AF7: 1 | AG7: 1 | AH7: 1 | AI7: 1 | AJ7: X | AK7: =COUNTIF(E7:AJ7,"PH") -> 0 | AL7: =COUNTIF(E7:AJ7,"1") -> 26 | AM7: =SUM((COUNTIF(E7:AJ7,"1"))+(COUNTIF(E7:AJ7,"PH"))) -> 26 | AN7: =COUNTIF(E7:AJ7,"am") -> 0 | AO7: =COUNTIF(E7:AJ7,"pm") -> 2 | AQ7: =SUM((COUNTIF(E7:AJ7,"1"))+(COUNTIF(E7:AJ7,"am"))+(COUNTIF(E7:AJ7,"pm"))) -> 28 | AR7: =COUNTIF(E7:AJ7,"x") -> 4 | AS7: =SUM(AQ7:AR7) -> 32 | AT7: =COUNTIF(E7:AJ7,"NA") -> 0 | AU7: 1 | AX7: 1 | BB7: =SUM(AV7:BA7) -> 1
A8: 4 | B8: Täiskasvanu | C8: Täiskasvanu | D8: 0 | AK8: =COUNTIF(E8:AJ8,"PH") -> 0 | AL8: =COUNTIF(E8:AJ8,"1") -> 0 | AM8: =SUM((COUNTIF(E8:AJ8,"1"))+(COUNTIF(E8:AJ8,"PH"))) -> 0 | AN8: =COUNTIF(E8:AJ8,"am") -> 0 | AO8: =COUNTIF(E8:AJ8,"pm") -> 0 | AQ8: =SUM((COUNTIF(E8:AJ8,"1"))+(COUNTIF(E8:AJ8,"am"))+(COUNTIF(E8:AJ8,"pm"))) -> 0 | AR8: =COUNTIF(E8:AJ8,"x") -> 0 | AS8: =SUM(AQ8:AR8) -> 0 | AT8: =COUNTIF(E8:AJ8,"NA") -> 0 | BB8: =SUM(AV8:BA8) -> 0
A9: 5 | B9: Täiskasvanu | C9: Täiskasvanu | D9: 0 | AK9: =COUNTIF(E9:AJ9,"PH") -> 0 | AL9: =COUNTIF(E9:AJ9,"1") -> 0 | AM9: =SUM((COUNTIF(E9:AJ9,"1"))+(COUNTIF(E9:AJ9,"PH"))) -> 0 | AN9: =COUNTIF(E9:AJ9,"am") -> 0 | AO9: =COUNTIF(E9:AJ9,"pm") -> 0 | AQ9: =SUM((COUNTIF(E9:AJ9,"1"))+(COUNTIF(E9:AJ9,"am"))+(COUNTIF(E9:AJ9,"pm"))) -> 0 | AR9: =COUNTIF(E9:AJ9,"x") -> 0 | AS9: =SUM(AQ9:AR9) -> 0 | AT9: =COUNTIF(E9:AJ9,"NA") -> 0 | BB9: =SUM(AV9:BA9) -> 0
A10: 6 | B10: Täiskasvanu | C10: Täiskasvanu | D10: 0 | AK10: =COUNTIF(E10:AJ10,"PH") -> 0 | AL10: =COUNTIF(E10:AJ10,"1") -> 0 | AM10: =SUM((COUNTIF(E10:AJ10,"1"))+(COUNTIF(E10:AJ10,"PH"))) -> 0 | AN10: =COUNTIF(E10:AJ10,"am") -> 0 | AO10: =COUNTIF(E10:AJ10,"pm") -> 0 | AQ10: =SUM((COUNTIF(E10:AJ10,"1"))+(COUNTIF(E10:AJ10,"am"))+(COUNTIF(E10:AJ10,"pm"))) -> 0 | AR10: =COUNTIF(E10:AJ10,"x") -> 0 | AS10: =SUM(AQ10:AR10) -> 0 | AT10: =COUNTIF(E10:AJ10,"NA") -> 0 | BB10: =SUM(AV10:BA10) -> 0
A11: 7 | B11: Mees | C11: 25-35 a | D11: 1 | E11: 1 | F11: 1 | G11: 1 | H11: 1 | I11: 1 | J11: 1 | K11: 1 | L11: 1 | M11: 1 | N11: 1 | O11: 1 | P11: 1 | Q11: 1 | R11: 1 | S11: 1 | T11: 1 | U11: 1 | V11: 1 | W11: 1 | X11: 1 | Y11: 1 | Z11: 1 | AA11: 1 | AB11: 1 | AC11: 1 | AD11: 1 | AE11: 1 | AF11: 1 | AG11: 1 | AH11: 1 | AI11: 1 | AJ11: 1 | AK11: =COUNTIF(E11:AJ11,"PH") -> 0 | AL11: =COUNTIF(E11:AJ11,"1") -> 32 | AM11: =SUM((COUNTIF(E11:AJ11,"1"))+(COUNTIF(E11:AJ11,"PH"))) -> 32 | AN11: =COUNTIF(E11:AJ11,"am") -> 0 | AO11: =COUNTIF(E11:AJ11,"pm") -> 0 | AQ11: =SUM((COUNTIF(E11:AJ11,"1"))+(COUNTIF(E11:AJ11,"am"))+(COUNTIF(E11:AJ11,"pm"))) -> 32 | AR11: =COUNTIF(E11:AJ11,"x") -> 0 | AS11: =SUM(AQ11:AR11) -> 32 | AT11: =COUNTIF(E11:AJ11,"NA") -> 0 | AU11: 1 | AV11: 1 | AW11: 1 | AX11: 1 | BB11: =SUM(AV11:BA11) -> 3
A12: 8 | B12: Täiskasvanu | C12: Täiskasvanu | D12: 0 | AK12: =COUNTIF(E12:AJ12,"PH") -> 0 | AL12: =COUNTIF(E12:AJ12,"1") -> 0 | AM12: =SUM((COUNTIF(E12:AJ12,"1"))+(COUNTIF(E12:AJ12,"PH"))) -> 0 | AN12: =COUNTIF(E12:AJ12,"am") -> 0 | AO12: =COUNTIF(E12:AJ12,"pm") -> 0 | AQ12: =SUM((COUNTIF(E12:AJ12,"1"))+(COUNTIF(E12:AJ12,"am"))+(COUNTIF(E12:AJ12,"pm"))) -> 0 | AR12: =COUNTIF(E12:AJ12,"x") -> 0 | AS12: =SUM(AQ12:AR12) -> 0 | AT12: =COUNTIF(E12:AJ12,"NA") -> 0 | BB12: =SUM(AV12:BA12) -> 0
A13: 9 | B13: Naine | C13: 25-35 a | D13: 1 | E13: 1 | F13: 1 | G13: 1 | H13: 1 | I13: 1 | J13: 1 | K13: 1 | L13: 1 | M13: 1 | N13: 1 | O13: 1 | P13: 1 | Q13: 1 | R13: 1 | S13: 1 | T13: pm | U13: 1 | V13: 1 | W13: 1 | X13: 1 | Y13: 1 | Z13: 1 | AA13: 1 | AB13: 1 | AC13: 1 | AD13: 1 | AE13: 1 | AF13: 1 | AG13: 1 | AH13: 1 | AI13: 1 | AJ13: 1 | AK13: =COUNTIF(E13:AJ13,"PH") -> 0 | AL13: =COUNTIF(E13:AJ13,"1") -> 31 | AM13: =SUM((COUNTIF(E13:AJ13,"1"))+(COUNTIF(E13:AJ13,"PH"))) -> 31 | AN13: =COUNTIF(E13:AJ13,"am") -> 0 | AO13: =COUNTIF(E13:AJ13,"pm") -> 1 | AQ13: =SUM((COUNTIF(E13:AJ13,"1"))+(COUNTIF(E13:AJ13,"am"))+(COUNTIF(E13:AJ13,"pm"))) -> 32 | AR13: =COUNTIF(E13:AJ13,"x") -> 0 | AS13: =SUM(AQ13:AR13) -> 32 | AT13: =COUNTIF(E13:AJ13,"NA") -> 0 | AU13: 1 | AV13: 1 | AW13: 1 | AX13: 1 | AY13: 1 | BA13: 1 | BB13: =SUM(AV13:BA13) -> 5
A14: 10 | B14: Täiskasvanu | C14: Täiskasvanu | D14: 0 | AK14: =COUNTIF(E14:AJ14,"PH") -> 0 | AL14: =COUNTIF(E14:AJ14,"1") -> 0 | AM14: =SUM((COUNTIF(E14:AJ14,"1"))+(COUNTIF(E14:AJ14,"PH"))) -> 0 | AN14: =COUNTIF(E14:AJ14,"am") -> 0 | AO14: =COUNTIF(E14:AJ14,"pm") -> 0 | AQ14: =SUM((COUNTIF(E14:AJ14,"1"))+(COUNTIF(E14:AJ14,"am"))+(COUNTIF(E14:AJ14,"pm"))) -> 0 | AR14: =COUNTIF(E14:AJ14,"x") -> 0 | AS14: =SUM(AQ14:AR14) -> 0 | AT14: =COUNTIF(E14:AJ14,"NA") -> 0 | BB14: =SUM(AV14:BA14) -> 0
A15: 11 | B15: Täiskasvanu | C15: Täiskasvanu | D15: 0 | AK15: =COUNTIF(E15:AJ15,"PH") -> 0 | AL15: =COUNTIF(E15:AJ15,"1") -> 0 | AM15: =SUM((COUNTIF(E15:AJ15,"1"))+(COUNTIF(E15:AJ15,"PH"))) -> 0 | AN15: =COUNTIF(E15:AJ15,"am") -> 0 | AO15: =COUNTIF(E15:AJ15,"pm") -> 0 | AQ15: =SUM((COUNTIF(E15:AJ15,"1"))+(COUNTIF(E15:AJ15,"am"))+(COUNTIF(E15:AJ15,"pm"))) -> 0 | AR15: =COUNTIF(E15:AJ15,"x") -> 0 | AS15: =SUM(AQ15:AR15) -> 0 | AT15: =COUNTIF(E15:AJ15,"NA") -> 0 | BB15: =SUM(AV15:BA15) -> 0
A16: 12 | B16: Naine | C16: 25-30 a | D16: 1 | J16: 1 | K16: 1 | M16: 1 | N16: 1 | U16: 1 | V16: 1 | W16: 1 | X16: 1 | Y16: 1 | Z16: 1 | AA16: 1 | AB16: 1 | AC16: 1 | AD16: 1 | AE16: pm | AF16: 1 | AG16: 1 | AH16: 1 | AI16: 1 | AJ16: 1 | AK16: =COUNTIF(E16:AJ16,"PH") -> 0 | AL16: =COUNTIF(E16:AJ16,"1") -> 19 | AM16: =SUM((COUNTIF(E16:AJ16,"1"))+(COUNTIF(E16:AJ16,"PH"))) -> 19 | AN16: =COUNTIF(E16:AJ16,"am") -> 0 | AO16: =COUNTIF(E16:AJ16,"pm") -> 1 | AQ16: =SUM((COUNTIF(E16:AJ16,"1"))+(COUNTIF(E16:AJ16,"am"))+(COUNTIF(E16:AJ16,"pm"))) -> 20 | AR16: =COUNTIF(E16:AJ16,"x") -> 0 | AS16: =SUM(AQ16:AR16) -> 20 | AT16: =COUNTIF(E16:AJ16,"NA") -> 0 | AU16: 1 | AV16: 1 | AW16: 1 | BA16: 1 | BB16: =SUM(AV16:BA16) -> 3
A17: 14 | B17: Alaealine | C17: Alaealine | D17: 0 | AK17: =COUNTIF(E17:AJ17,"PH") -> 0 | AL17: =COUNTIF(E17:AJ17,"1") -> 0 | AM17: =SUM((COUNTIF(E17:AJ17,"1"))+(COUNTIF(E17:AJ17,"PH"))) -> 0 | AN17: =COUNTIF(E17:AJ17,"am") -> 0 | AO17: =COUNTIF(E17:AJ17,"pm") -> 0 | AQ17: =SUM((COUNTIF(E17:AJ17,"1"))+(COUNTIF(E17:AJ17,"am"))+(COUNTIF(E17:AJ17,"pm"))) -> 0 | AR17: =COUNTIF(E17:AJ17,"x") -> 0 | AS17: =SUM(AQ17:AR17) -> 0 | AT17: =COUNTIF(E17:AJ17,"NA") -> 0 | BB17: =SUM(AV17:BA17) -> 0
A18: 15 | B18: Täiskasvanu | C18: Täiskasvanu | D18: 0 | AK18: =COUNTIF(E18:AJ18,"PH") -> 0 | AL18: =COUNTIF(E18:AJ18,"1") -> 0 | AM18: =SUM((COUNTIF(E18:AJ18,"1"))+(COUNTIF(E18:AJ18,"PH"))) -> 0 | AN18: =COUNTIF(E18:AJ18,"am") -> 0 | AO18: =COUNTIF(E18:AJ18,"pm") -> 0 | AQ18: =SUM((COUNTIF(E18:AJ18,"1"))+(COUNTIF(E18:AJ18,"am"))+(COUNTIF(E18:AJ18,"pm"))) -> 0 | AR18: =COUNTIF(E18:AJ18,"x") -> 0 | AS18: =SUM(AQ18:AR18) -> 0 | AT18: =COUNTIF(E18:AJ18,"NA") -> 0 | BB18: =SUM(AV18:BA18) -> 0
A19: 16 | B19: Täiskasvanu | C19: Täiskasvanu | D19: 0 | AK19: =COUNTIF(E19:AJ19,"PH") -> 0 | AL19: =COUNTIF(E19:AJ19,"1") -> 0 | AM19: =SUM((COUNTIF(E19:AJ19,"1"))+(COUNTIF(E19:AJ19,"PH"))) -> 0 | AN19: =COUNTIF(E19:AJ19,"am") -> 0 | AO19: =COUNTIF(E19:AJ19,"pm") -> 0 | AQ19: =SUM((COUNTIF(E19:AJ19,"1"))+(COUNTIF(E19:AJ19,"am"))+(COUNTIF(E19:AJ19,"pm"))) -> 0 | AR19: =COUNTIF(E19:AJ19,"x") -> 0 | AS19: =SUM(AQ19:AR19) -> 0 | AT19: =COUNTIF(E19:AJ19,"NA") -> 0 | BB19: =SUM(AV19:BA19) -> 0
A20: 17 | B20: Täiskasvanu | C20: Täiskasvanu | D20: 0 | AK20: =COUNTIF(E20:AJ20,"PH") -> 0 | AL20: =COUNTIF(E20:AJ20,"1") -> 0 | AM20: =SUM((COUNTIF(E20:AJ20,"1"))+(COUNTIF(E20:AJ20,"PH"))) -> 0 | AN20: =COUNTIF(E20:AJ20,"am") -> 0 | AO20: =COUNTIF(E20:AJ20,"pm") -> 0 | AQ20: =SUM((COUNTIF(E20:AJ20,"1"))+(COUNTIF(E20:AJ20,"am"))+(COUNTIF(E20:AJ20,"pm"))) -> 0 | AR20: =COUNTIF(E20:AJ20,"x") -> 0 | AS20: =SUM(AQ20:AR20) -> 0 | AT20: =COUNTIF(E20:AJ20,"NA") -> 0 | BB20: =SUM(AV20:BA20) -> 0
A21: 19 | B21: Mees | C21: Täiskasvanu | D21: 1 | R21: 1 | AK21: =COUNTIF(E21:AJ21,"PH") -> 0 | AL21: =COUNTIF(E21:AJ21,"1") -> 1 | AM21: =SUM((COUNTIF(E21:AJ21,"1"))+(COUNTIF(E21:AJ21,"PH"))) -> 1 | AN21: =COUNTIF(E21:AJ21,"am") -> 0 | AO21: =COUNTIF(E21:AJ21,"pm") -> 0 | AQ21: =SUM((COUNTIF(E21:AJ21,"1"))+(COUNTIF(E21:AJ21,"am"))+(COUNTIF(E21:AJ21,"pm"))) -> 1 | AR21: =COUNTIF(E21:AJ21,"x") -> 0 | AS21: =SUM(AQ21:AR21) -> 1 | AT21: =COUNTIF(E21:AJ21,"NA") -> 0 | AU21: 0 | BB21: =SUM(AV21:BA21) -> 0
A22: 20 | B22: Mees | C22: Täiskasvanu | D22: 1 | T22: 1 | AK22: =COUNTIF(E22:AJ22,"PH") -> 0 | AL22: =COUNTIF(E22:AJ22,"1") -> 1 | AM22: =SUM((COUNTIF(E22:AJ22,"1"))+(COUNTIF(E22:AJ22,"PH"))) -> 1 | AN22: =COUNTIF(E22:AJ22,"am") -> 0 | AO22: =COUNTIF(E22:AJ22,"pm") -> 0 | AQ22: =SUM((COUNTIF(E22:AJ22,"1"))+(COUNTIF(E22:AJ22,"am"))+(COUNTIF(E22:AJ22,"pm"))) -> 1 | AR22: =COUNTIF(E22:AJ22,"x") -> 0 | AS22: =SUM(AQ22:AR22) -> 1 | AT22: =COUNTIF(E22:AJ22,"NA") -> 0 | AU22: 0 | BB22: =SUM(AV22:BA22) -> 0
A23: 21 | B23: Naine | C23: 20-25 a | D23: 1 | E23: 1 | F23: 1 | G23: 1 | H23: 1 | I23: 1 | J23: 1 | K23: 1 | L23: pm | M23: pm | N23: 1 | O23: 1 | P23: 1 | Q23: 1 | R23: 1 | S23: 1 | T23: 1 | U23: 1 | V23: 1 | W23: 1 | X23: 1 | Y23: 1 | Z23: 1 | AA23: 1 | AB23: 1 | AC23: 1 | AD23: 1 | AE23: 1 | AF23: 1 | AG23: 1 | AH23: 1 | AI23: 1 | AJ23: 1 | AK23: =COUNTIF(E23:AJ23,"PH") -> 0 | AL23: =COUNTIF(E23:AJ23,"1") -> 30 | AM23: =SUM((COUNTIF(E23:AJ23,"1"))+(COUNTIF(E23:AJ23,"PH"))) -> 30 | AN23: =COUNTIF(E23:AJ23,"am") -> 0 | AO23: =COUNTIF(E23:AJ23,"pm") -> 2 | AQ23: =SUM((COUNTIF(E23:AJ23,"1"))+(COUNTIF(E23:AJ23,"am"))+(COUNTIF(E23:AJ23,"pm"))) -> 32 | AR23: =COUNTIF(E23:AJ23,"x") -> 0 | AS23: =SUM(AQ23:AR23) -> 32 | AT23: =COUNTIF(E23:AJ23,"NA") -> 0 | AU23: 1 | AV23: 1 | AW23: 1 | AX23: 1 | BB23: =SUM(AV23:BA23) -> 3
A24: 22 | B24: Naine | C24: 17-20 a | D24: 1 | E24: 1 | F24: 1 | G24: 1 | H24: 1 | I24: 1 | J24: 1 | K24: 1 | L24: 1 | M24: pm | N24: 1 | O24: pm | P24: 1 | Q24: 1 | R24: 1 | S24: 1 | T24: 1 | U24: 1 | V24: 1 | W24: 1 | X24: 1 | Y24: 1 | Z24: 1 | AA24: 1 | AB24: 1 | AC24: pm | AD24: 1 | AE24: 1 | AF24: 1 | AG24: 1 | AH24: 1 | AI24: 1 | AJ24: 1 | AK24: =COUNTIF(E24:AJ24,"PH") -> 0 | AL24: =COUNTIF(E24:AJ24,"1") -> 29 | AM24: =SUM((COUNTIF(E24:AJ24,"1"))+(COUNTIF(E24:AJ24,"PH"))) -> 29 | AN24: =COUNTIF(E24:AJ24,"am") -> 0 | AO24: =COUNTIF(E24:AJ24,"pm") -> 3 | AQ24: =SUM((COUNTIF(E24:AJ24,"1"))+(COUNTIF(E24:AJ24,"am"))+(COUNTIF(E24:AJ24,"pm"))) -> 32 | AR24: =COUNTIF(E24:AJ24,"x") -> 0 | AS24: =SUM(AQ24:AR24) -> 32 | AT24: =COUNTIF(E24:AJ24,"NA") -> 0 | AU24: 1 | AV24: 1 | AW24: 1 | BB24: =SUM(AV24:BA24) -> 2 | BD24: 1 | BE24: Ülemise p I2, C1 emailist tükid väljas
A25: 23 | B25: Alaealine | C25: 10 a ± 30k | D25: 1 | E25: X | F25: X | G25: 1 | H25: PH | I25: PH | J25: PH | K25: 1 | L25: 1 | M25: 1 | N25: pm | O25: PH | P25: pm | Q25: PH | R25: 1 | S25: X | T25: X | U25: X | V25: X | W25: 1 | X25: PH | Y25: X | Z25: 1 | AA25: 1 | AB25: 1 | AC25: 1 | AD25: 1 | AE25: 1 | AF25: X | AG25: PH | AH25: 1 | AI25: X | AJ25: X | AK25: =COUNTIF(E25:AJ25,"PH") -> 7 | AL25: =COUNTIF(E25:AJ25,"1") -> 13 | AM25: =SUM((COUNTIF(E25:AJ25,"1"))+(COUNTIF(E25:AJ25,"PH"))) -> 20 | AN25: =COUNTIF(E25:AJ25,"am") -> 0 | AO25: =COUNTIF(E25:AJ25,"pm") -> 2 | AQ25: =SUM((COUNTIF(E25:AJ25,"1"))+(COUNTIF(E25:AJ25,"am"))+(COUNTIF(E25:AJ25,"pm"))+(COUNTIF(E25:AJ25,"PH"))) -> 22 | AR25: =COUNTIF(E25:AJ25,"x") -> 10 | AS25: =SUM(AQ25:AR25) -> 32 | AT25: =COUNTIF(E25:AJ25,"NA") -> 0 | AU25: 1 | AV25: 1 | AX25: 1 | BB25: =SUM(AV25:BA25) -> 2 | BD25: 1 | BE25: Ülemise v I1 emailist tükid väljas
A26: 24 | B26: Mees | C26: 39-44 a | D26: 0 | AK26: =COUNTIF(E26:AJ26,"PH") -> 0 | AL26: =COUNTIF(E26:AJ26,"1") -> 0 | AM26: =SUM((COUNTIF(E26:AJ26,"1"))+(COUNTIF(E26:AJ26,"PH"))) -> 0 | AN26: =COUNTIF(E26:AJ26,"am") -> 0 | AO26: =COUNTIF(E26:AJ26,"pm") -> 0 | AQ26: =SUM((COUNTIF(E26:AJ26,"1"))+(COUNTIF(E26:AJ26,"am"))+(COUNTIF(E26:AJ26,"pm"))) -> 0 | AR26: =COUNTIF(E26:AJ26,"x") -> 0 | AS26: =SUM(AQ26:AR26) -> 0 | AT26: =COUNTIF(E26:AJ26,"NA") -> 0 | BB26: =SUM(AV26:BA26) -> 0
A27: 25 | B27: Alaealine | C27: 7-11 a | D27: 1 | E27: X | F27: X | G27: 1 | H27: PH | I27: PH | J27: PH | K27: 1 | L27: 1 | M27: 1 | N27: 1 | O27: PH | P27: PH | Q27: PH | R27: 1 | S27: X | T27: X | U27: X | V27: X | W27: 1 | X27: PH | Y27: PH | Z27: PH | AA27: 1 | AB27: 1 | AC27: 1 | AD27: 1 | AE27: PH | AF27: PH | AG27: PH | AH27: 1 | AI27: X | AJ27: X | AK27: =COUNTIF(E27:AJ27,"PH") -> 12 | AL27: =COUNTIF(E27:AJ27,"1") -> 12 | AM27: =SUM((COUNTIF(E27:AJ27,"1"))+(COUNTIF(E27:AJ27,"PH"))) -> 24 | AN27: =COUNTIF(E27:AJ27,"am") -> 0 | AO27: =COUNTIF(E27:AJ27,"pm") -> 0 | AQ27: =SUM((COUNTIF(E27:AJ27,"1"))+(COUNTIF(E27:AJ27,"am"))+(COUNTIF(E27:AJ27,"pm"))) -> 12 | AR27: =COUNTIF(E27:AJ27,"x") -> 8 | AS27: =SUM(AQ27:AR27) -> 20 | AT27: =COUNTIF(E27:AJ27,"NA") -> 0 | AU27: 1 | AV27: 1 | AX27: 1 | BB27: =SUM(AV27:BA27) -> 2
A28: 26a | B28: Alaealine | C28: 12-18 a | D28: 0 | AK28: =COUNTIF(E28:AJ28,"PH") -> 0 | AL28: =COUNTIF(E28:AJ28,"1") -> 0 | AM28: =SUM((COUNTIF(E28:AJ28,"1"))+(COUNTIF(E28:AJ28,"PH"))) -> 0 | AN28: =COUNTIF(E28:AJ28,"am") -> 0 | AO28: =COUNTIF(E28:AJ28,"pm") -> 0 | AQ28: =SUM((COUNTIF(E28:AJ28,"1"))+(COUNTIF(E28:AJ28,"am"))+(COUNTIF(E28:AJ28,"pm"))) -> 0 | AR28: =COUNTIF(E28:AJ28,"x") -> 0 | AS28: =SUM(AQ28:AR28) -> 0 | AT28: =COUNTIF(E28:AJ28,"NA") -> 0 | BB28: =SUM(AV28:BA28) -> 0
A29: 26b | B29: Täiskasvanu | C29: Täiskasvanu | D29: 0 | AK29: =COUNTIF(E29:AJ29,"PH") -> 0 | AL29: =COUNTIF(E29:AJ29,"1") -> 0 | AM29: =SUM((COUNTIF(E29:AJ29,"1"))+(COUNTIF(E29:AJ29,"PH"))) -> 0 | AN29: =COUNTIF(E29:AJ29,"am") -> 0 | AO29: =COUNTIF(E29:AJ29,"pm") -> 0 | AQ29: =SUM((COUNTIF(E29:AJ29,"1"))+(COUNTIF(E29:AJ29,"am"))+(COUNTIF(E29:AJ29,"pm"))) -> 0 | AR29: =COUNTIF(E29:AJ29,"x") -> 0 | AS29: =SUM(AQ29:AR29) -> 0 | AT29: =COUNTIF(E29:AJ29,"NA") -> 0 | BB29: =SUM(AV29:BA29) -> 0
A30: 27 | B30: Mees | C30: 40-50 a | D30: 0 | AK30: =COUNTIF(E30:AJ30,"PH") -> 0 | AL30: =COUNTIF(E30:AJ30,"1") -> 0 | AM30: =SUM((COUNTIF(E30:AJ30,"1"))+(COUNTIF(E30:AJ30,"PH"))) -> 0 | AN30: =COUNTIF(E30:AJ30,"am") -> 0 | AO30: =COUNTIF(E30:AJ30,"pm") -> 0 | AQ30: =SUM((COUNTIF(E30:AJ30,"1"))+(COUNTIF(E30:AJ30,"am"))+(COUNTIF(E30:AJ30,"pm"))) -> 0 | AR30: =COUNTIF(E30:AJ30,"x") -> 0 | AS30: =SUM(AQ30:AR30) -> 0 | AT30: =COUNTIF(E30:AJ30,"NA") -> 0 | BB30: =SUM(AV30:BA30) -> 0
A31: 28 | B31: Naine | C31: 25-50 a | D31: 1 | E31: 1 | F31: 1 | G31: 1 | H31: 1 | I31: 1 | J31: 1 | K31: 1 | L31: 1 | M31: 1 | N31: 1 | O31: 1 | P31: 1 | Q31: 1 | R31: 1 | S31: 1 | T31: 1 | V31: 1 | W31: 1 | X31: 1 | Y31: 1 | Z31: 1 | AA31: 1 | AB31: 1 | AC31: 1 | AD31: 1 | AE31: 1 | AF31: 1 | AG31: 1 | AH31: 1 | AI31: 1 | AK31: =COUNTIF(E31:AJ31,"PH") -> 0 | AL31: =COUNTIF(E31:AJ31,"1") -> 30 | AM31: =SUM((COUNTIF(E31:AJ31,"1"))+(COUNTIF(E31:AJ31,"PH"))) -> 30 | AN31: =COUNTIF(E31:AJ31,"am") -> 0 | AO31: =COUNTIF(E31:AJ31,"pm") -> 0 | AQ31: =SUM((COUNTIF(E31:AJ31,"1"))+(COUNTIF(E31:AJ31,"am"))+(COUNTIF(E31:AJ31,"pm"))) -> 30 | AR31: =COUNTIF(E31:AJ31,"x") -> 0 | AS31: =SUM(AQ31:AR31) -> 30 | AT31: =COUNTIF(E31:AJ31,"NA") -> 0 | AU31: 1 | AV31: 1 | AW31: 1 | AX31: 1 | BB31: =SUM(AV31:BA31) -> 3
A32: 29 | B32: Mees | C32: 25-30a | D32: 1 | E32: 1 | F32: 1 | G32: 1 | H32: 1 | I32: 1 | J32: 1 | K32: 1 | L32: 1 | M32: 1 | N32: 1 | O32: 1 | P32: 1 | Q32: 1 | R32: 1 | S32: 1 | T32: 1 | U32: 1 | V32: 1 | W32: 1 | X32: 1 | Y32: 1 | Z32: 1 | AA32: 1 | AB32: 1 | AC32: 1 | AD32: 1 | AE32: 1 | AF32: 1 | AG32: 1 | AH32: 1 | AI32: 1 | AJ32: 1 | AK32: =COUNTIF(E32:AJ32,"PH") -> 0 | AL32: =COUNTIF(E32:AJ32,"1") -> 32 | AM32: =SUM((COUNTIF(E32:AJ32,"1"))+(COUNTIF(E32:AJ32,"PH"))) -> 32 | AN32: =COUNTIF(E32:AJ32,"am") -> 0 | AO32: =COUNTIF(E32:AJ32,"pm") -> 0 | AQ32: =SUM((COUNTIF(E32:AJ32,"1"))+(COUNTIF(E32:AJ32,"am"))+(COUNTIF(E32:AJ32,"pm"))) -> 32 | AR32: =COUNTIF(E32:AJ32,"x") -> 0 | AS32: =SUM(AQ32:AR32) -> 32 | AT32: =COUNTIF(E32:AJ32,"NA") -> 0 | AU32: 1 | AV32: 1 | AX32: 1 | BB32: =SUM(AV32:BA32) -> 2 | BD32: 1 | BE32: Ülemistel p C1, v I1, I2, C1 emailist tükk väljas
A33: 30 | B33: Naine | C33: 17-25 a | D33: 1 | J33: 1 | M33: pm | N33: 1 | O33: 1 | P33: 1 | Q33: pm | R33: pm | S33: pm | T33: pm | U33: 1 | V33: 1 | W33: 1 | X33: 1 | Y33: 1 | Z33: 1 | AA33: 1 | AB33: 1 | AC33: 1 | AD33: 1 | AE33: pm | AF33: pm | AG33: 1 | AH33: 1 | AI33: am | AJ33: 1 | AK33: =COUNTIF(E33:AJ33,"PH") -> 0 | AL33: =COUNTIF(E33:AJ33,"1") -> 17 | AM33: =SUM((COUNTIF(E33:AJ33,"1"))+(COUNTIF(E33:AJ33,"PH"))) -> 17 | AN33: =COUNTIF(E33:AJ33,"am") -> 1 | AO33: =COUNTIF(E33:AJ33,"pm") -> 7 | AQ33: =SUM((COUNTIF(E33:AJ33,"1"))+(COUNTIF(E33:AJ33,"am"))+(COUNTIF(E33:AJ33,"pm"))) -> 25 | AR33: =COUNTIF(E33:AJ33,"x") -> 0 | AS33: =SUM(AQ33:AR33) -> 25 | AT33: =COUNTIF(E33:AJ33,"NA") -> 0 | AU33: 1 | AV33: 1 | AW33: 1 | AX33: 1 | AY33: 1 | AZ33: 1 | BB33: =SUM(AV33:BA33) -> 5
A34: 31 | B34: Alaealine | C34: 5+ a | D34: 0 | AK34: =COUNTIF(E34:AJ34,"PH") -> 0 | AL34: =COUNTIF(E34:AJ34,"1") -> 0 | AM34: =SUM((COUNTIF(E34:AJ34,"1"))+(COUNTIF(E34:AJ34,"PH"))) -> 0 | AN34: =COUNTIF(E34:AJ34,"am") -> 0 | AO34: =COUNTIF(E34:AJ34,"pm") -> 0 | AQ34: =SUM((COUNTIF(E34:AJ34,"1"))+(COUNTIF(E34:AJ34,"am"))+(COUNTIF(E34:AJ34,"pm"))) -> 0 | AR34: =COUNTIF(E34:AJ34,"x") -> 0 | AS34: =SUM(AQ34:AR34) -> 0 | AT34: =COUNTIF(E34:AJ34,"NA") -> 0 | BB34: =SUM(AV34:BA34) -> 0
A35: 32 | B35: Alaealine | C35: 3-5 a | D35: 0 | AK35: =COUNTIF(E35:AJ35,"PH") -> 0 | AL35: =COUNTIF(E35:AJ35,"1") -> 0 | AM35: =SUM((COUNTIF(E35:AJ35,"1"))+(COUNTIF(E35:AJ35,"PH"))) -> 0 | AN35: =COUNTIF(E35:AJ35,"am") -> 0 | AO35: =COUNTIF(E35:AJ35,"pm") -> 0 | AQ35: =SUM((COUNTIF(E35:AJ35,"1"))+(COUNTIF(E35:AJ35,"am"))+(COUNTIF(E35:AJ35,"pm"))) -> 0 | AR35: =COUNTIF(E35:AJ35,"x") -> 0 | AS35: =SUM(AQ35:AR35) -> 0 | AT35: =COUNTIF(E35:AJ35,"NA") -> 0 | BB35: =SUM(AV35:BA35) -> 0
A36: 33 | B36: Alaealine | C36: 1-2 a | D36: 1 | O36: PH | AK36: =COUNTIF(E36:AJ36,"PH") -> 1 | AL36: =COUNTIF(E36:AJ36,"1") -> 0 | AM36: =SUM((COUNTIF(E36:AJ36,"1"))+(COUNTIF(E36:AJ36,"PH"))) -> 1 | AN36: =COUNTIF(E36:AJ36,"am") -> 0 | AO36: =COUNTIF(E36:AJ36,"pm") -> 0 | AQ36: =SUM((COUNTIF(E36:AJ36,"1"))+(COUNTIF(E36:AJ36,"am"))+(COUNTIF(E36:AJ36,"pm"))) -> 0 | AR36: =COUNTIF(E36:AJ36,"x") -> 0 | AS36: =SUM(AQ36:AR36) -> 0 | AT36: =COUNTIF(E36:AJ36,"NA") -> 0 | AU36: 0 | BB36: =SUM(AV36:BA36) -> 0
A37: 34 | B37: Mees ? | C37: Täiskasvanu | D37: 0 | AK37: =COUNTIF(E37:AJ37,"PH") -> 0 | AL37: =COUNTIF(E37:AJ37,"1") -> 0 | AM37: =SUM((COUNTIF(E37:AJ37,"1"))+(COUNTIF(E37:AJ37,"PH"))) -> 0 | AN37: =COUNTIF(E37:AJ37,"am") -> 0 | AO37: =COUNTIF(E37:AJ37,"pm") -> 0 | AQ37: =SUM((COUNTIF(E37:AJ37,"1"))+(COUNTIF(E37:AJ37,"am"))+(COUNTIF(E37:AJ37,"pm"))) -> 0 | AR37: =COUNTIF(E37:AJ37,"x") -> 0 | AS37: =SUM(AQ37:AR37) -> 0 | AT37: =COUNTIF(E37:AJ37,"NA") -> 0 | BB37: =SUM(AV37:BA37) -> 0
A38: 35 | B38: Naine | C38: Täiskasvanu | D38: 0 | AK38: =COUNTIF(E38:AJ38,"PH") -> 0 | AL38: =COUNTIF(E38:AJ38,"1") -> 0 | AM38: =SUM((COUNTIF(E38:AJ38,"1"))+(COUNTIF(E38:AJ38,"PH"))) -> 0 | AN38: =COUNTIF(E38:AJ38,"am") -> 0 | AO38: =COUNTIF(E38:AJ38,"pm") -> 0 | AQ38: =SUM((COUNTIF(E38:AJ38,"1"))+(COUNTIF(E38:AJ38,"am"))+(COUNTIF(E38:AJ38,"pm"))) -> 0 | AR38: =COUNTIF(E38:AJ38,"x") -> 0 | AS38: =SUM(AQ38:AR38) -> 0 | AT38: =COUNTIF(E38:AJ38,"NA") -> 0 | BB38: =SUM(AV38:BA38) -> 0
A39: 36 | B39: Mees ? | C39: 40-50 a | D39: 0 | AK39: =COUNTIF(E39:AJ39,"PH") -> 0 | AL39: =COUNTIF(E39:AJ39,"1") -> 0 | AM39: =SUM((COUNTIF(E39:AJ39,"1"))+(COUNTIF(E39:AJ39,"PH"))) -> 0 | AN39: =COUNTIF(E39:AJ39,"am") -> 0 | AO39: =COUNTIF(E39:AJ39,"pm") -> 0 | AQ39: =SUM((COUNTIF(E39:AJ39,"1"))+(COUNTIF(E39:AJ39,"am"))+(COUNTIF(E39:AJ39,"pm"))) -> 0 | AR39: =COUNTIF(E39:AJ39,"x") -> 0 | AS39: =SUM(AQ39:AR39) -> 0 | AT39: =COUNTIF(E39:AJ39,"NA") -> 0 | BB39: =SUM(AV39:BA39) -> 0
A40: 37 | B40: Alaealine | C40: 12-18 a | D40: 1 | M40: 1 | N40: 1 | O40: 1 | P40: pm | Q40: pm | R40: 1 | S40: pm | T40: 1 | AB40: 1 | AC40: 1 | AD40: 1 | AE40: 1 | AF40: X | AG40: PH | AH40: 1 | AI40: 1 | AK40: =COUNTIF(E40:AJ40,"PH") -> 1 | AL40: =COUNTIF(E40:AJ40,"1") -> 11 | AM40: =SUM((COUNTIF(E40:AJ40,"1"))+(COUNTIF(E40:AJ40,"PH"))) -> 12 | AN40: =COUNTIF(E40:AJ40,"am") -> 0 | AO40: =COUNTIF(E40:AJ40,"pm") -> 3 | AQ40: =SUM((COUNTIF(E40:AJ40,"1"))+(COUNTIF(E40:AJ40,"am"))+(COUNTIF(E40:AJ40,"pm"))) -> 14 | AR40: =COUNTIF(E40:AJ40,"x") -> 1 | AS40: =SUM(AQ40:AR40) -> 15 | AT40: =COUNTIF(E40:AJ40,"NA") -> 0 | AU40: 1 | AV40: 1 | AX40: 1 | BB40: =SUM(AV40:BA40) -> 2
...

Sheet DC
D1: Hambakivi asukoht ja ulatus
D2: Ülalõug | T2: Alalõug | AO2: automaatne | AT2: automaatne
D3: Parem | L3: Vasak | T3: Parem | AB3: Vasak | AK3: autom. | AL3: autom. esilehelt | AM3: autom. | AO3: Hambakivi aste | AT3: Hambakivi asukoht
A4: Nr | B4: Sugu | C4: Vanus | D4: 8 | E4: 7 | F4: 6 | G4: 5 | H4: 4 | I4: 3 | J4: 2 | K4: 1 | L4: 1 | M4: 2 | N4: 3 | O4: 4 | P4: 5 | Q4: 6 | R4: 7 | S4: 8 | T4: 8 | U4: 7 | V4: 6 | W4: 5 | X4: 4 | Y4: 3 | Z4: 2 | AA4: 1 | AB4: 1 | AC4: 2 | AD4: 3 | AE4: 4 | AF4: 5 | AG4: 6 | AH4: 7 | AI4: 8 | AJ4: Kas on hambakivi? Jah=1; ei=tühi | AK4: DC hammaste arv | AL4: Säil. hammaste arv | AM4: DC hammaste osakaal | AO4: 1 | AP4: 2 | AQ4: 3 | AR4: Kokku | AT4: m | AU4: d | AV4: b | AW4: l | AX4: o | AY4: Kokku
A5: =Üldinfo!A4 -> 1a | B5: =Üldinfo!B4 -> Mees | C5: =Üldinfo!C4 -> Täiskasvanu | AK5: =COUNTA(D5:AI5) -> 0 | AL5: =Üldinfo!AM4 -> 0 | AM5: =AK5/AL5 -> #DIV/0! | AO5: =LEN(D5&E5&F5&G5&H5&I5&J5&K5&L5&M5&N5&O5&P5&Q5&R5&S5&T5&U5&V5&W5&X5&Y5&Z5&AA5&AB5&AC5&AD5&AE5&AF5&AG5&AH5&AI5)-LEN(SUBSTITUTE(D5&E5&F5&G5&H5&I5&J5&K5&L5&M5&N5&O5&P5&Q5&R5&S5&T5&U5&V5&W5&X5&Y5&Z5&AA5&AB5&AC5&AD5&AE5&AF5&AG5&AH5&AI5,"1","")) -> 0 | AP5: =LEN(D5&E5&F5&G5&H5&I5&J5&K5&L5&M5&N5&O5&P5&Q5&R5&S5&T5&U5&V5&W5&X5&Y5&Z5&AA5&AB5&AC5&AD5&AE5&AF5&AG5&AH5&AI5)-LEN(SUBSTITUTE(D5&E5&F5&G5&H5&I5&J5&K5&L5&M5&N5&O5&P5&Q5&R5&S5&T5&U5&V5&W5&X5&Y5&Z5&AA5&AB5&AC5&AD5&AE5&AF5&AG5&AH5&AI5,"2","")) -> 0 | AQ5: =LEN(D5&E5&F5&G5&H5&I5&J5&K5&L5&M5&N5&O5&P5&Q5&R5&S5&T5&U5&V5&W5&X5&Y5&Z5&AA5&AB5&AC5&AD5&AE5&AF5&AG5&AH5&AI5)-LEN(SUBSTITUTE(D5&E5&F5&G5&H5&I5&J5&K5&L5&M5&N5&O5&P5&Q5&R5&S5&T5&U5&V5&W5&X5&Y5&Z5&AA5&AB5&AC5&AD5&AE5&AF5&AG5&AH5&AI5,"3","")) -> 0 | AR5: =SUM(AO5:AQ5) -> 0 | AT5: =COUNTIF(D5:AI5,"*m*") -> 0 | AU5: =COUNTIF(D5:AI5,"*d*") -> 0 | AV5: =COUNTIF(D5:AI5,"*b*") -> 0 | AW5: =COUNTIF(D5:AI5,"*l*") -> 0 | AX5: =COUNTIF(D5:AI5,"*o*") -> 0 | AY5: =SUM(AT5:AX5) -> 0
A6: =Üldinfo!A5 -> 1b | B6: =Üldinfo!B5 -> Alaealine | C6: =Üldinfo!C5 -> Alaealine | AK6: =COUNTA(D6:AI6) -> 0 | AL6: =Üldinfo!AM5 -> 0 | AM6: =AK6/AL6 -> #DIV/0! | AO6: =LEN(D6&E6&F6&G6&H6&I6&J6&K6&L6&M6&N6&O6&P6&Q6&R6&S6&T6&U6&V6&W6&X6&Y6&Z6&AA6&AB6&AC6&AD6&AE6&AF6&AG6&AH6&AI6)-LEN(SUBSTITUTE(D6&E6&F6&G6&H6&I6&J6&K6&L6&M6&N6&O6&P6&Q6&R6&S6&T6&U6&V6&W6&X6&Y6&Z6&AA6&AB6&AC6&AD6&AE6&AF6&AG6&AH6&AI6,"1","")) -> 0 | AP6: =LEN(D6&E6&F6&G6&H6&I6&J6&K6&L6&M6&N6&O6&P6&Q6&R6&S6&T6&U6&V6&W6&X6&Y6&Z6&AA6&AB6&AC6&AD6&AE6&AF6&AG6&AH6&AI6)-LEN(SUBSTITUTE(D6&E6&F6&G6&H6&I6&J6&K6&L6&M6&N6&O6&P6&Q6&R6&S6&T6&U6&V6&W6&X6&Y6&Z6&AA6&AB6&AC6&AD6&AE6&AF6&AG6&AH6&AI6,"2","")) -> 0 | AQ6: =LEN(D6&E6&F6&G6&H6&I6&J6&K6&L6&M6&N6&O6&P6&Q6&R6&S6&T6&U6&V6&W6&X6&Y6&Z6&AA6&AB6&AC6&AD6&AE6&AF6&AG6&AH6&AI6)-LEN(SUBSTITUTE(D6&E6&F6&G6&H6&I6&J6&K6&L6&M6&N6&O6&P6&Q6&R6&S6&T6&U6&V6&W6&X6&Y6&Z6&AA6&AB6&AC6&AD6&AE6&AF6&AG6&AH6&AI6,"3","")) -> 0 | AR6: =SUM(AO6:AQ6) -> 0 | AT6: =COUNTIF(D6:AI6,"*m*") -> 0 | AU6: =COUNTIF(D6:AI6,"*d*") -> 0 | AV6: =COUNTIF(D6:AI6,"*b*") -> 0 | AW6: =COUNTIF(D6:AI6,"*l*") -> 0 | AX6: =COUNTIF(D6:AI6,"*o*") -> 0 | AY6: =SUM(AT6:AX6) -> 0
A7: =Üldinfo!A6 -> 2 | B7: =Üldinfo!B6 -> Naine | C7: =Üldinfo!C6 -> Täiskasvanu | AK7: =COUNTA(D7:AI7) -> 0 | AL7: =Üldinfo!AM6 -> 0 | AM7: =AK7/AL7 -> #DIV/0! | AO7: =LEN(D7&E7&F7&G7&H7&I7&J7&K7&L7&M7&N7&O7&P7&Q7&R7&S7&T7&U7&V7&W7&X7&Y7&Z7&AA7&AB7&AC7&AD7&AE7&AF7&AG7&AH7&AI7)-LEN(SUBSTITUTE(D7&E7&F7&G7&H7&I7&J7&K7&L7&M7&N7&O7&P7&Q7&R7&S7&T7&U7&V7&W7&X7&Y7&Z7&AA7&AB7&AC7&AD7&AE7&AF7&AG7&AH7&AI7,"1","")) -> 0 | AP7: =LEN(D7&E7&F7&G7&H7&I7&J7&K7&L7&M7&N7&O7&P7&Q7&R7&S7&T7&U7&V7&W7&X7&Y7&Z7&AA7&AB7&AC7&AD7&AE7&AF7&AG7&AH7&AI7)-LEN(SUBSTITUTE(D7&E7&F7&G7&H7&I7&J7&K7&L7&M7&N7&O7&P7&Q7&R7&S7&T7&U7&V7&W7&X7&Y7&Z7&AA7&AB7&AC7&AD7&AE7&AF7&AG7&AH7&AI7,"2","")) -> 0 | AQ7: =LEN(D7&E7&F7&G7&H7&I7&J7&K7&L7&M7&N7&O7&P7&Q7&R7&S7&T7&U7&V7&W7&X7&Y7&Z7&AA7&AB7&AC7&AD7&AE7&AF7&AG7&AH7&AI7)-LEN(SUBSTITUTE(D7&E7&F7&G7&H7&I7&J7&K7&L7&M7&N7&O7&P7&Q7&R7&S7&T7&U7&V7&W7&X7&Y7&Z7&AA7&AB7&AC7&AD7&AE7&AF7&AG7&AH7&AI7,"3","")) -> 0 | AR7: =SUM(AO7:AQ7) -> 0 | AT7: =COUNTIF(D7:AI7,"*m*") -> 0 | AU7: =COUNTIF(D7:AI7,"*d*") -> 0 | AV7: =COUNTIF(D7:AI7,"*b*") -> 0 | AW7: =COUNTIF(D7:AI7,"*l*") -> 0 | AX7: =COUNTIF(D7:AI7,"*o*") -> 0 | AY7: =SUM(AT7:AX7) -> 0
A8: =Üldinfo!A7 -> 3 | B8: =Üldinfo!B7 -> Alaealine | C8: =Üldinfo!C7 -> 12-18 a | AK8: =COUNTA(D8:AI8) -> 0 | AL8: =Üldinfo!AM7 -> 26 | AM8: =AK8/AL8 -> 0 | AO8: =LEN(D8&E8&F8&G8&H8&I8&J8&K8&L8&M8&N8&O8&P8&Q8&R8&S8&T8&U8&V8&W8&X8&Y8&Z8&AA8&AB8&AC8&AD8&AE8&AF8&AG8&AH8&AI8)-LEN(SUBSTITUTE(D8&E8&F8&G8&H8&I8&J8&K8&L8&M8&N8&O8&P8&Q8&R8&S8&T8&U8&V8&W8&X8&Y8&Z8&AA8&AB8&AC8&AD8&AE8&AF8&AG8&AH8&AI8,"1","")) -> 0 | AP8: =LEN(D8&E8&F8&G8&H8&I8&J8&K8&L8&M8&N8&O8&P8&Q8&R8&S8&T8&U8&V8&W8&X8&Y8&Z8&AA8&AB8&AC8&AD8&AE8&AF8&AG8&AH8&AI8)-LEN(SUBSTITUTE(D8&E8&F8&G8&H8&I8&J8&K8&L8&M8&N8&O8&P8&Q8&R8&S8&T8&U8&V8&W8&X8&Y8&Z8&AA8&AB8&AC8&AD8&AE8&AF8&AG8&AH8&AI8,"2","")) -> 0 | AQ8: =LEN(D8&E8&F8&G8&H8&I8&J8&K8&L8&M8&N8&O8&P8&Q8&R8&S8&T8&U8&V8&W8&X8&Y8&Z8&AA8&AB8&AC8&AD8&AE8&AF8&AG8&AH8&AI8)-LEN(SUBSTITUTE(D8&E8&F8&G8&H8&I8&J8&K8&L8&M8&N8&O8&P8&Q8&R8&S8&T8&U8&V8&W8&X8&Y8&Z8&AA8&AB8&AC8&AD8&AE8&AF8&AG8&AH8&AI8,"3","")) -> 0 | AR8: =SUM(AO8:AQ8) -> 0 | AT8: =COUNTIF(D8:AI8,"*m*") -> 0 | AU8: =COUNTIF(D8:AI8,"*d*") -> 0 | AV8: =COUNTIF(D8:AI8,"*b*") -> 0 | AW8: =COUNTIF(D8:AI8,"*l*") -> 0 | AX8: =COUNTIF(D8:AI8,"*o*") -> 0 | AY8: =SUM(AT8:AX8) -> 0
A9: =Üldinfo!A8 -> 4 | B9: =Üldinfo!B8 -> Täiskasvanu | C9: =Üldinfo!C8 -> Täiskasvanu | AK9: =COUNTA(D9:AI9) -> 0 | AL9: =Üldinfo!AM8 -> 0 | AM9: =AK9/AL9 -> #DIV/0! | AO9: =LEN(D9&E9&F9&G9&H9&I9&J9&K9&L9&M9&N9&O9&P9&Q9&R9&S9&T9&U9&V9&W9&X9&Y9&Z9&AA9&AB9&AC9&AD9&AE9&AF9&AG9&AH9&AI9)-LEN(SUBSTITUTE(D9&E9&F9&G9&H9&I9&J9&K9&L9&M9&N9&O9&P9&Q9&R9&S9&T9&U9&V9&W9&X9&Y9&Z9&AA9&AB9&AC9&AD9&AE9&AF9&AG9&AH9&AI9,"1","")) -> 0 | AP9: =LEN(D9&E9&F9&G9&H9&I9&J9&K9&L9&M9&N9&O9&P9&Q9&R9&S9&T9&U9&V9&W9&X9&Y9&Z9&AA9&AB9&AC9&AD9&AE9&AF9&AG9&AH9&AI9)-LEN(SUBSTITUTE(D9&E9&F9&G9&H9&I9&J9&K9&L9&M9&N9&O9&P9&Q9&R9&S9&T9&U9&V9&W9&X9&Y9&Z9&AA9&AB9&AC9&AD9&AE9&AF9&AG9&AH9&AI9,"2","")) -> 0 | AQ9: =LEN(D9&E9&F9&G9&H9&I9&J9&K9&L9&M9&N9&O9&P9&Q9&R9&S9&T9&U9&V9&W9&X9&Y9&Z9&AA9&AB9&AC9&AD9&AE9&AF9&AG9&AH9&AI9)-LEN(SUBSTITUTE(D9&E9&F9&G9&H9&I9&J9&K9&L9&M9&N9&O9&P9&Q9&R9&S9&T9&U9&V9&W9&X9&Y9&Z9&AA9&AB9&AC9&AD9&AE9&AF9&AG9&AH9&AI9,"3","")) -> 0 | AR9: =SUM(AO9:AQ9) -> 0 | AT9: =COUNTIF(D9:AI9,"*m*") -> 0 | AU9: =COUNTIF(D9:AI9,"*d*") -> 0 | AV9: =COUNTIF(D9:AI9,"*b*") -> 0 | AW9: =COUNTIF(D9:AI9,"*l*") -> 0 | AX9: =COUNTIF(D9:AI9,"*o*") -> 0 | AY9: =SUM(AT9:AX9) -> 0
A10: =Üldinfo!A9 -> 5 | B10: =Üldinfo!B9 -> Täiskasvanu | C10: =Üldinfo!C9 -> Täiskasvanu | AK10: =COUNTA(D10:AI10) -> 0 | AL10: =Üldinfo!AM9 -> 0 | AM10: =AK10/AL10 -> #DIV/0! | AO10: =LEN(D10&E10&F10&G10&H10&I10&J10&K10&L10&M10&N10&O10&P10&Q10&R10&S10&T10&U10&V10&W10&X10&Y10&Z10&AA10&AB10&AC10&AD10&AE10&AF10&AG10&AH10&AI10)-LEN(SUBSTITUTE(D10&E10&F10&G10&H10&I10&J10&K10&L10&M10&N10&O10&P10&Q10&R10&S10&T10&U10&V10&W10&X10&Y10&Z10&AA10&AB10&AC10&AD10&AE10&AF10&AG10&AH10&AI10,"1","")) -> 0 | AP10: =LEN(D10&E10&F10&G10&H10&I10&J10&K10&L10&M10&N10&O10&P10&Q10&R10&S10&T10&U10&V10&W10&X10&Y10&Z10&AA10&AB10&AC10&AD10&AE10&AF10&AG10&AH10&AI10)-LEN(SUBSTITUTE(D10&E10&F10&G10&H10&I10&J10&K10&L10&M10&N10&O10&P10&Q10&R10&S10&T10&U10&V10&W10&X10&Y10&Z10&AA10&AB10&AC10&AD10&AE10&AF10&AG10&AH10&AI10,"2","")) -> 0 | AQ10: =LEN(D10&E10&F10&G10&H10&I10&J10&K10&L10&M10&N10&O10&P10&Q10&R10&S10&T10&U10&V10&W10&X10&Y10&Z10&AA10&AB10&AC10&AD10&AE10&AF10&AG10&AH10&AI10)-LEN(SUBSTITUTE(D10&E10&F10&G10&H10&I10&J10&K10&L10&M10&N10&O10&P10&Q10&R10&S10&T10&U10&V10&W10&X10&Y10&Z10&AA10&AB10&AC10&AD10&AE10&AF10&AG10&AH10&AI10,"3","")) -> 0 | AR10: =SUM(AO10:AQ10) -> 0 | AT10: =COUNTIF(D10:AI10,"*m*") -> 0 | AU10: =COUNTIF(D10:AI10,"*d*") -> 0 | AV10: =COUNTIF(D10:AI10,"*b*") -> 0 | AW10: =COUNTIF(D10:AI10,"*l*") -> 0 | AX10: =COUNTIF(D10:AI10,"*o*") -> 0 | AY10: =SUM(AT10:AX10) -> 0
A11: =Üldinfo!A10 -> 6 | B11: =Üldinfo!B10 -> Täiskasvanu | C11: =Üldinfo!C10 -> Täiskasvanu | AK11: =COUNTA(D11:AI11) -> 0 | AL11: =Üldinfo!AM10 -> 0 | AM11: =AK11/AL11 -> #DIV/0! | AO11: =LEN(D11&E11&F11&G11&H11&I11&J11&K11&L11&M11&N11&O11&P11&Q11&R11&S11&T11&U11&V11&W11&X11&Y11&Z11&AA11&AB11&AC11&AD11&AE11&AF11&AG11&AH11&AI11)-LEN(SUBSTITUTE(D11&E11&F11&G11&H11&I11&J11&K11&L11&M11&N11&O11&P11&Q11&R11&S11&T11&U11&V11&W11&X11&Y11&Z11&AA11&AB11&AC11&AD11&AE11&AF11&AG11&AH11&AI11,"1","")) -> 0 | AP11: =LEN(D11&E11&F11&G11&H11&I11&J11&K11&L11&M11&N11&O11&P11&Q11&R11&S11&T11&U11&V11&W11&X11&Y11&Z11&AA11&AB11&AC11&AD11&AE11&AF11&AG11&AH11&AI11)-LEN(SUBSTITUTE(D11&E11&F11&G11&H11&I11&J11&K11&L11&M11&N11&O11&P11&Q11&R11&S11&T11&U11&V11&W11&X11&Y11&Z11&AA11&AB11&AC11&AD11&AE11&AF11&AG11&AH11&AI11,"2","")) -> 0 | AQ11: =LEN(D11&E11&F11&G11&H11&I11&J11&K11&L11&M11&N11&O11&P11&Q11&R11&S11&T11&U11&V11&W11&X11&Y11&Z11&AA11&AB11&AC11&AD11&AE11&AF11&AG11&AH11&AI11)-LEN(SUBSTITUTE(D11&E11&F11&G11&H11&I11&J11&K11&L11&M11&N11&O11&P11&Q11&R11&S11&T11&U11&V11&W11&X11&Y11&Z11&AA11&AB11&AC11&AD11&AE11&AF11&AG11&AH11&AI11,"3","")) -> 0 | AR11: =SUM(AO11:AQ11) -> 0 | AT11: =COUNTIF(D11:AI11,"*m*") -> 0 | AU11: =COUNTIF(D11:AI11,"*d*") -> 0 | AV11: =COUNTIF(D11:AI11,"*b*") -> 0 | AW11: =COUNTIF(D11:AI11,"*l*") -> 0 | AX11: =COUNTIF(D11:AI11,"*o*") -> 0 | AY11: =SUM(AT11:AX11) -> 0
A12: =Üldinfo!A11 -> 7 | B12: =Üldinfo!B11 -> Mees | C12: =Üldinfo!C11 -> 25-35 a | E12: 1m | F12: 1b | H12: 1b | I12: 1b1m | J12: 1b | K12: 1b | L12: 1b | M12: 1b | O12: 1b | P12: 1d | R12: 1b | W12: 1m1b1d1l | X12: 1m1b1d1l | Y12: 2b1m1d1l | Z12: 2b1m1d1l | AA12: 2b1m1d1l | AB12: 2b1m1d1l | AC12: 3b1m1d1l | AD12: 1m1b1d1l | AE12: 1m1b1d1l | AF12: 1b | AK12: =COUNTA(D12:AI12) -> 21 | AL12: =Üldinfo!AM11 -> 32 | AM12: =AK12/AL12 -> 0.65625 | AO12: =LEN(D12&E12&F12&G12&H12&I12&J12&K12&L12&M12&N12&O12&P12&Q12&R12&S12&T12&U12&V12&W12&X12&Y12&Z12&AA12&AB12&AC12&AD12&AE12&AF12&AG12&AH12&AI12)-LEN(SUBSTITUTE(D12&E12&F12&G12&H12&I12&J12&K12&L12&M12&N12&O12&P12&Q12&R12&S12&T12&U12&V12&W12&X12&Y12&Z12&AA12&AB12&AC12&AD12&AE12&AF12&AG12&AH12&AI12,"1","")) -> 44 | AP12: =LEN(D12&E12&F12&G12&H12&I12&J12&K12&L12&M12&N12&O12&P12&Q12&R12&S12&T12&U12&V12&W12&X12&Y12&Z12&AA12&AB12&AC12&AD12&AE12&AF12&AG12&AH12&AI12)-LEN(SUBSTITUTE(D12&E12&F12&G12&H12&I12&J12&K12&L12&M12&N12&O12&P12&Q12&R12&S12&T12&U12&V12&W12&X12&Y12&Z12&AA12&AB12&AC12&AD12&AE12&AF12&AG12&AH12&AI12,"2","")) -> 4 | AQ12: =LEN(D12&E12&F12&G12&H12&I12&J12&K12&L12&M12&N12&O12&P12&Q12&R12&S12&T12&U12&V12&W12&X12&Y12&Z12&AA12&AB12&AC12&AD12&AE12&AF12&AG12&AH12&AI12)-LEN(SUBSTITUTE(D12&E12&F12&G12&H12&I12&J12&K12&L12&M12&N12&O12&P12&Q12&R12&S12&T12&U12&V12&W12&X12&Y12&Z12&AA12&AB12&AC12&AD12&AE12&AF12&AG12&AH12&AI12,"3","")) -> 1 | AR12: =SUM(AO12:AQ12) -> 49 | AT12: =COUNTIF(D12:AI12,"*m*") -> 11 | AU12: =COUNTIF(D12:AI12,"*d*") -> 10 | AV12: =COUNTIF(D12:AI12,"*b*") -> 19 | AW12: =COUNTIF(D12:AI12,"*l*") -> 9 | AX12: =COUNTIF(D12:AI12,"*o*") -> 0 | AY12: =SUM(AT12:AX12) -> 49
A13: =Üldinfo!A12 -> 8 | B13: =Üldinfo!B12 -> Täiskasvanu | C13: =Üldinfo!C12 -> Täiskasvanu | AK13: =COUNTA(D13:AI13) -> 0 | AL13: =Üldinfo!AM12 -> 0 | AM13: =AK13/AL13 -> #DIV/0! | AO13: =LEN(D13&E13&F13&G13&H13&I13&J13&K13&L13&M13&N13&O13&P13&Q13&R13&S13&T13&U13&V13&W13&X13&Y13&Z13&AA13&AB13&AC13&AD13&AE13&AF13&AG13&AH13&AI13)-LEN(SUBSTITUTE(D13&E13&F13&G13&H13&I13&J13&K13&L13&M13&N13&O13&P13&Q13&R13&S13&T13&U13&V13&W13&X13&Y13&Z13&AA13&AB13&AC13&AD13&AE13&AF13&AG13&AH13&AI13,"1","")) -> 0 | AP13: =LEN(D13&E13&F13&G13&H13&I13&J13&K13&L13&M13&N13&O13&P13&Q13&R13&S13&T13&U13&V13&W13&X13&Y13&Z13&AA13&AB13&AC13&AD13&AE13&AF13&AG13&AH13&AI13)-LEN(SUBSTITUTE(D13&E13&F13&G13&H13&I13&J13&K13&L13&M13&N13&O13&P13&Q13&R13&S13&T13&U13&V13&W13&X13&Y13&Z13&AA13&AB13&AC13&AD13&AE13&AF13&AG13&AH13&AI13,"2","")) -> 0 | AQ13: =LEN(D13&E13&F13&G13&H13&I13&J13&K13&L13&M13&N13&O13&P13&Q13&R13&S13&T13&U13&V13&W13&X13&Y13&Z13&AA13&AB13&AC13&AD13&AE13&AF13&AG13&AH13&AI13)-LEN(SUBSTITUTE(D13&E13&F13&G13&H13&I13&J13&K13&L13&M13&N13&O13&P13&Q13&R13&S13&T13&U13&V13&W13&X13&Y13&Z13&AA13&AB13&AC13&AD13&AE13&AF13&AG13&AH13&AI13,"3","")) -> 0 | AR13: =SUM(AO13:AQ13) -> 0 | AT13: =COUNTIF(D13:AI13,"*m*") -> 0 | AU13: =COUNTIF(D13:AI13,"*d*") -> 0 | AV13: =COUNTIF(D13:AI13,"*b*") -> 0 | AW13: =COUNTIF(D13:AI13,"*l*") -> 0 | AX13: =COUNTIF(D13:AI13,"*o*") -> 0 | AY13: =SUM(AT13:AX13) -> 0
A14: =Üldinfo!A13 -> 9 | B14: =Üldinfo!B13 -> Naine | C14: =Üldinfo!C13 -> 25-35 a | D14: 1m | E14: 1d | K14: 1b1d | R14: 1d | Y14: 1m1b1d1l | Z14: 1m1b1d1l | AA14: 1b | AD14: 1b | AG14: 1b | AK14: =COUNTA(D14:AI14) -> 9 | AL14: =Üldinfo!AM13 -> 31 | AM14: =AK14/AL14 -> 0.29032258 | AO14: =LEN(D14&E14&F14&G14&H14&I14&J14&K14&L14&M14&N14&O14&P14&Q14&R14&S14&T14&U14&V14&W14&X14&Y14&Z14&AA14&AB14&AC14&AD14&AE14&AF14&AG14&AH14&AI14)-LEN(SUBSTITUTE(D14&E14&F14&G14&H14&I14&J14&K14&L14&M14&N14&O14&P14&Q14&R14&S14&T14&U14&V14&W14&X14&Y14&Z14&AA14&AB14&AC14&AD14&AE14&AF14&AG14&AH14&AI14,"1","")) -> 16 | AP14: =LEN(D14&E14&F14&G14&H14&I14&J14&K14&L14&M14&N14&O14&P14&Q14&R14&S14&T14&U14&V14&W14&X14&Y14&Z14&AA14&AB14&AC14&AD14&AE14&AF14&AG14&AH14&AI14)-LEN(SUBSTITUTE(D14&E14&F14&G14&H14&I14&J14&K14&L14&M14&N14&O14&P14&Q14&R14&S14&T14&U14&V14&W14&X14&Y14&Z14&AA14&AB14&AC14&AD14&AE14&AF14&AG14&AH14&AI14,"2","")) -> 0 | AQ14: =LEN(D14&E14&F14&G14&H14&I14&J14&K14&L14&M14&N14&O14&P14&Q14&R14&S14&T14&U14&V14&W14&X14&Y14&Z14&AA14&AB14&AC14&AD14&AE14&AF14&AG14&AH14&AI14)-LEN(SUBSTITUTE(D14&E14&F14&G14&H14&I14&J14&K14&L14&M14&N14&O14&P14&Q14&R14&S14&T14&U14&V14&W14&X14&Y14&Z14&AA14&AB14&AC14&AD14&AE14&AF14&AG14&AH14&AI14,"3","")) -> 0 | AR14: =SUM(AO14:AQ14) -> 16 | AT14: =COUNTIF(D14:AI14,"*m*") -> 3 | AU14: =COUNTIF(D14:AI14,"*d*") -> 5 | AV14: =COUNTIF(D14:AI14,"*b*") -> 6 | AW14: =COUNTIF(D14:AI14,"*l*") -> 2 | AX14: =COUNTIF(D14:AI14,"*o*") -> 0 | AY14: =SUM(AT14:AX14) -> 16
A15: =Üldinfo!A14 -> 10 | B15: =Üldinfo!B14 -> Täiskasvanu | C15: =Üldinfo!C14 -> Täiskasvanu | AK15: =COUNTA(D15:AI15) -> 0 | AL15: =Üldinfo!AM14 -> 0 | AM15: =AK15/AL15 -> #DIV/0! | AO15: =LEN(D15&E15&F15&G15&H15&I15&J15&K15&L15&M15&N15&O15&P15&Q15&R15&S15&T15&U15&V15&W15&X15&Y15&Z15&AA15&AB15&AC15&AD15&AE15&AF15&AG15&AH15&AI15)-LEN(SUBSTITUTE(D15&E15&F15&G15&H15&I15&J15&K15&L15&M15&N15&O15&P15&Q15&R15&S15&T15&U15&V15&W15&X15&Y15&Z15&AA15&AB15&AC15&AD15&AE15&AF15&AG15&AH15&AI15,"1","")) -> 0 | AP15: =LEN(D15&E15&F15&G15&H15&I15&J15&K15&L15&M15&N15&O15&P15&Q15&R15&S15&T15&U15&V15&W15&X15&Y15&Z15&AA15&AB15&AC15&AD15&AE15&AF15&AG15&AH15&AI15)-LEN(SUBSTITUTE(D15&E15&F15&G15&H15&I15&J15&K15&L15&M15&N15&O15&P15&Q15&R15&S15&T15&U15&V15&W15&X15&Y15&Z15&AA15&AB15&AC15&AD15&AE15&AF15&AG15&AH15&AI15,"2","")) -> 0 | AQ15: =LEN(D15&E15&F15&G15&H15&I15&J15&K15&L15&M15&N15&O15&P15&Q15&R15&S15&T15&U15&V15&W15&X15&Y15&Z15&AA15&AB15&AC15&AD15&AE15&AF15&AG15&AH15&AI15)-LEN(SUBSTITUTE(D15&E15&F15&G15&H15&I15&J15&K15&L15&M15&N15&O15&P15&Q15&R15&S15&T15&U15&V15&W15&X15&Y15&Z15&AA15&AB15&AC15&AD15&AE15&AF15&AG15&AH15&AI15,"3","")) -> 0 | AR15: =SUM(AO15:AQ15) -> 0 | AT15: =COUNTIF(D15:AI15,"*m*") -> 0 | AU15: =COUNTIF(D15:AI15,"*d*") -> 0 | AV15: =COUNTIF(D15:AI15,"*b*") -> 0 | AW15: =COUNTIF(D15:AI15,"*l*") -> 0 | AX15: =COUNTIF(D15:AI15,"*o*") -> 0 | AY15: =SUM(AT15:AX15) -> 0
A16: =Üldinfo!A15 -> 11 | B16: =Üldinfo!B15 -> Täiskasvanu | C16: =Üldinfo!C15 -> Täiskasvanu | AK16: =COUNTA(D16:AI16) -> 0 | AL16: =Üldinfo!AM15 -> 0 | AM16: =AK16/AL16 -> #DIV/0! | AO16: =LEN(D16&E16&F16&G16&H16&I16&J16&K16&L16&M16&N16&O16&P16&Q16&R16&S16&T16&U16&V16&W16&X16&Y16&Z16&AA16&AB16&AC16&AD16&AE16&AF16&AG16&AH16&AI16)-LEN(SUBSTITUTE(D16&E16&F16&G16&H16&I16&J16&K16&L16&M16&N16&O16&P16&Q16&R16&S16&T16&U16&V16&W16&X16&Y16&Z16&AA16&AB16&AC16&AD16&AE16&AF16&AG16&AH16&AI16,"1","")) -> 0 | AP16: =LEN(D16&E16&F16&G16&H16&I16&J16&K16&L16&M16&N16&O16&P16&Q16&R16&S16&T16&U16&V16&W16&X16&Y16&Z16&AA16&AB16&AC16&AD16&AE16&AF16&AG16&AH16&AI16)-LEN(SUBSTITUTE(D16&E16&F16&G16&H16&I16&J16&K16&L16&M16&N16&O16&P16&Q16&R16&S16&T16&U16&V16&W16&X16&Y16&Z16&AA16&AB16&AC16&AD16&AE16&AF16&AG16&AH16&AI16,"2","")) -> 0 | AQ16: =LEN(D16&E16&F16&G16&H16&I16&J16&K16&L16&M16&N16&O16&P16&Q16&R16&S16&T16&U16&V16&W16&X16&Y16&Z16&AA16&AB16&AC16&AD16&AE16&AF16&AG16&AH16&AI16)-LEN(SUBSTITUTE(D16&E16&F16&G16&H16&I16&J16&K16&L16&M16&N16&O16&P16&Q16&R16&S16&T16&U16&V16&W16&X16&Y16&Z16&AA16&AB16&AC16&AD16&AE16&AF16&AG16&AH16&AI16,"3","")) -> 0 | AR16: =SUM(AO16:AQ16) -> 0 | AT16: =COUNTIF(D16:AI16,"*m*") -> 0 | AU16: =COUNTIF(D16:AI16,"*d*") -> 0 | AV16: =COUNTIF(D16:AI16,"*b*") -> 0 | AW16: =COUNTIF(D16:AI16,"*l*") -> 0 | AX16: =COUNTIF(D16:AI16,"*o*") -> 0 | AY16: =SUM(AT16:AX16) -> 0
A17: =Üldinfo!A16 -> 12 | B17: =Üldinfo!B16 -> Naine | C17: =Üldinfo!C16 -> 25-30 a | I17: 1b | Z17: 1b | AA17: 1b | AB17: 1b | AC17: 1b | AK17: =COUNTA(D17:AI17) -> 5 | AL17: =Üldinfo!AM16 -> 19 | AM17: =AK17/AL17 -> 0.26315789 | AO17: =LEN(D17&E17&F17&G17&H17&I17&J17&K17&L17&M17&N17&O17&P17&Q17&R17&S17&T17&U17&V17&W17&X17&Y17&Z17&AA17&AB17&AC17&AD17&AE17&AF17&AG17&AH17&AI17)-LEN(SUBSTITUTE(D17&E17&F17&G17&H17&I17&J17&K17&L17&M17&N17&O17&P17&Q17&R17&S17&T17&U17&V17&W17&X17&Y17&Z17&AA17&AB17&AC17&AD17&AE17&AF17&AG17&AH17&AI17,"1","")) -> 5 | AP17: =LEN(D17&E17&F17&G17&H17&I17&J17&K17&L17&M17&N17&O17&P17&Q17&R17&S17&T17&U17&V17&W17&X17&Y17&Z17&AA17&AB17&AC17&AD17&AE17&AF17&AG17&AH17&AI17)-LEN(SUBSTITUTE(D17&E17&F17&G17&H17&I17&J17&K17&L17&M17&N17&O17&P17&Q17&R17&S17&T17&U17&V17&W17&X17&Y17&Z17&AA17&AB17&AC17&AD17&AE17&AF17&AG17&AH17&AI17,"2","")) -> 0 | AQ17: =LEN(D17&E17&F17&G17&H17&I17&J17&K17&L17&M17&N17&O17&P17&Q17&R17&S17&T17&U17&V17&W17&X17&Y17&Z17&AA17&AB17&AC17&AD17&AE17&AF17&AG17&AH17&AI17)-LEN(SUBSTITUTE(D17&E17&F17&G17&H17&I17&J17&K17&L17&M17&N17&O17&P17&Q17&R17&S17&T17&U17&V17&W17&X17&Y17&Z17&AA17&AB17&AC17&AD17&AE17&AF17&AG17&AH17&AI17,"3","")) -> 0 | AR17: =SUM(AO17:AQ17) -> 5 | AT17: =COUNTIF(D17:AI17,"*m*") -> 0 | AU17: =COUNTIF(D17:AI17,"*d*") -> 0 | AV17: =COUNTIF(D17:AI17,"*b*") -> 5 | AW17: =COUNTIF(D17:AI17,"*l*") -> 0 | AX17: =COUNTIF(D17:AI17,"*o*") -> 0 | AY17: =SUM(AT17:AX17) -> 5
A18: =Üldinfo!A17 -> 14 | B18: =Üldinfo!B17 -> Alaealine | C18: =Üldinfo!C17 -> Alaealine | AK18: =COUNTA(D18:AI18) -> 0 | AL18: =Üldinfo!AM17 -> 0 | AM18: =AK18/AL18 -> #DIV/0! | AO18: =LEN(D18&E18&F18&G18&H18&I18&J18&K18&L18&M18&N18&O18&P18&Q18&R18&S18&T18&U18&V18&W18&X18&Y18&Z18&AA18&AB18&AC18&AD18&AE18&AF18&AG18&AH18&AI18)-LEN(SUBSTITUTE(D18&E18&F18&G18&H18&I18&J18&K18&L18&M18&N18&O18&P18&Q18&R18&S18&T18&U18&V18&W18&X18&Y18&Z18&AA18&AB18&AC18&AD18&AE18&AF18&AG18&AH18&AI18,"1","")) -> 0 | AP18: =LEN(D18&E18&F18&G18&H18&I18&J18&K18&L18&M18&N18&O18&P18&Q18&R18&S18&T18&U18&V18&W18&X18&Y18&Z18&AA18&AB18&AC18&AD18&AE18&AF18&AG18&AH18&AI18)-LEN(SUBSTITUTE(D18&E18&F18&G18&H18&I18&J18&K18&L18&M18&N18&O18&P18&Q18&R18&S18&T18&U18&V18&W18&X18&Y18&Z18&AA18&AB18&AC18&AD18&AE18&AF18&AG18&AH18&AI18,"2","")) -> 0 | AQ18: =LEN(D18&E18&F18&G18&H18&I18&J18&K18&L18&M18&N18&O18&P18&Q18&R18&S18&T18&U18&V18&W18&X18&Y18&Z18&AA18&AB18&AC18&AD18&AE18&AF18&AG18&AH18&AI18)-LEN(SUBSTITUTE(D18&E18&F18&G18&H18&I18&J18&K18&L18&M18&N18&O18&P18&Q18&R18&S18&T18&U18&V18&W18&X18&Y18&Z18&AA18&AB18&AC18&AD18&AE18&AF18&AG18&AH18&AI18,"3","")) -> 0 | AR18: =SUM(AO18:AQ18) -> 0 | AT18: =COUNTIF(D18:AI18,"*m*") -> 0 | AU18: =COUNTIF(D18:AI18,"*d*") -> 0 | AV18: =COUNTIF(D18:AI18,"*b*") -> 0 | AW18: =COUNTIF(D18:AI18,"*l*") -> 0 | AX18: =COUNTIF(D18:AI18,"*o*") -> 0 | AY18: =SUM(AT18:AX18) -> 0
A19: =Üldinfo!A18 -> 15 | B19: =Üldinfo!B18 -> Täiskasvanu | C19: =Üldinfo!C18 -> Täiskasvanu | AK19: =COUNTA(D19:AI19) -> 0 | AL19: =Üldinfo!AM18 -> 0 | AM19: =AK19/AL19 -> #DIV/0! | AO19: =LEN(D19&E19&F19&G19&H19&I19&J19&K19&L19&M19&N19&O19&P19&Q19&R19&S19&T19&U19&V19&W19&X19&Y19&Z19&AA19&AB19&AC19&AD19&AE19&AF19&AG19&AH19&AI19)-LEN(SUBSTITUTE(D19&E19&F19&G19&H19&I19&J19&K19&L19&M19&N19&O19&P19&Q19&R19&S19&T19&U19&V19&W19&X19&Y19&Z19&AA19&AB19&AC19&AD19&AE19&AF19&AG19&AH19&AI19,"1","")) -> 0 | AP19: =LEN(D19&E19&F19&G19&H19&I19&J19&K19&L19&M19&N19&O19&P19&Q19&R19&S19&T19&U19&V19&W19&X19&Y19&Z19&AA19&AB19&AC19&AD19&AE19&AF19&AG19&AH19&AI19)-LEN(SUBSTITUTE(D19&E19&F19&G19&H19&I19&J19&K19&L19&M19&N19&O19&P19&Q19&R19&S19&T19&U19&V19&W19&X19&Y19&Z19&AA19&AB19&AC19&AD19&AE19&AF19&AG19&AH19&AI19,"2","")) -> 0 | AQ19: =LEN(D19&E19&F19&G19&H19&I19&J19&K19&L19&M19&N19&O19&P19&Q19&R19&S19&T19&U19&V19&W19&X19&Y19&Z19&AA19&AB19&AC19&AD19&AE19&AF19&AG19&AH19&AI19)-LEN(SUBSTITUTE(D19&E19&F19&G19&H19&I19&J19&K19&L19&M19&N19&O19&P19&Q19&R19&S19&T19&U19&V19&W19&X19&Y19&Z19&AA19&AB19&AC19&AD19&AE19&AF19&AG19&AH19&AI19,"3","")) -> 0 | AR19: =SUM(AO19:AQ19) -> 0 | AT19: =COUNTIF(D19:AI19,"*m*") -> 0 | AU19: =COUNTIF(D19:AI19,"*d*") -> 0 | AV19: =COUNTIF(D19:AI19,"*b*") -> 0 | AW19: =COUNTIF(D19:AI19,"*l*") -> 0 | AX19: =COUNTIF(D19:AI19,"*o*") -> 0 | AY19: =SUM(AT19:AX19) -> 0
A20: =Üldinfo!A19 -> 16 | B20: =Üldinfo!B19 -> Täiskasvanu | C20: =Üldinfo!C19 -> Täiskasvanu | AK20: =COUNTA(D20:AI20) -> 0 | AL20: =Üldinfo!AM19 -> 0 | AM20: =AK20/AL20 -> #DIV/0! | AO20: =LEN(D20&E20&F20&G20&H20&I20&J20&K20&L20&M20&N20&O20&P20&Q20&R20&S20&T20&U20&V20&W20&X20&Y20&Z20&AA20&AB20&AC20&AD20&AE20&AF20&AG20&AH20&AI20)-LEN(SUBSTITUTE(D20&E20&F20&G20&H20&I20&J20&K20&L20&M20&N20&O20&P20&Q20&R20&S20&T20&U20&V20&W20&X20&Y20&Z20&AA20&AB20&AC20&AD20&AE20&AF20&AG20&AH20&AI20,"1","")) -> 0 | AP20: =LEN(D20&E20&F20&G20&H20&I20&J20&K20&L20&M20&N20&O20&P20&Q20&R20&S20&T20&U20&V20&W20&X20&Y20&Z20&AA20&AB20&AC20&AD20&AE20&AF20&AG20&AH20&AI20)-LEN(SUBSTITUTE(D20&E20&F20&G20&H20&I20&J20&K20&L20&M20&N20&O20&P20&Q20&R20&S20&T20&U20&V20&W20&X20&Y20&Z20&AA20&AB20&AC20&AD20&AE20&AF20&AG20&AH20&AI20,"2","")) -> 0 | AQ20: =LEN(D20&E20&F20&G20&H20&I20&J20&K20&L20&M20&N20&O20&P20&Q20&R20&S20&T20&U20&V20&W20&X20&Y20&Z20&AA20&AB20&AC20&AD20&AE20&AF20&AG20&AH20&AI20)-LEN(SUBSTITUTE(D20&E20&F20&G20&H20&I20&J20&K20&L20&M20&N20&O20&P20&Q20&R20&S20&T20&U20&V20&W20&X20&Y20&Z20&AA20&AB20&AC20&AD20&AE20&AF20&AG20&AH20&AI20,"3","")) -> 0 | AR20: =SUM(AO20:AQ20) -> 0 | AT20: =COUNTIF(D20:AI20,"*m*") -> 0 | AU20: =COUNTIF(D20:AI20,"*d*") -> 0 | AV20: =COUNTIF(D20:AI20,"*b*") -> 0 | AW20: =COUNTIF(D20:AI20,"*l*") -> 0 | AX20: =COUNTIF(D20:AI20,"*o*") -> 0 | AY20: =SUM(AT20:AX20) -> 0
A21: =Üldinfo!A20 -> 17 | B21: =Üldinfo!B20 -> Täiskasvanu | C21: =Üldinfo!C20 -> Täiskasvanu | AK21: =COUNTA(D21:AI21) -> 0 | AL21: =Üldinfo!AM20 -> 0 | AM21: =AK21/AL21 -> #DIV/0! | AO21: =LEN(D21&E21&F21&G21&H21&I21&J21&K21&L21&M21&N21&O21&P21&Q21&R21&S21&T21&U21&V21&W21&X21&Y21&Z21&AA21&AB21&AC21&AD21&AE21&AF21&AG21&AH21&AI21)-LEN(SUBSTITUTE(D21&E21&F21&G21&H21&I21&J21&K21&L21&M21&N21&O21&P21&Q21&R21&S21&T21&U21&V21&W21&X21&Y21&Z21&AA21&AB21&AC21&AD21&AE21&AF21&AG21&AH21&AI21,"1","")) -> 0 | AP21: =LEN(D21&E21&F21&G21&H21&I21&J21&K21&L21&M21&N21&O21&P21&Q21&R21&S21&T21&U21&V21&W21&X21&Y21&Z21&AA21&AB21&AC21&AD21&AE21&AF21&AG21&AH21&AI21)-LEN(SUBSTITUTE(D21&E21&F21&G21&H21&I21&J21&K21&L21&M21&N21&O21&P21&Q21&R21&S21&T21&U21&V21&W21&X21&Y21&Z21&AA21&AB21&AC21&AD21&AE21&AF21&AG21&AH21&AI21,"2","")) -> 0 | AQ21: =LEN(D21&E21&F21&G21&H21&I21&J21&K21&L21&M21&N21&O21&P21&Q21&R21&S21&T21&U21&V21&W21&X21&Y21&Z21&AA21&AB21&AC21&AD21&AE21&AF21&AG21&AH21&AI21)-LEN(SUBSTITUTE(D21&E21&F21&G21&H21&I21&J21&K21&L21&M21&N21&O21&P21&Q21&R21&S21&T21&U21&V21&W21&X21&Y21&Z21&AA21&AB21&AC21&AD21&AE21&AF21&AG21&AH21&AI21,"3","")) -> 0 | AR21: =SUM(AO21:AQ21) -> 0 | AT21: =COUNTIF(D21:AI21,"*m*") -> 0 | AU21: =COUNTIF(D21:AI21,"*d*") -> 0 | AV21: =COUNTIF(D21:AI21,"*b*") -> 0 | AW21: =COUNTIF(D21:AI21,"*l*") -> 0 | AX21: =COUNTIF(D21:AI21,"*o*") -> 0 | AY21: =SUM(AT21:AX21) -> 0
A22: =Üldinfo!A21 -> 19 | B22: =Üldinfo!B21 -> Mees | C22: =Üldinfo!C21 -> Täiskasvanu | AK22: =COUNTA(D22:AI22) -> 0 | AL22: =Üldinfo!AM21 -> 1 | AM22: =AK22/AL22 -> 0 | AO22: =LEN(D22&E22&F22&G22&H22&I22&J22&K22&L22&M22&N22&O22&P22&Q22&R22&S22&T22&U22&V22&W22&X22&Y22&Z22&AA22&AB22&AC22&AD22&AE22&AF22&AG22&AH22&AI22)-LEN(SUBSTITUTE(D22&E22&F22&G22&H22&I22&J22&K22&L22&M22&N22&O22&P22&Q22&R22&S22&T22&U22&V22&W22&X22&Y22&Z22&AA22&AB22&AC22&AD22&AE22&AF22&AG22&AH22&AI22,"1","")) -> 0 | AP22: =LEN(D22&E22&F22&G22&H22&I22&J22&K22&L22&M22&N22&O22&P22&Q22&R22&S22&T22&U22&V22&W22&X22&Y22&Z22&AA22&AB22&AC22&AD22&AE22&AF22&AG22&AH22&AI22)-LEN(SUBSTITUTE(D22&E22&F22&G22&H22&I22&J22&K22&L22&M22&N22&O22&P22&Q22&R22&S22&T22&U22&V22&W22&X22&Y22&Z22&AA22&AB22&AC22&AD22&AE22&AF22&AG22&AH22&AI22,"2","")) -> 0 | AQ22: =LEN(D22&E22&F22&G22&H22&I22&J22&K22&L22&M22&N22&O22&P22&Q22&R22&S22&T22&U22&V22&W22&X22&Y22&Z22&AA22&AB22&AC22&AD22&AE22&AF22&AG22&AH22&AI22)-LEN(SUBSTITUTE(D22&E22&F22&G22&H22&I22&J22&K22&L22&M22&N22&O22&P22&Q22&R22&S22&T22&U22&V22&W22&X22&Y22&Z22&AA22&AB22&AC22&AD22&AE22&AF22&AG22&AH22&AI22,"3","")) -> 0 | AR22: =SUM(AO22:AQ22) -> 0 | AT22: =COUNTIF(D22:AI22,"*m*") -> 0 | AU22: =COUNTIF(D22:AI22,"*d*") -> 0 | AV22: =COUNTIF(D22:AI22,"*b*") -> 0 | AW22: =COUNTIF(D22:AI22,"*l*") -> 0 | AX22: =COUNTIF(D22:AI22,"*o*") -> 0 | AY22: =SUM(AT22:AX22) -> 0
A23: =Üldinfo!A22 -> 20 | B23: =Üldinfo!B22 -> Mees | C23: =Üldinfo!C22 -> Täiskasvanu | AK23: =COUNTA(D23:AI23) -> 0 | AL23: =Üldinfo!AM22 -> 1 | AM23: =AK23/AL23 -> 0 | AO23: =LEN(D23&E23&F23&G23&H23&I23&J23&K23&L23&M23&N23&O23&P23&Q23&R23&S23&T23&U23&V23&W23&X23&Y23&Z23&AA23&AB23&AC23&AD23&AE23&AF23&AG23&AH23&AI23)-LEN(SUBSTITUTE(D23&E23&F23&G23&H23&I23&J23&K23&L23&M23&N23&O23&P23&Q23&R23&S23&T23&U23&V23&W23&X23&Y23&Z23&AA23&AB23&AC23&AD23&AE23&AF23&AG23&AH23&AI23,"1","")) -> 0 | AP23: =LEN(D23&E23&F23&G23&H23&I23&J23&K23&L23&M23&N23&O23&P23&Q23&R23&S23&T23&U23&V23&W23&X23&Y23&Z23&AA23&AB23&AC23&AD23&AE23&AF23&AG23&AH23&AI23)-LEN(SUBSTITUTE(D23&E23&F23&G23&H23&I23&J23&K23&L23&M23&N23&O23&P23&Q23&R23&S23&T23&U23&V23&W23&X23&Y23&Z23&AA23&AB23&AC23&AD23&AE23&AF23&AG23&AH23&AI23,"2","")) -> 0 | AQ23: =LEN(D23&E23&F23&G23&H23&I23&J23&K23&L23&M23&N23&O23&P23&Q23&R23&S23&T23&U23&V23&W23&X23&Y23&Z23&AA23&AB23&AC23&AD23&AE23&AF23&AG23&AH23&AI23)-LEN(SUBSTITUTE(D23&E23&F23&G23&H23&I23&J23&K23&L23&M23&N23&O23&P23&Q23&R23&S23&T23&U23&V23&W23&X23&Y23&Z23&AA23&AB23&AC23&AD23&AE23&AF23&AG23&AH23&AI23,"3","")) -> 0 | AR23: =SUM(AO23:AQ23) -> 0 | AT23: =COUNTIF(D23:AI23,"*m*") -> 0 | AU23: =COUNTIF(D23:AI23,"*d*") -> 0 | AV23: =COUNTIF(D23:AI23,"*b*") -> 0 | AW23: =COUNTIF(D23:AI23,"*l*") -> 0 | AX23: =COUNTIF(D23:AI23,"*o*") -> 0 | AY23: =SUM(AT23:AX23) -> 0
A24: =Üldinfo!A23 -> 21 | B24: =Üldinfo!B23 -> Naine | C24: =Üldinfo!C23 -> 20-25 a | I24: 1b | T24: 1l | U24: 1l | Y24: 1b | Z24: 1b | AA24: 1b | AB24: 1b | AC24: 1b | AD24: 1b | AG24: 1l | AK24: =COUNTA(D24:AI24) -> 10 | AL24: =Üldinfo!AM23 -> 30 | AM24: =AK24/AL24 -> 0.33333333 | AO24: =LEN(D24&E24&F24&G24&H24&I24&J24&K24&L24&M24&N24&O24&P24&Q24&R24&S24&T24&U24&V24&W24&X24&Y24&Z24&AA24&AB24&AC24&AD24&AE24&AF24&AG24&AH24&AI24)-LEN(SUBSTITUTE(D24&E24&F24&G24&H24&I24&J24&K24&L24&M24&N24&O24&P24&Q24&R24&S24&T24&U24&V24&W24&X24&Y24&Z24&AA24&AB24&AC24&AD24&AE24&AF24&AG24&AH24&AI24,"1","")) -> 10 | AP24: =LEN(D24&E24&F24&G24&H24&I24&J24&K24&L24&M24&N24&O24&P24&Q24&R24&S24&T24&U24&V24&W24&X24&Y24&Z24&AA24&AB24&AC24&AD24&AE24&AF24&AG24&AH24&AI24)-LEN(SUBSTITUTE(D24&E24&F24&G24&H24&I24&J24&K24&L24&M24&N24&O24&P24&Q24&R24&S24&T24&U24&V24&W24&X24&Y24&Z24&AA24&AB24&AC24&AD24&AE24&AF24&AG24&AH24&AI24,"2","")) -> 0 | AQ24: =LEN(D24&E24&F24&G24&H24&I24&J24&K24&L24&M24&N24&O24&P24&Q24&R24&S24&T24&U24&V24&W24&X24&Y24&Z24&AA24&AB24&AC24&AD24&AE24&AF24&AG24&AH24&AI24)-LEN(SUBSTITUTE(D24&E24&F24&G24&H24&I24&J24&K24&L24&M24&N24&O24&P24&Q24&R24&S24&T24&U24&V24&W24&X24&Y24&Z24&AA24&AB24&AC24&AD24&AE24&AF24&AG24&AH24&AI24,"3","")) -> 0 | AR24: =SUM(AO24:AQ24) -> 10 | AT24: =COUNTIF(D24:AI24,"*m*") -> 0 | AU24: =COUNTIF(D24:AI24,"*d*") -> 0 | AV24: =COUNTIF(D24:AI24,"*b*") -> 7 | AW24: =COUNTIF(D24:AI24,"*l*") -> 3 | AX24: =COUNTIF(D24:AI24,"*o*") -> 0 | AY24: =SUM(AT24:AX24) -> 10
A25: =Üldinfo!A24 -> 22 | B25: =Üldinfo!B24 -> Naine | C25: =Üldinfo!C24 -> 17-20 a | AK25: =COUNTA(D25:AI25) -> 0 | AL25: =Üldinfo!AM24 -> 29 | AM25: =AK25/AL25 -> 0 | AO25: =LEN(D25&E25&F25&G25&H25&I25&J25&K25&L25&M25&N25&O25&P25&Q25&R25&S25&T25&U25&V25&W25&X25&Y25&Z25&AA25&AB25&AC25&AD25&AE25&AF25&AG25&AH25&AI25)-LEN(SUBSTITUTE(D25&E25&F25&G25&H25&I25&J25&K25&L25&M25&N25&O25&P25&Q25&R25&S25&T25&U25&V25&W25&X25&Y25&Z25&AA25&AB25&AC25&AD25&AE25&AF25&AG25&AH25&AI25,"1","")) -> 0 | AP25: =LEN(D25&E25&F25&G25&H25&I25&J25&K25&L25&M25&N25&O25&P25&Q25&R25&S25&T25&U25&V25&W25&X25&Y25&Z25&AA25&AB25&AC25&AD25&AE25&AF25&AG25&AH25&AI25)-LEN(SUBSTITUTE(D25&E25&F25&G25&H25&I25&J25&K25&L25&M25&N25&O25&P25&Q25&R25&S25&T25&U25&V25&W25&X25&Y25&Z25&AA25&AB25&AC25&AD25&AE25&AF25&AG25&AH25&AI25,"2","")) -> 0 | AQ25: =LEN(D25&E25&F25&G25&H25&I25&J25&K25&L25&M25&N25&O25&P25&Q25&R25&S25&T25&U25&V25&W25&X25&Y25&Z25&AA25&AB25&AC25&AD25&AE25&AF25&AG25&AH25&AI25)-LEN(SUBSTITUTE(D25&E25&F25&G25&H25&I25&J25&K25&L25&M25&N25&O25&P25&Q25&R25&S25&T25&U25&V25&W25&X25&Y25&Z25&AA25&AB25&AC25&AD25&AE25&AF25&AG25&AH25&AI25,"3","")) -> 0 | AR25: =SUM(AO25:AQ25) -> 0 | AT25: =COUNTIF(D25:AI25,"*m*") -> 0 | AU25: =COUNTIF(D25:AI25,"*d*") -> 0 | AV25: =COUNTIF(D25:AI25,"*b*") -> 0 | AW25: =COUNTIF(D25:AI25,"*l*") -> 0 | AX25: =COUNTIF(D25:AI25,"*o*") -> 0 | AY25: =SUM(AT25:AX25) -> 0
A26: =Üldinfo!A25 -> 23 | B26: =Üldinfo!B25 -> Alaealine | C26: =Üldinfo!C25 -> 10 a ± 30k | Q26: 1l | AK26: =COUNTA(D26:AI26) -> 1 | AL26: =Üldinfo!AM25 -> 20 | AM26: =AK26/AL26 -> 0.05 | AO26: =LEN(D26&E26&F26&G26&H26&I26&J26&K26&L26&M26&N26&O26&P26&Q26&R26&S26&T26&U26&V26&W26&X26&Y26&Z26&AA26&AB26&AC26&AD26&AE26&AF26&AG26&AH26&AI26)-LEN(SUBSTITUTE(D26&E26&F26&G26&H26&I26&J26&K26&L26&M26&N26&O26&P26&Q26&R26&S26&T26&U26&V26&W26&X26&Y26&Z26&AA26&AB26&AC26&AD26&AE26&AF26&AG26&AH26&AI26,"1","")) -> 1 | AP26: =LEN(D26&E26&F26&G26&H26&I26&J26&K26&L26&M26&N26&O26&P26&Q26&R26&S26&T26&U26&V26&W26&X26&Y26&Z26&AA26&AB26&AC26&AD26&AE26&AF26&AG26&AH26&AI26)-LEN(SUBSTITUTE(D26&E26&F26&G26&H26&I26&J26&K26&L26&M26&N26&O26&P26&Q26&R26&S26&T26&U26&V26&W26&X26&Y26&Z26&AA26&AB26&AC26&AD26&AE26&AF26&AG26&AH26&AI26,"2","")) -> 0 | AQ26: =LEN(D26&E26&F26&G26&H26&I26&J26&K26&L26&M26&N26&O26&P26&Q26&R26&S26&T26&U26&V26&W26&X26&Y26&Z26&AA26&AB26&AC26&AD26&AE26&AF26&AG26&AH26&AI26)-LEN(SUBSTITUTE(D26&E26&F26&G26&H26&I26&J26&K26&L26&M26&N26&O26&P26&Q26&R26&S26&T26&U26&V26&W26&X26&Y26&Z26&AA26&AB26&AC26&AD26&AE26&AF26&AG26&AH26&AI26,"3","")) -> 0 | AR26: =SUM(AO26:AQ26) -> 1 | AT26: =COUNTIF(D26:AI26,"*m*") -> 0 | AU26: =COUNTIF(D26:AI26,"*d*") -> 0 | AV26: =COUNTIF(D26:AI26,"*b*") -> 0 | AW26: =COUNTIF(D26:AI26,"*l*") -> 1 | AX26: =COUNTIF(D26:AI26,"*o*") -> 0 | AY26: =SUM(AT26:AX26) -> 1
A27: =Üldinfo!A26 -> 24 | B27: =Üldinfo!B26 -> Mees | C27: =Üldinfo!C26 -> 39-44 a | AK27: =COUNTA(D27:AI27) -> 0 | AL27: =Üldinfo!AM26 -> 0 | AM27: =AK27/AL27 -> #DIV/0! | AO27: =LEN(D27&E27&F27&G27&H27&I27&J27&K27&L27&M27&N27&O27&P27&Q27&R27&S27&T27&U27&V27&W27&X27&Y27&Z27&AA27&AB27&AC27&AD27&AE27&AF27&AG27&AH27&AI27)-LEN(SUBSTITUTE(D27&E27&F27&G27&H27&I27&J27&K27&L27&M27&N27&O27&P27&Q27&R27&S27&T27&U27&V27&W27&X27&Y27&Z27&AA27&AB27&AC27&AD27&AE27&AF27&AG27&AH27&AI27,"1","")) -> 0 | AP27: =LEN(D27&E27&F27&G27&H27&I27&J27&K27&L27&M27&N27&O27&P27&Q27&R27&S27&T27&U27&V27&W27&X27&Y27&Z27&AA27&AB27&AC27&AD27&AE27&AF27&AG27&AH27&AI27)-LEN(SUBSTITUTE(D27&E27&F27&G27&H27&I27&J27&K27&L27&M27&N27&O27&P27&Q27&R27&S27&T27&U27&V27&W27&X27&Y27&Z27&AA27&AB27&AC27&AD27&AE27&AF27&AG27&AH27&AI27,"2","")) -> 0 | AQ27: =LEN(D27&E27&F27&G27&H27&I27&J27&K27&L27&M27&N27&O27&P27&Q27&R27&S27&T27&U27&V27&W27&X27&Y27&Z27&AA27&AB27&AC27&AD27&AE27&AF27&AG27&AH27&AI27)-LEN(SUBSTITUTE(D27&E27&F27&G27&H27&I27&J27&K27&L27&M27&N27&O27&P27&Q27&R27&S27&T27&U27&V27&W27&X27&Y27&Z27&AA27&AB27&AC27&AD27&AE27&AF27&AG27&AH27&AI27,"3","")) -> 0 | AR27: =SUM(AO27:AQ27) -> 0 | AT27: =COUNTIF(D27:AI27,"*m*") -> 0 | AU27: =COUNTIF(D27:AI27,"*d*") -> 0 | AV27: =COUNTIF(D27:AI27,"*b*") -> 0 | AW27: =COUNTIF(D27:AI27,"*l*") -> 0 | AX27: =COUNTIF(D27:AI27,"*o*") -> 0 | AY27: =SUM(AT27:AX27) -> 0
A28: =Üldinfo!A27 -> 25 | B28: =Üldinfo!B27 -> Alaealine | C28: =Üldinfo!C27 -> 7-11 a | V28: 1o | AK28: =COUNTA(D28:AI28) -> 1 | AL28: =Üldinfo!AM27 -> 24 | AM28: =AK28/AL28 -> 0.041666667 | AO28: =LEN(D28&E28&F28&G28&H28&I28&J28&K28&L28&M28&N28&O28&P28&Q28&R28&S28&T28&U28&V28&W28&X28&Y28&Z28&AA28&AB28&AC28&AD28&AE28&AF28&AG28&AH28&AI28)-LEN(SUBSTITUTE(D28&E28&F28&G28&H28&I28&J28&K28&L28&M28&N28&O28&P28&Q28&R28&S28&T28&U28&V28&W28&X28&Y28&Z28&AA28&AB28&AC28&AD28&AE28&AF28&AG28&AH28&AI28,"1","")) -> 1 | AP28: =LEN(D28&E28&F28&G28&H28&I28&J28&K28&L28&M28&N28&O28&P28&Q28&R28&S28&T28&U28&V28&W28&X28&Y28&Z28&AA28&AB28&AC28&AD28&AE28&AF28&AG28&AH28&AI28)-LEN(SUBSTITUTE(D28&E28&F28&G28&H28&I28&J28&K28&L28&M28&N28&O28&P28&Q28&R28&S28&T28&U28&V28&W28&X28&Y28&Z28&AA28&AB28&AC28&AD28&AE28&AF28&AG28&AH28&AI28,"2","")) -> 0 | AQ28: =LEN(D28&E28&F28&G28&H28&I28&J28&K28&L28&M28&N28&O28&P28&Q28&R28&S28&T28&U28&V28&W28&X28&Y28&Z28&AA28&AB28&AC28&AD28&AE28&AF28&AG28&AH28&AI28)-LEN(SUBSTITUTE(D28&E28&F28&G28&H28&I28&J28&K28&L28&M28&N28&O28&P28&Q28&R28&S28&T28&U28&V28&W28&X28&Y28&Z28&AA28&AB28&AC28&AD28&AE28&AF28&AG28&AH28&AI28,"3","")) -> 0 | AR28: =SUM(AO28:AQ28) -> 1 | AT28: =COUNTIF(D28:AI28,"*m*") -> 0 | AU28: =COUNTIF(D28:AI28,"*d*") -> 0 | AV28: =COUNTIF(D28:AI28,"*b*") -> 0 | AW28: =COUNTIF(D28:AI28,"*l*") -> 0 | AX28: =COUNTIF(D28:AI28,"*o*") -> 1 | AY28: =SUM(AT28:AX28) -> 1
A29: =Üldinfo!A28 -> 26a | B29: =Üldinfo!B28 -> Alaealine | C29: =Üldinfo!C28 -> 12-18 a | AK29: =COUNTA(D29:AI29) -> 0 | AL29: =Üldinfo!AM28 -> 0 | AM29: =AK29/AL29 -> #DIV/0! | AO29: =LEN(D29&E29&F29&G29&H29&I29&J29&K29&L29&M29&N29&O29&P29&Q29&R29&S29&T29&U29&V29&W29&X29&Y29&Z29&AA29&AB29&AC29&AD29&AE29&AF29&AG29&AH29&AI29)-LEN(SUBSTITUTE(D29&E29&F29&G29&H29&I29&J29&K29&L29&M29&N29&O29&P29&Q29&R29&S29&T29&U29&V29&W29&X29&Y29&Z29&AA29&AB29&AC29&AD29&AE29&AF29&AG29&AH29&AI29,"1","")) -> 0 | AP29: =LEN(D29&E29&F29&G29&H29&I29&J29&K29&L29&M29&N29&O29&P29&Q29&R29&S29&T29&U29&V29&W29&X29&Y29&Z29&AA29&AB29&AC29&AD29&AE29&AF29&AG29&AH29&AI29)-LEN(SUBSTITUTE(D29&E29&F29&G29&H29&I29&J29&K29&L29&M29&N29&O29&P29&Q29&R29&S29&T29&U29&V29&W29&X29&Y29&Z29&AA29&AB29&AC29&AD29&AE29&AF29&AG29&AH29&AI29,"2","")) -> 0 | AQ29: =LEN(D29&E29&F29&G29&H29&I29&J29&K29&L29&M29&N29&O29&P29&Q29&R29&S29&T29&U29&V29&W29&X29&Y29&Z29&AA29&AB29&AC29&AD29&AE29&AF29&AG29&AH29&AI29)-LEN(SUBSTITUTE(D29&E29&F29&G29&H29&I29&J29&K29&L29&M29&N29&O29&P29&Q29&R29&S29&T29&U29&V29&W29&X29&Y29&Z29&AA29&AB29&AC29&AD29&AE29&AF29&AG29&AH29&AI29,"3","")) -> 0 | AR29: =SUM(AO29:AQ29) -> 0 | AT29: =COUNTIF(D29:AI29,"*m*") -> 0 | AU29: =COUNTIF(D29:AI29,"*d*") -> 0 | AV29: =COUNTIF(D29:AI29,"*b*") -> 0 | AW29: =COUNTIF(D29:AI29,"*l*") -> 0 | AX29: =COUNTIF(D29:AI29,"*o*") -> 0 | AY29: =SUM(AT29:AX29) -> 0
A30: =Üldinfo!A29 -> 26b | B30: =Üldinfo!B29 -> Täiskasvanu | C30: =Üldinfo!C29 -> Täiskasvanu | AK30: =COUNTA(D30:AI30) -> 0 | AL30: =Üldinfo!AM29 -> 0 | AM30: =AK30/AL30 -> #DIV/0! | AO30: =LEN(D30&E30&F30&G30&H30&I30&J30&K30&L30&M30&N30&O30&P30&Q30&R30&S30&T30&U30&V30&W30&X30&Y30&Z30&AA30&AB30&AC30&AD30&AE30&AF30&AG30&AH30&AI30)-LEN(SUBSTITUTE(D30&E30&F30&G30&H30&I30&J30&K30&L30&M30&N30&O30&P30&Q30&R30&S30&T30&U30&V30&W30&X30&Y30&Z30&AA30&AB30&AC30&AD30&AE30&AF30&AG30&AH30&AI30,"1","")) -> 0 | AP30: =LEN(D30&E30&F30&G30&H30&I30&J30&K30&L30&M30&N30&O30&P30&Q30&R30&S30&T30&U30&V30&W30&X30&Y30&Z30&AA30&AB30&AC30&AD30&AE30&AF30&AG30&AH30&AI30)-LEN(SUBSTITUTE(D30&E30&F30&G30&H30&I30&J30&K30&L30&M30&N30&O30&P30&Q30&R30&S30&T30&U30&V30&W30&X30&Y30&Z30&AA30&AB30&AC30&AD30&AE30&AF30&AG30&AH30&AI30,"2","")) -> 0 | AQ30: =LEN(D30&E30&F30&G30&H30&I30&J30&K30&L30&M30&N30&O30&P30&Q30&R30&S30&T30&U30&V30&W30&X30&Y30&Z30&AA30&AB30&AC30&AD30&AE30&AF30&AG30&AH30&AI30)-LEN(SUBSTITUTE(D30&E30&F30&G30&H30&I30&J30&K30&L30&M30&N30&O30&P30&Q30&R30&S30&T30&U30&V30&W30&X30&Y30&Z30&AA30&AB30&AC30&AD30&AE30&AF30&AG30&AH30&AI30,"3","")) -> 0 | AR30: =SUM(AO30:AQ30) -> 0 | AT30: =COUNTIF(D30:AI30,"*m*") -> 0 | AU30: =COUNTIF(D30:AI30,"*d*") -> 0 | AV30: =COUNTIF(D30:AI30,"*b*") -> 0 | AW30: =COUNTIF(D30:AI30,"*l*") -> 0 | AX30: =COUNTIF(D30:AI30,"*o*") -> 0 | AY30: =SUM(AT30:AX30) -> 0
